2020-09-18 11:35:28,710 (15879/MainThread) litecli.main ERROR - sql: 'select *', error: OperationalError('Not connected to database.')
2020-09-18 11:35:28,711 (15879/MainThread) litecli.main ERROR - traceback: 'Traceback (most recent call last):\n  File "/home/arthur/.local/lib/python3.8/site-packages/litecli/main.py", line 441, in one_iteration\n    for title, cur, headers, status in res:\n  File "/home/arthur/.local/lib/python3.8/site-packages/litecli/sqlexecute.py", line 114, in run\n    raise OperationalError("Not connected to database.")\nsqlite3.OperationalError: Not connected to database.\n'
2020-09-18 11:35:34,162 (15879/MainThread) litecli.main ERROR - sql: 'show ', error: OperationalError('Not connected to database.')
2020-09-18 11:35:34,165 (15879/MainThread) litecli.main ERROR - traceback: 'Traceback (most recent call last):\n  File "/home/arthur/.local/lib/python3.8/site-packages/litecli/main.py", line 441, in one_iteration\n    for title, cur, headers, status in res:\n  File "/home/arthur/.local/lib/python3.8/site-packages/litecli/sqlexecute.py", line 114, in run\n    raise OperationalError("Not connected to database.")\nsqlite3.OperationalError: Not connected to database.\n'
2020-09-25 12:27:24,383 (446/MainThread) litecli.main ERROR - sql: 'show database', error: OperationalError('Not connected to database.')
2020-09-25 12:27:24,391 (446/MainThread) litecli.main ERROR - traceback: 'Traceback (most recent call last):\n  File "/home/arthur/.local/lib/python3.8/site-packages/litecli/main.py", line 441, in one_iteration\n    for title, cur, headers, status in res:\n  File "/home/arthur/.local/lib/python3.8/site-packages/litecli/sqlexecute.py", line 114, in run\n    raise OperationalError("Not connected to database.")\nsqlite3.OperationalError: Not connected to database.\n'
2020-09-25 12:27:25,214 (446/MainThread) litecli.main ERROR - sql: 'show databases', error: OperationalError('Not connected to database.')
2020-09-25 12:27:25,214 (446/MainThread) litecli.main ERROR - traceback: 'Traceback (most recent call last):\n  File "/home/arthur/.local/lib/python3.8/site-packages/litecli/main.py", line 441, in one_iteration\n    for title, cur, headers, status in res:\n  File "/home/arthur/.local/lib/python3.8/site-packages/litecli/sqlexecute.py", line 114, in run\n    raise OperationalError("Not connected to database.")\nsqlite3.OperationalError: Not connected to database.\n'
2020-09-25 12:27:26,174 (446/MainThread) litecli.main ERROR - sql: 'show databases', error: OperationalError('Not connected to database.')
2020-09-25 12:27:26,174 (446/MainThread) litecli.main ERROR - traceback: 'Traceback (most recent call last):\n  File "/home/arthur/.local/lib/python3.8/site-packages/litecli/main.py", line 441, in one_iteration\n    for title, cur, headers, status in res:\n  File "/home/arthur/.local/lib/python3.8/site-packages/litecli/sqlexecute.py", line 114, in run\n    raise OperationalError("Not connected to database.")\nsqlite3.OperationalError: Not connected to database.\n'
2020-09-25 12:27:33,167 (446/MainThread) litecli.main ERROR - sql: 'use', error: TypeError('expected str, bytes or os.PathLike object, not NoneType')
2020-09-25 12:27:33,168 (446/MainThread) litecli.main ERROR - traceback: 'Traceback (most recent call last):\n  File "/home/arthur/.local/lib/python3.8/site-packages/litecli/main.py", line 441, in one_iteration\n    for title, cur, headers, status in res:\n  File "/home/arthur/.local/lib/python3.8/site-packages/litecli/sqlexecute.py", line 121, in run\n    for result in special.execute(cur, sql):\n  File "/home/arthur/.local/lib/python3.8/site-packages/litecli/main.py", line 190, in change_db\n    self.sqlexecute.connect(database=arg)\n  File "/home/arthur/.local/lib/python3.8/site-packages/litecli/sqlexecute.py", line 58, in connect\n    db_name = os.path.expanduser(db)\n  File "/usr/lib/python3.8/posixpath.py", line 231, in expanduser\n    path = os.fspath(path)\nTypeError: expected str, bytes or os.PathLike object, not NoneType\n'
2020-09-25 12:27:36,266 (446/MainThread) litecli.main ERROR - sql: 'connect', error: OperationalError('Not connected to database.')
2020-09-25 12:27:36,267 (446/MainThread) litecli.main ERROR - traceback: 'Traceback (most recent call last):\n  File "/home/arthur/.local/lib/python3.8/site-packages/litecli/main.py", line 441, in one_iteration\n    for title, cur, headers, status in res:\n  File "/home/arthur/.local/lib/python3.8/site-packages/litecli/sqlexecute.py", line 114, in run\n    raise OperationalError("Not connected to database.")\nsqlite3.OperationalError: Not connected to database.\n'
2020-09-25 12:27:36,994 (446/MainThread) litecli.main ERROR - sql: 'ls', error: OperationalError('Not connected to database.')
2020-09-25 12:27:36,994 (446/MainThread) litecli.main ERROR - traceback: 'Traceback (most recent call last):\n  File "/home/arthur/.local/lib/python3.8/site-packages/litecli/main.py", line 441, in one_iteration\n    for title, cur, headers, status in res:\n  File "/home/arthur/.local/lib/python3.8/site-packages/litecli/sqlexecute.py", line 114, in run\n    raise OperationalError("Not connected to database.")\nsqlite3.OperationalError: Not connected to database.\n'
2020-09-25 12:27:38,443 (446/MainThread) litecli.main ERROR - sql: 'sdfa', error: OperationalError('Not connected to database.')
2020-09-25 12:27:38,443 (446/MainThread) litecli.main ERROR - traceback: 'Traceback (most recent call last):\n  File "/home/arthur/.local/lib/python3.8/site-packages/litecli/main.py", line 441, in one_iteration\n    for title, cur, headers, status in res:\n  File "/home/arthur/.local/lib/python3.8/site-packages/litecli/sqlexecute.py", line 114, in run\n    raise OperationalError("Not connected to database.")\nsqlite3.OperationalError: Not connected to database.\n'
2020-09-25 12:27:42,691 (446/MainThread) litecli.main ERROR - sql: 'ls', error: OperationalError('Not connected to database.')
2020-09-25 12:27:42,691 (446/MainThread) litecli.main ERROR - traceback: 'Traceback (most recent call last):\n  File "/home/arthur/.local/lib/python3.8/site-packages/litecli/main.py", line 441, in one_iteration\n    for title, cur, headers, status in res:\n  File "/home/arthur/.local/lib/python3.8/site-packages/litecli/sqlexecute.py", line 114, in run\n    raise OperationalError("Not connected to database.")\nsqlite3.OperationalError: Not connected to database.\n'
2020-09-25 12:27:43,131 (446/MainThread) litecli.main ERROR - sql: 'ls', error: OperationalError('Not connected to database.')
2020-09-25 12:27:43,131 (446/MainThread) litecli.main ERROR - traceback: 'Traceback (most recent call last):\n  File "/home/arthur/.local/lib/python3.8/site-packages/litecli/main.py", line 441, in one_iteration\n    for title, cur, headers, status in res:\n  File "/home/arthur/.local/lib/python3.8/site-packages/litecli/sqlexecute.py", line 114, in run\n    raise OperationalError("Not connected to database.")\nsqlite3.OperationalError: Not connected to database.\n'
2020-10-04 11:07:39,728 (1805/MainThread) litecli.main ERROR - sql: 'show databases', error: OperationalError('Not connected to database.')
2020-10-04 11:07:39,740 (1805/MainThread) litecli.main ERROR - traceback: 'Traceback (most recent call last):\n  File "/home/arthur/.local/lib/python3.8/site-packages/litecli/main.py", line 441, in one_iteration\n    for title, cur, headers, status in res:\n  File "/home/arthur/.local/lib/python3.8/site-packages/litecli/sqlexecute.py", line 114, in run\n    raise OperationalError("Not connected to database.")\nsqlite3.OperationalError: Not connected to database.\n'
2020-10-04 11:07:41,403 (1805/MainThread) litecli.main ERROR - sql: 'use', error: TypeError('expected str, bytes or os.PathLike object, not NoneType')
2020-10-04 11:07:41,412 (1805/MainThread) litecli.main ERROR - traceback: 'Traceback (most recent call last):\n  File "/home/arthur/.local/lib/python3.8/site-packages/litecli/main.py", line 441, in one_iteration\n    for title, cur, headers, status in res:\n  File "/home/arthur/.local/lib/python3.8/site-packages/litecli/sqlexecute.py", line 121, in run\n    for result in special.execute(cur, sql):\n  File "/home/arthur/.local/lib/python3.8/site-packages/litecli/main.py", line 190, in change_db\n    self.sqlexecute.connect(database=arg)\n  File "/home/arthur/.local/lib/python3.8/site-packages/litecli/sqlexecute.py", line 58, in connect\n    db_name = os.path.expanduser(db)\n  File "/usr/lib/python3.8/posixpath.py", line 231, in expanduser\n    path = os.fspath(path)\nTypeError: expected str, bytes or os.PathLike object, not NoneType\n'
2020-10-04 11:08:08,094 (1805/MainThread) litecli.main ERROR - sql: 'create DATABASE test ()', error: OperationalError('Not connected to database.')
2020-10-04 11:08:08,094 (1805/MainThread) litecli.main ERROR - traceback: 'Traceback (most recent call last):\n  File "/home/arthur/.local/lib/python3.8/site-packages/litecli/main.py", line 441, in one_iteration\n    for title, cur, headers, status in res:\n  File "/home/arthur/.local/lib/python3.8/site-packages/litecli/sqlexecute.py", line 114, in run\n    raise OperationalError("Not connected to database.")\nsqlite3.OperationalError: Not connected to database.\n'
2020-10-04 11:08:11,984 (1805/MainThread) litecli.main ERROR - sql: 'create DATABASE test( )', error: OperationalError('Not connected to database.')
2020-10-04 11:08:11,985 (1805/MainThread) litecli.main ERROR - traceback: 'Traceback (most recent call last):\n  File "/home/arthur/.local/lib/python3.8/site-packages/litecli/main.py", line 441, in one_iteration\n    for title, cur, headers, status in res:\n  File "/home/arthur/.local/lib/python3.8/site-packages/litecli/sqlexecute.py", line 114, in run\n    raise OperationalError("Not connected to database.")\nsqlite3.OperationalError: Not connected to database.\n'
2020-10-09 11:21:29,414 (5980/MainThread) litecli.main ERROR - sql: 'select "Hello, World"', error: OperationalError('Not connected to database.')
2020-10-09 11:21:29,426 (5980/MainThread) litecli.main ERROR - traceback: 'Traceback (most recent call last):\n  File "/home/arthur/.local/lib/python3.8/site-packages/litecli/main.py", line 441, in one_iteration\n    for title, cur, headers, status in res:\n  File "/home/arthur/.local/lib/python3.8/site-packages/litecli/sqlexecute.py", line 114, in run\n    raise OperationalError("Not connected to database.")\nsqlite3.OperationalError: Not connected to database.\n'
2020-10-09 11:21:37,722 (5980/MainThread) litecli.main ERROR - sql: "select 'Hello, World'", error: OperationalError('Not connected to database.')
2020-10-09 11:21:37,722 (5980/MainThread) litecli.main ERROR - traceback: 'Traceback (most recent call last):\n  File "/home/arthur/.local/lib/python3.8/site-packages/litecli/main.py", line 441, in one_iteration\n    for title, cur, headers, status in res:\n  File "/home/arthur/.local/lib/python3.8/site-packages/litecli/sqlexecute.py", line 114, in run\n    raise OperationalError("Not connected to database.")\nsqlite3.OperationalError: Not connected to database.\n'
2020-10-09 11:21:44,891 (5980/MainThread) litecli.main ERROR - sql: '.header on', error: OperationalError('Not connected to database.')
2020-10-09 11:21:44,891 (5980/MainThread) litecli.main ERROR - traceback: 'Traceback (most recent call last):\n  File "/home/arthur/.local/lib/python3.8/site-packages/litecli/main.py", line 441, in one_iteration\n    for title, cur, headers, status in res:\n  File "/home/arthur/.local/lib/python3.8/site-packages/litecli/sqlexecute.py", line 114, in run\n    raise OperationalError("Not connected to database.")\nsqlite3.OperationalError: Not connected to database.\n'
2020-10-09 11:21:46,661 (5980/MainThread) litecli.main ERROR - sql: 'fas', error: OperationalError('Not connected to database.')
2020-10-09 11:21:46,662 (5980/MainThread) litecli.main ERROR - traceback: 'Traceback (most recent call last):\n  File "/home/arthur/.local/lib/python3.8/site-packages/litecli/main.py", line 441, in one_iteration\n    for title, cur, headers, status in res:\n  File "/home/arthur/.local/lib/python3.8/site-packages/litecli/sqlexecute.py", line 114, in run\n    raise OperationalError("Not connected to database.")\nsqlite3.OperationalError: Not connected to database.\n'
2020-10-09 11:21:52,346 (5980/MainThread) litecli.main ERROR - sql: 'create TABLE', error: OperationalError('Not connected to database.')
2020-10-09 11:21:52,346 (5980/MainThread) litecli.main ERROR - traceback: 'Traceback (most recent call last):\n  File "/home/arthur/.local/lib/python3.8/site-packages/litecli/main.py", line 441, in one_iteration\n    for title, cur, headers, status in res:\n  File "/home/arthur/.local/lib/python3.8/site-packages/litecli/sqlexecute.py", line 114, in run\n    raise OperationalError("Not connected to database.")\nsqlite3.OperationalError: Not connected to database.\n'
2020-10-09 11:23:21,026 (6025/MainThread) litecli.main ERROR - sql: 'show databases', error: OperationalError('near "show": syntax error')
2020-10-09 11:23:21,035 (6025/MainThread) litecli.main ERROR - traceback: 'Traceback (most recent call last):\n  File "/home/arthur/.local/lib/python3.8/site-packages/litecli/sqlexecute.py", line 121, in run\n    for result in special.execute(cur, sql):\n  File "/home/arthur/.local/lib/python3.8/site-packages/litecli/packages/special/main.py", line 109, in execute\n    raise CommandNotFound\nlitecli.packages.special.main.CommandNotFound\n\nDuring handling of the above exception, another exception occurred:\n\nTraceback (most recent call last):\n  File "/home/arthur/.local/lib/python3.8/site-packages/litecli/main.py", line 441, in one_iteration\n    for title, cur, headers, status in res:\n  File "/home/arthur/.local/lib/python3.8/site-packages/litecli/sqlexecute.py", line 125, in run\n    cur.execute(sql)\nsqlite3.OperationalError: near "show": syntax error\n'
2020-10-09 11:23:26,661 (6025/MainThread) litecli.main ERROR - sql: "select 'Hello, World", error: OperationalError('unrecognized token: "\'Hello, World"')
2020-10-09 11:23:26,662 (6025/MainThread) litecli.main ERROR - traceback: 'Traceback (most recent call last):\n  File "/home/arthur/.local/lib/python3.8/site-packages/litecli/sqlexecute.py", line 121, in run\n    for result in special.execute(cur, sql):\n  File "/home/arthur/.local/lib/python3.8/site-packages/litecli/packages/special/main.py", line 109, in execute\n    raise CommandNotFound\nlitecli.packages.special.main.CommandNotFound\n\nDuring handling of the above exception, another exception occurred:\n\nTraceback (most recent call last):\n  File "/home/arthur/.local/lib/python3.8/site-packages/litecli/main.py", line 441, in one_iteration\n    for title, cur, headers, status in res:\n  File "/home/arthur/.local/lib/python3.8/site-packages/litecli/sqlexecute.py", line 125, in run\n    cur.execute(sql)\nsqlite3.OperationalError: unrecognized token: "\'Hello, World"\n'
2020-10-09 11:23:50,012 (6041/MainThread) litecli.main ERROR - sql: 'create table cars (', error: OperationalError('incomplete input')
2020-10-09 11:23:50,013 (6041/MainThread) litecli.main ERROR - traceback: 'Traceback (most recent call last):\n  File "/home/arthur/.local/lib/python3.8/site-packages/litecli/sqlexecute.py", line 121, in run\n    for result in special.execute(cur, sql):\n  File "/home/arthur/.local/lib/python3.8/site-packages/litecli/packages/special/main.py", line 109, in execute\n    raise CommandNotFound\nlitecli.packages.special.main.CommandNotFound\n\nDuring handling of the above exception, another exception occurred:\n\nTraceback (most recent call last):\n  File "/home/arthur/.local/lib/python3.8/site-packages/litecli/main.py", line 441, in one_iteration\n    for title, cur, headers, status in res:\n  File "/home/arthur/.local/lib/python3.8/site-packages/litecli/sqlexecute.py", line 125, in run\n    cur.execute(sql)\nsqlite3.OperationalError: incomplete input\n'
2020-10-09 11:24:17,211 (6041/MainThread) litecli.main ERROR - sql: 'ls\n;', error: OperationalError('near "ls": syntax error')
2020-10-09 11:24:17,211 (6041/MainThread) litecli.main ERROR - traceback: 'Traceback (most recent call last):\n  File "/home/arthur/.local/lib/python3.8/site-packages/litecli/sqlexecute.py", line 121, in run\n    for result in special.execute(cur, sql):\n  File "/home/arthur/.local/lib/python3.8/site-packages/litecli/packages/special/main.py", line 109, in execute\n    raise CommandNotFound\nlitecli.packages.special.main.CommandNotFound\n\nDuring handling of the above exception, another exception occurred:\n\nTraceback (most recent call last):\n  File "/home/arthur/.local/lib/python3.8/site-packages/litecli/main.py", line 441, in one_iteration\n    for title, cur, headers, status in res:\n  File "/home/arthur/.local/lib/python3.8/site-packages/litecli/sqlexecute.py", line 125, in run\n    cur.execute(sql)\nsqlite3.OperationalError: near "ls": syntax error\n'
2020-10-09 11:24:24,539 (6041/MainThread) litecli.main ERROR - sql: 'show tables\n;', error: OperationalError('near "show": syntax error')
2020-10-09 11:24:24,540 (6041/MainThread) litecli.main ERROR - traceback: 'Traceback (most recent call last):\n  File "/home/arthur/.local/lib/python3.8/site-packages/litecli/sqlexecute.py", line 121, in run\n    for result in special.execute(cur, sql):\n  File "/home/arthur/.local/lib/python3.8/site-packages/litecli/packages/special/main.py", line 109, in execute\n    raise CommandNotFound\nlitecli.packages.special.main.CommandNotFound\n\nDuring handling of the above exception, another exception occurred:\n\nTraceback (most recent call last):\n  File "/home/arthur/.local/lib/python3.8/site-packages/litecli/main.py", line 441, in one_iteration\n    for title, cur, headers, status in res:\n  File "/home/arthur/.local/lib/python3.8/site-packages/litecli/sqlexecute.py", line 125, in run\n    cur.execute(sql)\nsqlite3.OperationalError: near "show": syntax error\n'
2020-10-09 11:24:28,471 (6041/MainThread) litecli.main ERROR - sql: 'show tables;', error: OperationalError('near "show": syntax error')
2020-10-09 11:24:28,471 (6041/MainThread) litecli.main ERROR - traceback: 'Traceback (most recent call last):\n  File "/home/arthur/.local/lib/python3.8/site-packages/litecli/sqlexecute.py", line 121, in run\n    for result in special.execute(cur, sql):\n  File "/home/arthur/.local/lib/python3.8/site-packages/litecli/packages/special/main.py", line 109, in execute\n    raise CommandNotFound\nlitecli.packages.special.main.CommandNotFound\n\nDuring handling of the above exception, another exception occurred:\n\nTraceback (most recent call last):\n  File "/home/arthur/.local/lib/python3.8/site-packages/litecli/main.py", line 441, in one_iteration\n    for title, cur, headers, status in res:\n  File "/home/arthur/.local/lib/python3.8/site-packages/litecli/sqlexecute.py", line 125, in run\n    cur.execute(sql)\nsqlite3.OperationalError: near "show": syntax error\n'
2020-10-15 08:08:51,681 (4978/MainThread) litecli.main ERROR - sql: '.help', error: OperationalError('near ".": syntax error')
2020-10-15 08:08:51,686 (4978/MainThread) litecli.main ERROR - traceback: 'Traceback (most recent call last):\n  File "/home/arthur/.local/lib/python3.8/site-packages/litecli/sqlexecute.py", line 121, in run\n    for result in special.execute(cur, sql):\n  File "/home/arthur/.local/lib/python3.8/site-packages/litecli/packages/special/main.py", line 109, in execute\n    raise CommandNotFound\nlitecli.packages.special.main.CommandNotFound\n\nDuring handling of the above exception, another exception occurred:\n\nTraceback (most recent call last):\n  File "/home/arthur/.local/lib/python3.8/site-packages/litecli/main.py", line 441, in one_iteration\n    for title, cur, headers, status in res:\n  File "/home/arthur/.local/lib/python3.8/site-packages/litecli/sqlexecute.py", line 125, in run\n    cur.execute(sql)\nsqlite3.OperationalError: near ".": syntax error\n'
2020-10-15 08:08:53,948 (4978/MainThread) litecli.main ERROR - sql: '/help', error: OperationalError('near "/": syntax error')
2020-10-15 08:08:53,949 (4978/MainThread) litecli.main ERROR - traceback: 'Traceback (most recent call last):\n  File "/home/arthur/.local/lib/python3.8/site-packages/litecli/sqlexecute.py", line 121, in run\n    for result in special.execute(cur, sql):\n  File "/home/arthur/.local/lib/python3.8/site-packages/litecli/packages/special/main.py", line 109, in execute\n    raise CommandNotFound\nlitecli.packages.special.main.CommandNotFound\n\nDuring handling of the above exception, another exception occurred:\n\nTraceback (most recent call last):\n  File "/home/arthur/.local/lib/python3.8/site-packages/litecli/main.py", line 441, in one_iteration\n    for title, cur, headers, status in res:\n  File "/home/arthur/.local/lib/python3.8/site-packages/litecli/sqlexecute.py", line 125, in run\n    cur.execute(sql)\nsqlite3.OperationalError: near "/": syntax error\n'
2020-10-15 08:09:28,374 (4978/MainThread) litecli.main ERROR - sql: 'create database', error: OperationalError('near "database": syntax error')
2020-10-15 08:09:28,374 (4978/MainThread) litecli.main ERROR - traceback: 'Traceback (most recent call last):\n  File "/home/arthur/.local/lib/python3.8/site-packages/litecli/sqlexecute.py", line 121, in run\n    for result in special.execute(cur, sql):\n  File "/home/arthur/.local/lib/python3.8/site-packages/litecli/packages/special/main.py", line 109, in execute\n    raise CommandNotFound\nlitecli.packages.special.main.CommandNotFound\n\nDuring handling of the above exception, another exception occurred:\n\nTraceback (most recent call last):\n  File "/home/arthur/.local/lib/python3.8/site-packages/litecli/main.py", line 441, in one_iteration\n    for title, cur, headers, status in res:\n  File "/home/arthur/.local/lib/python3.8/site-packages/litecli/sqlexecute.py", line 125, in run\n    cur.execute(sql)\nsqlite3.OperationalError: near "database": syntax error\n'
2020-10-15 08:09:30,998 (4978/MainThread) litecli.main ERROR - sql: 'create database main', error: OperationalError('near "database": syntax error')
2020-10-15 08:09:30,998 (4978/MainThread) litecli.main ERROR - traceback: 'Traceback (most recent call last):\n  File "/home/arthur/.local/lib/python3.8/site-packages/litecli/sqlexecute.py", line 121, in run\n    for result in special.execute(cur, sql):\n  File "/home/arthur/.local/lib/python3.8/site-packages/litecli/packages/special/main.py", line 109, in execute\n    raise CommandNotFound\nlitecli.packages.special.main.CommandNotFound\n\nDuring handling of the above exception, another exception occurred:\n\nTraceback (most recent call last):\n  File "/home/arthur/.local/lib/python3.8/site-packages/litecli/main.py", line 441, in one_iteration\n    for title, cur, headers, status in res:\n  File "/home/arthur/.local/lib/python3.8/site-packages/litecli/sqlexecute.py", line 125, in run\n    cur.execute(sql)\nsqlite3.OperationalError: near "database": syntax error\n'
2020-10-15 08:09:42,102 (4978/MainThread) litecli.main ERROR - sql: 'create table customers', error: OperationalError('incomplete input')
2020-10-15 08:09:42,102 (4978/MainThread) litecli.main ERROR - traceback: 'Traceback (most recent call last):\n  File "/home/arthur/.local/lib/python3.8/site-packages/litecli/sqlexecute.py", line 121, in run\n    for result in special.execute(cur, sql):\n  File "/home/arthur/.local/lib/python3.8/site-packages/litecli/packages/special/main.py", line 109, in execute\n    raise CommandNotFound\nlitecli.packages.special.main.CommandNotFound\n\nDuring handling of the above exception, another exception occurred:\n\nTraceback (most recent call last):\n  File "/home/arthur/.local/lib/python3.8/site-packages/litecli/main.py", line 441, in one_iteration\n    for title, cur, headers, status in res:\n  File "/home/arthur/.local/lib/python3.8/site-packages/litecli/sqlexecute.py", line 125, in run\n    cur.execute(sql)\nsqlite3.OperationalError: incomplete input\n'
2020-10-15 08:09:43,786 (4978/MainThread) litecli.main ERROR - sql: 'create table customers;', error: OperationalError('incomplete input')
2020-10-15 08:09:43,787 (4978/MainThread) litecli.main ERROR - traceback: 'Traceback (most recent call last):\n  File "/home/arthur/.local/lib/python3.8/site-packages/litecli/sqlexecute.py", line 121, in run\n    for result in special.execute(cur, sql):\n  File "/home/arthur/.local/lib/python3.8/site-packages/litecli/packages/special/main.py", line 109, in execute\n    raise CommandNotFound\nlitecli.packages.special.main.CommandNotFound\n\nDuring handling of the above exception, another exception occurred:\n\nTraceback (most recent call last):\n  File "/home/arthur/.local/lib/python3.8/site-packages/litecli/main.py", line 441, in one_iteration\n    for title, cur, headers, status in res:\n  File "/home/arthur/.local/lib/python3.8/site-packages/litecli/sqlexecute.py", line 125, in run\n    cur.execute(sql)\nsqlite3.OperationalError: incomplete input\n'
2020-10-15 08:10:30,780 (4978/MainThread) litecli.main ERROR - sql: 'create table customers()', error: OperationalError('near ")": syntax error')
2020-10-15 08:10:30,780 (4978/MainThread) litecli.main ERROR - traceback: 'Traceback (most recent call last):\n  File "/home/arthur/.local/lib/python3.8/site-packages/litecli/sqlexecute.py", line 121, in run\n    for result in special.execute(cur, sql):\n  File "/home/arthur/.local/lib/python3.8/site-packages/litecli/packages/special/main.py", line 109, in execute\n    raise CommandNotFound\nlitecli.packages.special.main.CommandNotFound\n\nDuring handling of the above exception, another exception occurred:\n\nTraceback (most recent call last):\n  File "/home/arthur/.local/lib/python3.8/site-packages/litecli/main.py", line 441, in one_iteration\n    for title, cur, headers, status in res:\n  File "/home/arthur/.local/lib/python3.8/site-packages/litecli/sqlexecute.py", line 125, in run\n    cur.execute(sql)\nsqlite3.OperationalError: near ")": syntax error\n'
2020-10-15 08:19:55,293 (4978/MainThread) litecli.main ERROR - sql: 'alter table shit \ndrop column didDogDoThat\n;', error: OperationalError('near "drop": syntax error')
2020-10-15 08:19:55,293 (4978/MainThread) litecli.main ERROR - traceback: 'Traceback (most recent call last):\n  File "/home/arthur/.local/lib/python3.8/site-packages/litecli/sqlexecute.py", line 121, in run\n    for result in special.execute(cur, sql):\n  File "/home/arthur/.local/lib/python3.8/site-packages/litecli/packages/special/main.py", line 109, in execute\n    raise CommandNotFound\nlitecli.packages.special.main.CommandNotFound\n\nDuring handling of the above exception, another exception occurred:\n\nTraceback (most recent call last):\n  File "/home/arthur/.local/lib/python3.8/site-packages/litecli/main.py", line 441, in one_iteration\n    for title, cur, headers, status in res:\n  File "/home/arthur/.local/lib/python3.8/site-packages/litecli/sqlexecute.py", line 125, in run\n    cur.execute(sql)\nsqlite3.OperationalError: near "drop": syntax error\n'
2020-12-25 10:41:08,915 (3225/MainThread) litecli.main ERROR - sql: '/?', error: OperationalError('Not connected to database.')
2020-12-25 10:41:08,924 (3225/MainThread) litecli.main ERROR - traceback: 'Traceback (most recent call last):\n  File "/home/arthur/.local/lib/python3.8/site-packages/litecli/main.py", line 441, in one_iteration\n    for title, cur, headers, status in res:\n  File "/home/arthur/.local/lib/python3.8/site-packages/litecli/sqlexecute.py", line 114, in run\n    raise OperationalError("Not connected to database.")\nsqlite3.OperationalError: Not connected to database.\n'
2020-12-25 10:41:10,298 (3225/MainThread) litecli.main ERROR - sql: '.?', error: OperationalError('Not connected to database.')
2020-12-25 10:41:10,301 (3225/MainThread) litecli.main ERROR - traceback: 'Traceback (most recent call last):\n  File "/home/arthur/.local/lib/python3.8/site-packages/litecli/main.py", line 441, in one_iteration\n    for title, cur, headers, status in res:\n  File "/home/arthur/.local/lib/python3.8/site-packages/litecli/sqlexecute.py", line 114, in run\n    raise OperationalError("Not connected to database.")\nsqlite3.OperationalError: Not connected to database.\n'
2020-12-25 10:41:23,935 (3225/MainThread) litecli.main ERROR - sql: '/?', error: OperationalError('near "/": syntax error')
2020-12-25 10:41:23,942 (3225/MainThread) litecli.main ERROR - traceback: 'Traceback (most recent call last):\n  File "/home/arthur/.local/lib/python3.8/site-packages/litecli/sqlexecute.py", line 121, in run\n    for result in special.execute(cur, sql):\n  File "/home/arthur/.local/lib/python3.8/site-packages/litecli/packages/special/main.py", line 109, in execute\n    raise CommandNotFound\nlitecli.packages.special.main.CommandNotFound\n\nDuring handling of the above exception, another exception occurred:\n\nTraceback (most recent call last):\n  File "/home/arthur/.local/lib/python3.8/site-packages/litecli/main.py", line 441, in one_iteration\n    for title, cur, headers, status in res:\n  File "/home/arthur/.local/lib/python3.8/site-packages/litecli/sqlexecute.py", line 125, in run\n    cur.execute(sql)\nsqlite3.OperationalError: near "/": syntax error\n'
2020-12-25 10:41:24,808 (3225/MainThread) litecli.main ERROR - sql: '.?', error: OperationalError('near ".": syntax error')
2020-12-25 10:41:24,809 (3225/MainThread) litecli.main ERROR - traceback: 'Traceback (most recent call last):\n  File "/home/arthur/.local/lib/python3.8/site-packages/litecli/sqlexecute.py", line 121, in run\n    for result in special.execute(cur, sql):\n  File "/home/arthur/.local/lib/python3.8/site-packages/litecli/packages/special/main.py", line 109, in execute\n    raise CommandNotFound\nlitecli.packages.special.main.CommandNotFound\n\nDuring handling of the above exception, another exception occurred:\n\nTraceback (most recent call last):\n  File "/home/arthur/.local/lib/python3.8/site-packages/litecli/main.py", line 441, in one_iteration\n    for title, cur, headers, status in res:\n  File "/home/arthur/.local/lib/python3.8/site-packages/litecli/sqlexecute.py", line 125, in run\n    cur.execute(sql)\nsqlite3.OperationalError: near ".": syntax error\n'
2020-12-25 10:42:53,784 (3225/MainThread) litecli.main ERROR - sql: 'ls', error: OperationalError('near "ls": syntax error')
2020-12-25 10:42:53,784 (3225/MainThread) litecli.main ERROR - traceback: 'Traceback (most recent call last):\n  File "/home/arthur/.local/lib/python3.8/site-packages/litecli/sqlexecute.py", line 121, in run\n    for result in special.execute(cur, sql):\n  File "/home/arthur/.local/lib/python3.8/site-packages/litecli/packages/special/main.py", line 109, in execute\n    raise CommandNotFound\nlitecli.packages.special.main.CommandNotFound\n\nDuring handling of the above exception, another exception occurred:\n\nTraceback (most recent call last):\n  File "/home/arthur/.local/lib/python3.8/site-packages/litecli/main.py", line 441, in one_iteration\n    for title, cur, headers, status in res:\n  File "/home/arthur/.local/lib/python3.8/site-packages/litecli/sqlexecute.py", line 125, in run\n    cur.execute(sql)\nsqlite3.OperationalError: near "ls": syntax error\n'
2020-12-25 10:43:05,758 (3225/MainThread) litecli.main ERROR - sql: 'varchar', error: OperationalError('near "varchar": syntax error')
2020-12-25 10:43:05,758 (3225/MainThread) litecli.main ERROR - traceback: 'Traceback (most recent call last):\n  File "/home/arthur/.local/lib/python3.8/site-packages/litecli/sqlexecute.py", line 121, in run\n    for result in special.execute(cur, sql):\n  File "/home/arthur/.local/lib/python3.8/site-packages/litecli/packages/special/main.py", line 109, in execute\n    raise CommandNotFound\nlitecli.packages.special.main.CommandNotFound\n\nDuring handling of the above exception, another exception occurred:\n\nTraceback (most recent call last):\n  File "/home/arthur/.local/lib/python3.8/site-packages/litecli/main.py", line 441, in one_iteration\n    for title, cur, headers, status in res:\n  File "/home/arthur/.local/lib/python3.8/site-packages/litecli/sqlexecute.py", line 125, in run\n    cur.execute(sql)\nsqlite3.OperationalError: near "varchar": syntax error\n'
2021-02-07 18:16:30,734 (330252/MainThread) litecli.main ERROR - sql: 'select * from *', error: OperationalError('near "*": syntax error')
2021-02-07 18:16:30,743 (330252/MainThread) litecli.main ERROR - traceback: 'Traceback (most recent call last):\n  File "/home/arthur/.local/lib/python3.9/site-packages/litecli/sqlexecute.py", line 121, in run\n    for result in special.execute(cur, sql):\n  File "/home/arthur/.local/lib/python3.9/site-packages/litecli/packages/special/main.py", line 109, in execute\n    raise CommandNotFound\nlitecli.packages.special.main.CommandNotFound\n\nDuring handling of the above exception, another exception occurred:\n\nTraceback (most recent call last):\n  File "/home/arthur/.local/lib/python3.9/site-packages/litecli/main.py", line 441, in one_iteration\n    for title, cur, headers, status in res:\n  File "/home/arthur/.local/lib/python3.9/site-packages/litecli/sqlexecute.py", line 125, in run\n    cur.execute(sql)\nsqlite3.OperationalError: near "*": syntax error\n'
2021-03-05 08:06:58,313 (311106/MainThread) litecli.main ERROR - sql: 'create database main', error: OperationalError('Not connected to database.')
2021-03-05 08:06:58,321 (311106/MainThread) litecli.main ERROR - traceback: 'Traceback (most recent call last):\n  File "/home/arthur/.local/lib/python3.9/site-packages/litecli/main.py", line 441, in one_iteration\n    for title, cur, headers, status in res:\n  File "/home/arthur/.local/lib/python3.9/site-packages/litecli/sqlexecute.py", line 114, in run\n    raise OperationalError("Not connected to database.")\nsqlite3.OperationalError: Not connected to database.\n'
2021-03-05 08:07:01,542 (311106/MainThread) litecli.main ERROR - sql: '.help', error: OperationalError('Not connected to database.')
2021-03-05 08:07:01,542 (311106/MainThread) litecli.main ERROR - traceback: 'Traceback (most recent call last):\n  File "/home/arthur/.local/lib/python3.9/site-packages/litecli/main.py", line 441, in one_iteration\n    for title, cur, headers, status in res:\n  File "/home/arthur/.local/lib/python3.9/site-packages/litecli/sqlexecute.py", line 114, in run\n    raise OperationalError("Not connected to database.")\nsqlite3.OperationalError: Not connected to database.\n'
2021-03-05 08:08:16,218 (311106/MainThread) litecli.main ERROR - sql: 'ls', error: OperationalError('near "ls": syntax error')
2021-03-05 08:08:16,226 (311106/MainThread) litecli.main ERROR - traceback: 'Traceback (most recent call last):\n  File "/home/arthur/.local/lib/python3.9/site-packages/litecli/sqlexecute.py", line 121, in run\n    for result in special.execute(cur, sql):\n  File "/home/arthur/.local/lib/python3.9/site-packages/litecli/packages/special/main.py", line 109, in execute\n    raise CommandNotFound\nlitecli.packages.special.main.CommandNotFound\n\nDuring handling of the above exception, another exception occurred:\n\nTraceback (most recent call last):\n  File "/home/arthur/.local/lib/python3.9/site-packages/litecli/main.py", line 441, in one_iteration\n    for title, cur, headers, status in res:\n  File "/home/arthur/.local/lib/python3.9/site-packages/litecli/sqlexecute.py", line 125, in run\n    cur.execute(sql)\nsqlite3.OperationalError: near "ls": syntax error\n'
2021-03-05 08:15:31,373 (311380/MainThread) litecli.main ERROR - sql: 'create table people (id int, name varchar(255))', error: OperationalError('table people already exists')
2021-03-05 08:15:31,374 (311380/MainThread) litecli.main ERROR - traceback: 'Traceback (most recent call last):\n  File "/home/arthur/.local/lib/python3.9/site-packages/litecli/sqlexecute.py", line 121, in run\n    for result in special.execute(cur, sql):\n  File "/home/arthur/.local/lib/python3.9/site-packages/litecli/packages/special/main.py", line 109, in execute\n    raise CommandNotFound\nlitecli.packages.special.main.CommandNotFound\n\nDuring handling of the above exception, another exception occurred:\n\nTraceback (most recent call last):\n  File "/home/arthur/.local/lib/python3.9/site-packages/litecli/main.py", line 441, in one_iteration\n    for title, cur, headers, status in res:\n  File "/home/arthur/.local/lib/python3.9/site-packages/litecli/sqlexecute.py", line 125, in run\n    cur.execute(sql)\nsqlite3.OperationalError: table people already exists\n'
2021-03-05 08:15:37,851 (311380/MainThread) litecli.main ERROR - sql: 'show tables;', error: OperationalError('near "show": syntax error')
2021-03-05 08:15:37,851 (311380/MainThread) litecli.main ERROR - traceback: 'Traceback (most recent call last):\n  File "/home/arthur/.local/lib/python3.9/site-packages/litecli/sqlexecute.py", line 121, in run\n    for result in special.execute(cur, sql):\n  File "/home/arthur/.local/lib/python3.9/site-packages/litecli/packages/special/main.py", line 109, in execute\n    raise CommandNotFound\nlitecli.packages.special.main.CommandNotFound\n\nDuring handling of the above exception, another exception occurred:\n\nTraceback (most recent call last):\n  File "/home/arthur/.local/lib/python3.9/site-packages/litecli/main.py", line 441, in one_iteration\n    for title, cur, headers, status in res:\n  File "/home/arthur/.local/lib/python3.9/site-packages/litecli/sqlexecute.py", line 125, in run\n    cur.execute(sql)\nsqlite3.OperationalError: near "show": syntax error\n'
2021-03-05 08:49:24,957 (324262/MainThread) litecli.main ERROR - sql: 'select * from xsql', error: OperationalError("Could not decode to UTF-8 column 'sqltext' with text 'select abs( .11)UNION all\r'")
2021-03-05 08:49:24,958 (324262/MainThread) litecli.main ERROR - traceback: 'Traceback (most recent call last):\n  File "/home/arthur/.local/lib/python3.9/site-packages/litecli/sqlexecute.py", line 121, in run\n    for result in special.execute(cur, sql):\n  File "/home/arthur/.local/lib/python3.9/site-packages/litecli/packages/special/main.py", line 109, in execute\n    raise CommandNotFound\nlitecli.packages.special.main.CommandNotFound\n\nDuring handling of the above exception, another exception occurred:\n\nTraceback (most recent call last):\n  File "/home/arthur/.local/lib/python3.9/site-packages/litecli/main.py", line 441, in one_iteration\n    for title, cur, headers, status in res:\n  File "/home/arthur/.local/lib/python3.9/site-packages/litecli/sqlexecute.py", line 126, in run\n    yield self.get_result(cur)\n  File "/home/arthur/.local/lib/python3.9/site-packages/litecli/sqlexecute.py", line 137, in get_result\n    cursor = list(cursor)\nsqlite3.OperationalError: Could not decode to UTF-8 column \'sqltext\' with text \'select abs( .11)UNION all\r\'\n'
2021-03-05 08:49:46,125 (324262/MainThread) litecli.main ERROR - sql: 'select * from *', error: OperationalError('near "*": syntax error')
2021-03-05 08:49:46,126 (324262/MainThread) litecli.main ERROR - traceback: 'Traceback (most recent call last):\n  File "/home/arthur/.local/lib/python3.9/site-packages/litecli/sqlexecute.py", line 121, in run\n    for result in special.execute(cur, sql):\n  File "/home/arthur/.local/lib/python3.9/site-packages/litecli/packages/special/main.py", line 109, in execute\n    raise CommandNotFound\nlitecli.packages.special.main.CommandNotFound\n\nDuring handling of the above exception, another exception occurred:\n\nTraceback (most recent call last):\n  File "/home/arthur/.local/lib/python3.9/site-packages/litecli/main.py", line 441, in one_iteration\n    for title, cur, headers, status in res:\n  File "/home/arthur/.local/lib/python3.9/site-packages/litecli/sqlexecute.py", line 125, in run\n    cur.execute(sql)\nsqlite3.OperationalError: near "*": syntax error\n'
2021-03-05 08:49:49,417 (324262/MainThread) litecli.main ERROR - sql: "select * from '%'", error: OperationalError('no such table: %')
2021-03-05 08:49:49,417 (324262/MainThread) litecli.main ERROR - traceback: 'Traceback (most recent call last):\n  File "/home/arthur/.local/lib/python3.9/site-packages/litecli/sqlexecute.py", line 121, in run\n    for result in special.execute(cur, sql):\n  File "/home/arthur/.local/lib/python3.9/site-packages/litecli/packages/special/main.py", line 109, in execute\n    raise CommandNotFound\nlitecli.packages.special.main.CommandNotFound\n\nDuring handling of the above exception, another exception occurred:\n\nTraceback (most recent call last):\n  File "/home/arthur/.local/lib/python3.9/site-packages/litecli/main.py", line 441, in one_iteration\n    for title, cur, headers, status in res:\n  File "/home/arthur/.local/lib/python3.9/site-packages/litecli/sqlexecute.py", line 125, in run\n    cur.execute(sql)\nsqlite3.OperationalError: no such table: %\n'
2021-03-05 08:49:50,289 (324262/MainThread) litecli.main ERROR - sql: 'ls', error: OperationalError('near "ls": syntax error')
2021-03-05 08:49:50,290 (324262/MainThread) litecli.main ERROR - traceback: 'Traceback (most recent call last):\n  File "/home/arthur/.local/lib/python3.9/site-packages/litecli/sqlexecute.py", line 121, in run\n    for result in special.execute(cur, sql):\n  File "/home/arthur/.local/lib/python3.9/site-packages/litecli/packages/special/main.py", line 109, in execute\n    raise CommandNotFound\nlitecli.packages.special.main.CommandNotFound\n\nDuring handling of the above exception, another exception occurred:\n\nTraceback (most recent call last):\n  File "/home/arthur/.local/lib/python3.9/site-packages/litecli/main.py", line 441, in one_iteration\n    for title, cur, headers, status in res:\n  File "/home/arthur/.local/lib/python3.9/site-packages/litecli/sqlexecute.py", line 125, in run\n    cur.execute(sql)\nsqlite3.OperationalError: near "ls": syntax error\n'
2021-03-05 08:49:50,833 (324262/MainThread) litecli.main ERROR - sql: 'ls', error: OperationalError('near "ls": syntax error')
2021-03-05 08:49:50,833 (324262/MainThread) litecli.main ERROR - traceback: 'Traceback (most recent call last):\n  File "/home/arthur/.local/lib/python3.9/site-packages/litecli/sqlexecute.py", line 121, in run\n    for result in special.execute(cur, sql):\n  File "/home/arthur/.local/lib/python3.9/site-packages/litecli/packages/special/main.py", line 109, in execute\n    raise CommandNotFound\nlitecli.packages.special.main.CommandNotFound\n\nDuring handling of the above exception, another exception occurred:\n\nTraceback (most recent call last):\n  File "/home/arthur/.local/lib/python3.9/site-packages/litecli/main.py", line 441, in one_iteration\n    for title, cur, headers, status in res:\n  File "/home/arthur/.local/lib/python3.9/site-packages/litecli/sqlexecute.py", line 125, in run\n    cur.execute(sql)\nsqlite3.OperationalError: near "ls": syntax error\n'
2021-03-05 08:49:56,578 (324262/MainThread) litecli.main ERROR - sql: 'select * from xsql', error: OperationalError("Could not decode to UTF-8 column 'sqltext' with text 'select abs( .11)UNION all\r'")
2021-03-05 08:49:56,579 (324262/MainThread) litecli.main ERROR - traceback: 'Traceback (most recent call last):\n  File "/home/arthur/.local/lib/python3.9/site-packages/litecli/sqlexecute.py", line 121, in run\n    for result in special.execute(cur, sql):\n  File "/home/arthur/.local/lib/python3.9/site-packages/litecli/packages/special/main.py", line 109, in execute\n    raise CommandNotFound\nlitecli.packages.special.main.CommandNotFound\n\nDuring handling of the above exception, another exception occurred:\n\nTraceback (most recent call last):\n  File "/home/arthur/.local/lib/python3.9/site-packages/litecli/main.py", line 441, in one_iteration\n    for title, cur, headers, status in res:\n  File "/home/arthur/.local/lib/python3.9/site-packages/litecli/sqlexecute.py", line 126, in run\n    yield self.get_result(cur)\n  File "/home/arthur/.local/lib/python3.9/site-packages/litecli/sqlexecute.py", line 137, in get_result\n    cursor = list(cursor)\nsqlite3.OperationalError: Could not decode to UTF-8 column \'sqltext\' with text \'select abs( .11)UNION all\r\'\n'
2021-03-05 08:49:57,359 (324262/MainThread) litecli.main ERROR - sql: 'ls', error: OperationalError('near "ls": syntax error')
2021-03-05 08:49:57,359 (324262/MainThread) litecli.main ERROR - traceback: 'Traceback (most recent call last):\n  File "/home/arthur/.local/lib/python3.9/site-packages/litecli/sqlexecute.py", line 121, in run\n    for result in special.execute(cur, sql):\n  File "/home/arthur/.local/lib/python3.9/site-packages/litecli/packages/special/main.py", line 109, in execute\n    raise CommandNotFound\nlitecli.packages.special.main.CommandNotFound\n\nDuring handling of the above exception, another exception occurred:\n\nTraceback (most recent call last):\n  File "/home/arthur/.local/lib/python3.9/site-packages/litecli/main.py", line 441, in one_iteration\n    for title, cur, headers, status in res:\n  File "/home/arthur/.local/lib/python3.9/site-packages/litecli/sqlexecute.py", line 125, in run\n    cur.execute(sql)\nsqlite3.OperationalError: near "ls": syntax error\n'
2021-03-05 08:51:37,788 (324348/MainThread) litecli.main ERROR - sql: '.help\n;', error: OperationalError('near ".": syntax error')
2021-03-05 08:51:37,789 (324348/MainThread) litecli.main ERROR - traceback: 'Traceback (most recent call last):\n  File "/home/arthur/.local/lib/python3.9/site-packages/litecli/sqlexecute.py", line 121, in run\n    for result in special.execute(cur, sql):\n  File "/home/arthur/.local/lib/python3.9/site-packages/litecli/packages/special/main.py", line 109, in execute\n    raise CommandNotFound\nlitecli.packages.special.main.CommandNotFound\n\nDuring handling of the above exception, another exception occurred:\n\nTraceback (most recent call last):\n  File "/home/arthur/.local/lib/python3.9/site-packages/litecli/main.py", line 441, in one_iteration\n    for title, cur, headers, status in res:\n  File "/home/arthur/.local/lib/python3.9/site-packages/litecli/sqlexecute.py", line 125, in run\n    cur.execute(sql)\nsqlite3.OperationalError: near ".": syntax error\n'
2021-03-05 08:51:41,527 (324348/MainThread) litecli.main ERROR - sql: '.?', error: OperationalError('near ".": syntax error')
2021-03-05 08:51:41,527 (324348/MainThread) litecli.main ERROR - traceback: 'Traceback (most recent call last):\n  File "/home/arthur/.local/lib/python3.9/site-packages/litecli/sqlexecute.py", line 121, in run\n    for result in special.execute(cur, sql):\n  File "/home/arthur/.local/lib/python3.9/site-packages/litecli/packages/special/main.py", line 109, in execute\n    raise CommandNotFound\nlitecli.packages.special.main.CommandNotFound\n\nDuring handling of the above exception, another exception occurred:\n\nTraceback (most recent call last):\n  File "/home/arthur/.local/lib/python3.9/site-packages/litecli/main.py", line 441, in one_iteration\n    for title, cur, headers, status in res:\n  File "/home/arthur/.local/lib/python3.9/site-packages/litecli/sqlexecute.py", line 125, in run\n    cur.execute(sql)\nsqlite3.OperationalError: near ".": syntax error\n'
2021-03-05 08:51:55,802 (324348/MainThread) litecli.main ERROR - sql: '.header on', error: OperationalError('near ".": syntax error')
2021-03-05 08:51:55,803 (324348/MainThread) litecli.main ERROR - traceback: 'Traceback (most recent call last):\n  File "/home/arthur/.local/lib/python3.9/site-packages/litecli/sqlexecute.py", line 121, in run\n    for result in special.execute(cur, sql):\n  File "/home/arthur/.local/lib/python3.9/site-packages/litecli/packages/special/main.py", line 109, in execute\n    raise CommandNotFound\nlitecli.packages.special.main.CommandNotFound\n\nDuring handling of the above exception, another exception occurred:\n\nTraceback (most recent call last):\n  File "/home/arthur/.local/lib/python3.9/site-packages/litecli/main.py", line 441, in one_iteration\n    for title, cur, headers, status in res:\n  File "/home/arthur/.local/lib/python3.9/site-packages/litecli/sqlexecute.py", line 125, in run\n    cur.execute(sql)\nsqlite3.OperationalError: near ".": syntax error\n'
2021-03-05 08:54:22,027 (324477/MainThread) litecli.main ERROR - sql: 'ls', error: OperationalError('near "ls": syntax error')
2021-03-05 08:54:22,028 (324477/MainThread) litecli.main ERROR - traceback: 'Traceback (most recent call last):\n  File "/home/arthur/.local/lib/python3.9/site-packages/litecli/sqlexecute.py", line 121, in run\n    for result in special.execute(cur, sql):\n  File "/home/arthur/.local/lib/python3.9/site-packages/litecli/packages/special/main.py", line 109, in execute\n    raise CommandNotFound\nlitecli.packages.special.main.CommandNotFound\n\nDuring handling of the above exception, another exception occurred:\n\nTraceback (most recent call last):\n  File "/home/arthur/.local/lib/python3.9/site-packages/litecli/main.py", line 441, in one_iteration\n    for title, cur, headers, status in res:\n  File "/home/arthur/.local/lib/python3.9/site-packages/litecli/sqlexecute.py", line 125, in run\n    cur.execute(sql)\nsqlite3.OperationalError: near "ls": syntax error\n'
2021-03-05 09:01:00,468 (324565/MainThread) litecli.main ERROR - sql: 'null ', error: OperationalError('near "null": syntax error')
2021-03-05 09:01:00,469 (324565/MainThread) litecli.main ERROR - traceback: 'Traceback (most recent call last):\n  File "/home/arthur/.local/lib/python3.9/site-packages/litecli/sqlexecute.py", line 121, in run\n    for result in special.execute(cur, sql):\n  File "/home/arthur/.local/lib/python3.9/site-packages/litecli/packages/special/main.py", line 109, in execute\n    raise CommandNotFound\nlitecli.packages.special.main.CommandNotFound\n\nDuring handling of the above exception, another exception occurred:\n\nTraceback (most recent call last):\n  File "/home/arthur/.local/lib/python3.9/site-packages/litecli/main.py", line 441, in one_iteration\n    for title, cur, headers, status in res:\n  File "/home/arthur/.local/lib/python3.9/site-packages/litecli/sqlexecute.py", line 125, in run\n    cur.execute(sql)\nsqlite3.OperationalError: near "null": syntax error\n'
2021-03-05 09:01:05,166 (324565/MainThread) litecli.main ERROR - sql: 'select cos(2)', error: OperationalError('no such function: cos')
2021-03-05 09:01:05,167 (324565/MainThread) litecli.main ERROR - traceback: 'Traceback (most recent call last):\n  File "/home/arthur/.local/lib/python3.9/site-packages/litecli/sqlexecute.py", line 121, in run\n    for result in special.execute(cur, sql):\n  File "/home/arthur/.local/lib/python3.9/site-packages/litecli/packages/special/main.py", line 109, in execute\n    raise CommandNotFound\nlitecli.packages.special.main.CommandNotFound\n\nDuring handling of the above exception, another exception occurred:\n\nTraceback (most recent call last):\n  File "/home/arthur/.local/lib/python3.9/site-packages/litecli/main.py", line 441, in one_iteration\n    for title, cur, headers, status in res:\n  File "/home/arthur/.local/lib/python3.9/site-packages/litecli/sqlexecute.py", line 125, in run\n    cur.execute(sql)\nsqlite3.OperationalError: no such function: cos\n'
2021-03-05 09:04:12,872 (324565/MainThread) litecli.main ERROR - sql: 'select 2 21 % 2', error: OperationalError('near "21": syntax error')
2021-03-05 09:04:12,872 (324565/MainThread) litecli.main ERROR - traceback: 'Traceback (most recent call last):\n  File "/home/arthur/.local/lib/python3.9/site-packages/litecli/sqlexecute.py", line 121, in run\n    for result in special.execute(cur, sql):\n  File "/home/arthur/.local/lib/python3.9/site-packages/litecli/packages/special/main.py", line 109, in execute\n    raise CommandNotFound\nlitecli.packages.special.main.CommandNotFound\n\nDuring handling of the above exception, another exception occurred:\n\nTraceback (most recent call last):\n  File "/home/arthur/.local/lib/python3.9/site-packages/litecli/main.py", line 441, in one_iteration\n    for title, cur, headers, status in res:\n  File "/home/arthur/.local/lib/python3.9/site-packages/litecli/sqlexecute.py", line 125, in run\n    cur.execute(sql)\nsqlite3.OperationalError: near "21": syntax error\n'
2021-03-05 09:04:27,291 (324565/MainThread) litecli.main ERROR - sql: 'select 2 <<', error: OperationalError('incomplete input')
2021-03-05 09:04:27,292 (324565/MainThread) litecli.main ERROR - traceback: 'Traceback (most recent call last):\n  File "/home/arthur/.local/lib/python3.9/site-packages/litecli/sqlexecute.py", line 121, in run\n    for result in special.execute(cur, sql):\n  File "/home/arthur/.local/lib/python3.9/site-packages/litecli/packages/special/main.py", line 109, in execute\n    raise CommandNotFound\nlitecli.packages.special.main.CommandNotFound\n\nDuring handling of the above exception, another exception occurred:\n\nTraceback (most recent call last):\n  File "/home/arthur/.local/lib/python3.9/site-packages/litecli/main.py", line 441, in one_iteration\n    for title, cur, headers, status in res:\n  File "/home/arthur/.local/lib/python3.9/site-packages/litecli/sqlexecute.py", line 125, in run\n    cur.execute(sql)\nsqlite3.OperationalError: incomplete input\n'
2021-03-05 09:09:11,515 (325017/MainThread) litecli.main ERROR - sql: 'status', error: OperationalError('Not connected to database.')
2021-03-05 09:09:11,515 (325017/MainThread) litecli.main ERROR - traceback: 'Traceback (most recent call last):\n  File "/home/arthur/.local/lib/python3.9/site-packages/litecli/main.py", line 441, in one_iteration\n    for title, cur, headers, status in res:\n  File "/home/arthur/.local/lib/python3.9/site-packages/litecli/sqlexecute.py", line 114, in run\n    raise OperationalError("Not connected to database.")\nsqlite3.OperationalError: Not connected to database.\n'
2021-03-05 09:09:25,790 (325033/MainThread) litecli.main ERROR - sql: 'status', error: OperationalError('near "status": syntax error')
2021-03-05 09:09:25,791 (325033/MainThread) litecli.main ERROR - traceback: 'Traceback (most recent call last):\n  File "/home/arthur/.local/lib/python3.9/site-packages/litecli/sqlexecute.py", line 121, in run\n    for result in special.execute(cur, sql):\n  File "/home/arthur/.local/lib/python3.9/site-packages/litecli/packages/special/main.py", line 109, in execute\n    raise CommandNotFound\nlitecli.packages.special.main.CommandNotFound\n\nDuring handling of the above exception, another exception occurred:\n\nTraceback (most recent call last):\n  File "/home/arthur/.local/lib/python3.9/site-packages/litecli/main.py", line 441, in one_iteration\n    for title, cur, headers, status in res:\n  File "/home/arthur/.local/lib/python3.9/site-packages/litecli/sqlexecute.py", line 125, in run\n    cur.execute(sql)\nsqlite3.OperationalError: near "status": syntax error\n'
2021-03-05 09:09:48,611 (324818/MainThread) litecli.main ERROR - sql: 'create table animals\n(\n  specie varchar(255),\n  status int,\n);', error: OperationalError('near ")": syntax error')
2021-03-05 09:09:48,612 (324818/MainThread) litecli.main ERROR - traceback: 'Traceback (most recent call last):\n  File "/home/arthur/.local/lib/python3.9/site-packages/litecli/sqlexecute.py", line 121, in run\n    for result in special.execute(cur, sql):\n  File "/home/arthur/.local/lib/python3.9/site-packages/litecli/packages/special/main.py", line 109, in execute\n    raise CommandNotFound\nlitecli.packages.special.main.CommandNotFound\n\nDuring handling of the above exception, another exception occurred:\n\nTraceback (most recent call last):\n  File "/home/arthur/.local/lib/python3.9/site-packages/litecli/main.py", line 441, in one_iteration\n    for title, cur, headers, status in res:\n  File "/home/arthur/.local/lib/python3.9/site-packages/litecli/sqlexecute.py", line 125, in run\n    cur.execute(sql)\nsqlite3.OperationalError: near ")": syntax error\n'
2021-03-05 09:12:03,050 (324818/MainThread) litecli.main ERROR - sql: "select 0x1234abcd'", error: OperationalError('unrecognized token: "\'"')
2021-03-05 09:12:03,050 (324818/MainThread) litecli.main ERROR - traceback: 'Traceback (most recent call last):\n  File "/home/arthur/.local/lib/python3.9/site-packages/litecli/sqlexecute.py", line 121, in run\n    for result in special.execute(cur, sql):\n  File "/home/arthur/.local/lib/python3.9/site-packages/litecli/packages/special/main.py", line 109, in execute\n    raise CommandNotFound\nlitecli.packages.special.main.CommandNotFound\n\nDuring handling of the above exception, another exception occurred:\n\nTraceback (most recent call last):\n  File "/home/arthur/.local/lib/python3.9/site-packages/litecli/main.py", line 441, in one_iteration\n    for title, cur, headers, status in res:\n  File "/home/arthur/.local/lib/python3.9/site-packages/litecli/sqlexecute.py", line 125, in run\n    cur.execute(sql)\nsqlite3.OperationalError: unrecognized token: "\'"\n'
2021-03-05 09:16:15,259 (324818/MainThread) litecli.main ERROR - sql: "create table parts (\npart_id int primary key.\nstock int default 0 not null,\ndesc char check( desc !='' ) -- empt sctrings not allowed\n);", error: OperationalError('near ".": syntax error')
2021-03-05 09:16:15,260 (324818/MainThread) litecli.main ERROR - traceback: 'Traceback (most recent call last):\n  File "/home/arthur/.local/lib/python3.9/site-packages/litecli/sqlexecute.py", line 121, in run\n    for result in special.execute(cur, sql):\n  File "/home/arthur/.local/lib/python3.9/site-packages/litecli/packages/special/main.py", line 109, in execute\n    raise CommandNotFound\nlitecli.packages.special.main.CommandNotFound\n\nDuring handling of the above exception, another exception occurred:\n\nTraceback (most recent call last):\n  File "/home/arthur/.local/lib/python3.9/site-packages/litecli/main.py", line 441, in one_iteration\n    for title, cur, headers, status in res:\n  File "/home/arthur/.local/lib/python3.9/site-packages/litecli/sqlexecute.py", line 125, in run\n    cur.execute(sql)\nsqlite3.OperationalError: near ".": syntax error\n'
2021-03-05 09:16:42,324 (325109/MainThread) litecli.main ERROR - sql: 'ls', error: OperationalError('near "ls": syntax error')
2021-03-05 09:16:42,325 (325109/MainThread) litecli.main ERROR - traceback: 'Traceback (most recent call last):\n  File "/home/arthur/.local/lib/python3.9/site-packages/litecli/sqlexecute.py", line 121, in run\n    for result in special.execute(cur, sql):\n  File "/home/arthur/.local/lib/python3.9/site-packages/litecli/packages/special/main.py", line 109, in execute\n    raise CommandNotFound\nlitecli.packages.special.main.CommandNotFound\n\nDuring handling of the above exception, another exception occurred:\n\nTraceback (most recent call last):\n  File "/home/arthur/.local/lib/python3.9/site-packages/litecli/main.py", line 441, in one_iteration\n    for title, cur, headers, status in res:\n  File "/home/arthur/.local/lib/python3.9/site-packages/litecli/sqlexecute.py", line 125, in run\n    cur.execute(sql)\nsqlite3.OperationalError: near "ls": syntax error\n'
2021-03-05 09:17:27,432 (325109/MainThread) litecli.main ERROR - sql: "insert into parts (part_id, stock, desc) values (1, null, '')", error: IntegrityError('NOT NULL constraint failed: parts.stock')
2021-03-05 09:17:27,432 (325109/MainThread) litecli.main ERROR - traceback: 'Traceback (most recent call last):\n  File "/home/arthur/.local/lib/python3.9/site-packages/litecli/sqlexecute.py", line 121, in run\n    for result in special.execute(cur, sql):\n  File "/home/arthur/.local/lib/python3.9/site-packages/litecli/packages/special/main.py", line 109, in execute\n    raise CommandNotFound\nlitecli.packages.special.main.CommandNotFound\n\nDuring handling of the above exception, another exception occurred:\n\nTraceback (most recent call last):\n  File "/home/arthur/.local/lib/python3.9/site-packages/litecli/main.py", line 441, in one_iteration\n    for title, cur, headers, status in res:\n  File "/home/arthur/.local/lib/python3.9/site-packages/litecli/sqlexecute.py", line 125, in run\n    cur.execute(sql)\nsqlite3.IntegrityError: NOT NULL constraint failed: parts.stock\n'
2021-03-05 09:17:34,730 (325109/MainThread) litecli.main ERROR - sql: "insert into parts (part_id, stock, desc) values (1, 2, '')", error: IntegrityError("CHECK constraint failed: desc !=''")
2021-03-05 09:17:34,731 (325109/MainThread) litecli.main ERROR - traceback: 'Traceback (most recent call last):\n  File "/home/arthur/.local/lib/python3.9/site-packages/litecli/sqlexecute.py", line 121, in run\n    for result in special.execute(cur, sql):\n  File "/home/arthur/.local/lib/python3.9/site-packages/litecli/packages/special/main.py", line 109, in execute\n    raise CommandNotFound\nlitecli.packages.special.main.CommandNotFound\n\nDuring handling of the above exception, another exception occurred:\n\nTraceback (most recent call last):\n  File "/home/arthur/.local/lib/python3.9/site-packages/litecli/main.py", line 441, in one_iteration\n    for title, cur, headers, status in res:\n  File "/home/arthur/.local/lib/python3.9/site-packages/litecli/sqlexecute.py", line 125, in run\n    cur.execute(sql)\nsqlite3.IntegrityError: CHECK constraint failed: desc !=\'\'\n'
2021-03-05 09:17:40,539 (325109/MainThread) litecli.main ERROR - sql: 'select * from parts\\', error: OperationalError('unrecognized token: "\\"')
2021-03-05 09:17:40,540 (325109/MainThread) litecli.main ERROR - traceback: 'Traceback (most recent call last):\n  File "/home/arthur/.local/lib/python3.9/site-packages/litecli/sqlexecute.py", line 121, in run\n    for result in special.execute(cur, sql):\n  File "/home/arthur/.local/lib/python3.9/site-packages/litecli/packages/special/main.py", line 109, in execute\n    raise CommandNotFound\nlitecli.packages.special.main.CommandNotFound\n\nDuring handling of the above exception, another exception occurred:\n\nTraceback (most recent call last):\n  File "/home/arthur/.local/lib/python3.9/site-packages/litecli/main.py", line 441, in one_iteration\n    for title, cur, headers, status in res:\n  File "/home/arthur/.local/lib/python3.9/site-packages/litecli/sqlexecute.py", line 125, in run\n    cur.execute(sql)\nsqlite3.OperationalError: unrecognized token: "\\"\n'
2021-03-05 09:17:41,929 (325109/MainThread) litecli.main ERROR - sql: 'select * from parts\\', error: OperationalError('unrecognized token: "\\"')
2021-03-05 09:17:41,929 (325109/MainThread) litecli.main ERROR - traceback: 'Traceback (most recent call last):\n  File "/home/arthur/.local/lib/python3.9/site-packages/litecli/sqlexecute.py", line 121, in run\n    for result in special.execute(cur, sql):\n  File "/home/arthur/.local/lib/python3.9/site-packages/litecli/packages/special/main.py", line 109, in execute\n    raise CommandNotFound\nlitecli.packages.special.main.CommandNotFound\n\nDuring handling of the above exception, another exception occurred:\n\nTraceback (most recent call last):\n  File "/home/arthur/.local/lib/python3.9/site-packages/litecli/main.py", line 441, in one_iteration\n    for title, cur, headers, status in res:\n  File "/home/arthur/.local/lib/python3.9/site-packages/litecli/sqlexecute.py", line 125, in run\n    cur.execute(sql)\nsqlite3.OperationalError: unrecognized token: "\\"\n'
2021-03-05 09:18:14,114 (325109/MainThread) litecli.main ERROR - sql: "insert into parts (part_id, stock, desc) values (1, 2, 'f')", error: IntegrityError('UNIQUE constraint failed: parts.part_id')
2021-03-05 09:18:14,114 (325109/MainThread) litecli.main ERROR - traceback: 'Traceback (most recent call last):\n  File "/home/arthur/.local/lib/python3.9/site-packages/litecli/sqlexecute.py", line 121, in run\n    for result in special.execute(cur, sql):\n  File "/home/arthur/.local/lib/python3.9/site-packages/litecli/packages/special/main.py", line 109, in execute\n    raise CommandNotFound\nlitecli.packages.special.main.CommandNotFound\n\nDuring handling of the above exception, another exception occurred:\n\nTraceback (most recent call last):\n  File "/home/arthur/.local/lib/python3.9/site-packages/litecli/main.py", line 441, in one_iteration\n    for title, cur, headers, status in res:\n  File "/home/arthur/.local/lib/python3.9/site-packages/litecli/sqlexecute.py", line 125, in run\n    cur.execute(sql)\nsqlite3.IntegrityError: UNIQUE constraint failed: parts.part_id\n'
2021-03-05 09:20:23,389 (325200/MainThread) litecli.main ERROR - sql: 'create table parts (', error: OperationalError('incomplete input')
2021-03-05 09:20:23,390 (325200/MainThread) litecli.main ERROR - traceback: 'Traceback (most recent call last):\n  File "/home/arthur/.local/lib/python3.9/site-packages/litecli/sqlexecute.py", line 121, in run\n    for result in special.execute(cur, sql):\n  File "/home/arthur/.local/lib/python3.9/site-packages/litecli/packages/special/main.py", line 109, in execute\n    raise CommandNotFound\nlitecli.packages.special.main.CommandNotFound\n\nDuring handling of the above exception, another exception occurred:\n\nTraceback (most recent call last):\n  File "/home/arthur/.local/lib/python3.9/site-packages/litecli/main.py", line 441, in one_iteration\n    for title, cur, headers, status in res:\n  File "/home/arthur/.local/lib/python3.9/site-packages/litecli/sqlexecute.py", line 125, in run\n    cur.execute(sql)\nsqlite3.OperationalError: incomplete input\n'
2021-03-05 09:20:47,619 (325200/MainThread) litecli.main ERROR - sql: "insert into parts (part_id, stock, desc) values (null, 2, 'f')", error: IntegrityError('NOT NULL constraint failed: parts.part_id')
2021-03-05 09:20:47,619 (325200/MainThread) litecli.main ERROR - traceback: 'Traceback (most recent call last):\n  File "/home/arthur/.local/lib/python3.9/site-packages/litecli/sqlexecute.py", line 121, in run\n    for result in special.execute(cur, sql):\n  File "/home/arthur/.local/lib/python3.9/site-packages/litecli/packages/special/main.py", line 109, in execute\n    raise CommandNotFound\nlitecli.packages.special.main.CommandNotFound\n\nDuring handling of the above exception, another exception occurred:\n\nTraceback (most recent call last):\n  File "/home/arthur/.local/lib/python3.9/site-packages/litecli/main.py", line 441, in one_iteration\n    for title, cur, headers, status in res:\n  File "/home/arthur/.local/lib/python3.9/site-packages/litecli/sqlexecute.py", line 125, in run\n    cur.execute(sql)\nsqlite3.IntegrityError: NOT NULL constraint failed: parts.part_id\n'
2021-03-05 09:28:37,174 (325241/MainThread) litecli.main ERROR - sql: 'create temp table temp1 as select 1 , 3 as num1, num2\n;', error: OperationalError('no such column: num2')
2021-03-05 09:28:37,174 (325241/MainThread) litecli.main ERROR - traceback: 'Traceback (most recent call last):\n  File "/home/arthur/.local/lib/python3.9/site-packages/litecli/sqlexecute.py", line 121, in run\n    for result in special.execute(cur, sql):\n  File "/home/arthur/.local/lib/python3.9/site-packages/litecli/packages/special/main.py", line 109, in execute\n    raise CommandNotFound\nlitecli.packages.special.main.CommandNotFound\n\nDuring handling of the above exception, another exception occurred:\n\nTraceback (most recent call last):\n  File "/home/arthur/.local/lib/python3.9/site-packages/litecli/main.py", line 441, in one_iteration\n    for title, cur, headers, status in res:\n  File "/home/arthur/.local/lib/python3.9/site-packages/litecli/sqlexecute.py", line 125, in run\n    cur.execute(sql)\nsqlite3.OperationalError: no such column: num2\n'
2021-03-05 09:29:10,770 (325241/MainThread) litecli.main ERROR - sql: 'fd', error: OperationalError('near "fd": syntax error')
2021-03-05 09:29:10,770 (325241/MainThread) litecli.main ERROR - traceback: 'Traceback (most recent call last):\n  File "/home/arthur/.local/lib/python3.9/site-packages/litecli/sqlexecute.py", line 121, in run\n    for result in special.execute(cur, sql):\n  File "/home/arthur/.local/lib/python3.9/site-packages/litecli/packages/special/main.py", line 109, in execute\n    raise CommandNotFound\nlitecli.packages.special.main.CommandNotFound\n\nDuring handling of the above exception, another exception occurred:\n\nTraceback (most recent call last):\n  File "/home/arthur/.local/lib/python3.9/site-packages/litecli/main.py", line 441, in one_iteration\n    for title, cur, headers, status in res:\n  File "/home/arthur/.local/lib/python3.9/site-packages/litecli/sqlexecute.py", line 125, in run\n    cur.execute(sql)\nsqlite3.OperationalError: near "fd": syntax error\n'
2021-03-05 09:33:47,859 (325241/MainThread) litecli.main ERROR - sql: "insert into people (id, name) value (3, 'Linus Torvalds');", error: OperationalError('near "value": syntax error')
2021-03-05 09:33:47,860 (325241/MainThread) litecli.main ERROR - traceback: 'Traceback (most recent call last):\n  File "/home/arthur/.local/lib/python3.9/site-packages/litecli/sqlexecute.py", line 121, in run\n    for result in special.execute(cur, sql):\n  File "/home/arthur/.local/lib/python3.9/site-packages/litecli/packages/special/main.py", line 109, in execute\n    raise CommandNotFound\nlitecli.packages.special.main.CommandNotFound\n\nDuring handling of the above exception, another exception occurred:\n\nTraceback (most recent call last):\n  File "/home/arthur/.local/lib/python3.9/site-packages/litecli/main.py", line 441, in one_iteration\n    for title, cur, headers, status in res:\n  File "/home/arthur/.local/lib/python3.9/site-packages/litecli/sqlexecute.py", line 125, in run\n    cur.execute(sql)\nsqlite3.OperationalError: near "value": syntax error\n'
2021-03-05 09:33:57,271 (325241/MainThread) litecli.main ERROR - sql: "insert into people (id, name) value (3, 'Linus Torvalds');", error: OperationalError('near "value": syntax error')
2021-03-05 09:33:57,271 (325241/MainThread) litecli.main ERROR - traceback: 'Traceback (most recent call last):\n  File "/home/arthur/.local/lib/python3.9/site-packages/litecli/sqlexecute.py", line 121, in run\n    for result in special.execute(cur, sql):\n  File "/home/arthur/.local/lib/python3.9/site-packages/litecli/packages/special/main.py", line 109, in execute\n    raise CommandNotFound\nlitecli.packages.special.main.CommandNotFound\n\nDuring handling of the above exception, another exception occurred:\n\nTraceback (most recent call last):\n  File "/home/arthur/.local/lib/python3.9/site-packages/litecli/main.py", line 441, in one_iteration\n    for title, cur, headers, status in res:\n  File "/home/arthur/.local/lib/python3.9/site-packages/litecli/sqlexecute.py", line 125, in run\n    cur.execute(sql)\nsqlite3.OperationalError: near "value": syntax error\n'
2021-03-05 09:39:35,445 (325241/MainThread) litecli.main ERROR - sql: 'select * from idx_people_name', error: OperationalError('no such table: idx_people_name')
2021-03-05 09:39:35,446 (325241/MainThread) litecli.main ERROR - traceback: 'Traceback (most recent call last):\n  File "/home/arthur/.local/lib/python3.9/site-packages/litecli/sqlexecute.py", line 121, in run\n    for result in special.execute(cur, sql):\n  File "/home/arthur/.local/lib/python3.9/site-packages/litecli/packages/special/main.py", line 109, in execute\n    raise CommandNotFound\nlitecli.packages.special.main.CommandNotFound\n\nDuring handling of the above exception, another exception occurred:\n\nTraceback (most recent call last):\n  File "/home/arthur/.local/lib/python3.9/site-packages/litecli/main.py", line 441, in one_iteration\n    for title, cur, headers, status in res:\n  File "/home/arthur/.local/lib/python3.9/site-packages/litecli/sqlexecute.py", line 125, in run\n    cur.execute(sql)\nsqlite3.OperationalError: no such table: idx_people_name\n'
2021-03-05 09:48:38,746 (325241/MainThread) litecli.main ERROR - sql: 'select inf', error: OperationalError('no such column: inf')
2021-03-05 09:48:38,746 (325241/MainThread) litecli.main ERROR - traceback: 'Traceback (most recent call last):\n  File "/home/arthur/.local/lib/python3.9/site-packages/litecli/sqlexecute.py", line 121, in run\n    for result in special.execute(cur, sql):\n  File "/home/arthur/.local/lib/python3.9/site-packages/litecli/packages/special/main.py", line 109, in execute\n    raise CommandNotFound\nlitecli.packages.special.main.CommandNotFound\n\nDuring handling of the above exception, another exception occurred:\n\nTraceback (most recent call last):\n  File "/home/arthur/.local/lib/python3.9/site-packages/litecli/main.py", line 441, in one_iteration\n    for title, cur, headers, status in res:\n  File "/home/arthur/.local/lib/python3.9/site-packages/litecli/sqlexecute.py", line 125, in run\n    cur.execute(sql)\nsqlite3.OperationalError: no such column: inf\n'
2021-03-06 20:57:29,299 (495008/MainThread) litecli.main ERROR - sql: 'create table rooms (', error: OperationalError('incomplete input')
2021-03-06 20:57:29,307 (495008/MainThread) litecli.main ERROR - traceback: 'Traceback (most recent call last):\n  File "/home/arthur/.local/lib/python3.9/site-packages/litecli/sqlexecute.py", line 121, in run\n    for result in special.execute(cur, sql):\n  File "/home/arthur/.local/lib/python3.9/site-packages/litecli/packages/special/main.py", line 109, in execute\n    raise CommandNotFound\nlitecli.packages.special.main.CommandNotFound\n\nDuring handling of the above exception, another exception occurred:\n\nTraceback (most recent call last):\n  File "/home/arthur/.local/lib/python3.9/site-packages/litecli/main.py", line 441, in one_iteration\n    for title, cur, headers, status in res:\n  File "/home/arthur/.local/lib/python3.9/site-packages/litecli/sqlexecute.py", line 125, in run\n    cur.execute(sql)\nsqlite3.OperationalError: incomplete input\n'
2021-03-06 20:58:50,932 (495008/MainThread) litecli.main ERROR - sql: 'create table rooms ( id integer unique autoincrement primary key)', error: OperationalError('near "autoincrement": syntax error')
2021-03-06 20:58:50,933 (495008/MainThread) litecli.main ERROR - traceback: 'Traceback (most recent call last):\n  File "/home/arthur/.local/lib/python3.9/site-packages/litecli/sqlexecute.py", line 121, in run\n    for result in special.execute(cur, sql):\n  File "/home/arthur/.local/lib/python3.9/site-packages/litecli/packages/special/main.py", line 109, in execute\n    raise CommandNotFound\nlitecli.packages.special.main.CommandNotFound\n\nDuring handling of the above exception, another exception occurred:\n\nTraceback (most recent call last):\n  File "/home/arthur/.local/lib/python3.9/site-packages/litecli/main.py", line 441, in one_iteration\n    for title, cur, headers, status in res:\n  File "/home/arthur/.local/lib/python3.9/site-packages/litecli/sqlexecute.py", line 125, in run\n    cur.execute(sql)\nsqlite3.OperationalError: near "autoincrement": syntax error\n'
2021-03-06 21:44:57,166 (498483/MainThread) litecli.main ERROR - sql: 'create table customers (', error: OperationalError('incomplete input')
2021-03-06 21:44:57,168 (498483/MainThread) litecli.main ERROR - traceback: 'Traceback (most recent call last):\n  File "/home/arthur/.local/lib/python3.9/site-packages/litecli/sqlexecute.py", line 121, in run\n    for result in special.execute(cur, sql):\n  File "/home/arthur/.local/lib/python3.9/site-packages/litecli/packages/special/main.py", line 109, in execute\n    raise CommandNotFound\nlitecli.packages.special.main.CommandNotFound\n\nDuring handling of the above exception, another exception occurred:\n\nTraceback (most recent call last):\n  File "/home/arthur/.local/lib/python3.9/site-packages/litecli/main.py", line 441, in one_iteration\n    for title, cur, headers, status in res:\n  File "/home/arthur/.local/lib/python3.9/site-packages/litecli/sqlexecute.py", line 125, in run\n    cur.execute(sql)\nsqlite3.OperationalError: incomplete input\n'
2021-03-06 22:14:14,335 (499741/MainThread) litecli.main ERROR - sql: 'ls', error: OperationalError('near "ls": syntax error')
2021-03-06 22:14:14,336 (499741/MainThread) litecli.main ERROR - traceback: 'Traceback (most recent call last):\n  File "/home/arthur/.local/lib/python3.9/site-packages/litecli/sqlexecute.py", line 121, in run\n    for result in special.execute(cur, sql):\n  File "/home/arthur/.local/lib/python3.9/site-packages/litecli/packages/special/main.py", line 109, in execute\n    raise CommandNotFound\nlitecli.packages.special.main.CommandNotFound\n\nDuring handling of the above exception, another exception occurred:\n\nTraceback (most recent call last):\n  File "/home/arthur/.local/lib/python3.9/site-packages/litecli/main.py", line 441, in one_iteration\n    for title, cur, headers, status in res:\n  File "/home/arthur/.local/lib/python3.9/site-packages/litecli/sqlexecute.py", line 125, in run\n    cur.execute(sql)\nsqlite3.OperationalError: near "ls": syntax error\n'
2021-03-06 22:22:42,887 (500579/MainThread) litecli.main ERROR - sql: 'select card_id from customers where dump', error: OperationalError('no such column: dump')
2021-03-06 22:22:42,888 (500579/MainThread) litecli.main ERROR - traceback: 'Traceback (most recent call last):\n  File "/home/arthur/.local/lib/python3.9/site-packages/litecli/sqlexecute.py", line 121, in run\n    for result in special.execute(cur, sql):\n  File "/home/arthur/.local/lib/python3.9/site-packages/litecli/packages/special/main.py", line 109, in execute\n    raise CommandNotFound\nlitecli.packages.special.main.CommandNotFound\n\nDuring handling of the above exception, another exception occurred:\n\nTraceback (most recent call last):\n  File "/home/arthur/.local/lib/python3.9/site-packages/litecli/main.py", line 441, in one_iteration\n    for title, cur, headers, status in res:\n  File "/home/arthur/.local/lib/python3.9/site-packages/litecli/sqlexecute.py", line 125, in run\n    cur.execute(sql)\nsqlite3.OperationalError: no such column: dump\n'
2021-03-06 22:23:13,849 (500579/MainThread) litecli.main ERROR - sql: 'select card_id from customers having count(*) > 1', error: OperationalError('a GROUP BY clause is required before HAVING')
2021-03-06 22:23:13,849 (500579/MainThread) litecli.main ERROR - traceback: 'Traceback (most recent call last):\n  File "/home/arthur/.local/lib/python3.9/site-packages/litecli/sqlexecute.py", line 121, in run\n    for result in special.execute(cur, sql):\n  File "/home/arthur/.local/lib/python3.9/site-packages/litecli/packages/special/main.py", line 109, in execute\n    raise CommandNotFound\nlitecli.packages.special.main.CommandNotFound\n\nDuring handling of the above exception, another exception occurred:\n\nTraceback (most recent call last):\n  File "/home/arthur/.local/lib/python3.9/site-packages/litecli/main.py", line 441, in one_iteration\n    for title, cur, headers, status in res:\n  File "/home/arthur/.local/lib/python3.9/site-packages/litecli/sqlexecute.py", line 125, in run\n    cur.execute(sql)\nsqlite3.OperationalError: a GROUP BY clause is required before HAVING\n'
2021-03-06 23:30:05,273 (505298/MainThread) litecli.main ERROR - sql: 'create table customers (', error: OperationalError('incomplete input')
2021-03-06 23:30:05,281 (505298/MainThread) litecli.main ERROR - traceback: 'Traceback (most recent call last):\n  File "/home/arthur/.local/lib/python3.9/site-packages/litecli/sqlexecute.py", line 121, in run\n    for result in special.execute(cur, sql):\n  File "/home/arthur/.local/lib/python3.9/site-packages/litecli/packages/special/main.py", line 109, in execute\n    raise CommandNotFound\nlitecli.packages.special.main.CommandNotFound\n\nDuring handling of the above exception, another exception occurred:\n\nTraceback (most recent call last):\n  File "/home/arthur/.local/lib/python3.9/site-packages/litecli/main.py", line 441, in one_iteration\n    for title, cur, headers, status in res:\n  File "/home/arthur/.local/lib/python3.9/site-packages/litecli/sqlexecute.py", line 125, in run\n    cur.execute(sql)\nsqlite3.OperationalError: incomplete input\n'
2021-03-07 00:09:52,959 (507187/MainThread) litecli.main ERROR - sql: 'truncate customers;', error: OperationalError('near "truncate": syntax error')
2021-03-07 00:09:52,960 (507187/MainThread) litecli.main ERROR - traceback: 'Traceback (most recent call last):\n  File "/home/arthur/.local/lib/python3.9/site-packages/litecli/sqlexecute.py", line 121, in run\n    for result in special.execute(cur, sql):\n  File "/home/arthur/.local/lib/python3.9/site-packages/litecli/packages/special/main.py", line 109, in execute\n    raise CommandNotFound\nlitecli.packages.special.main.CommandNotFound\n\nDuring handling of the above exception, another exception occurred:\n\nTraceback (most recent call last):\n  File "/home/arthur/.local/lib/python3.9/site-packages/litecli/main.py", line 441, in one_iteration\n    for title, cur, headers, status in res:\n  File "/home/arthur/.local/lib/python3.9/site-packages/litecli/sqlexecute.py", line 125, in run\n    cur.execute(sql)\nsqlite3.OperationalError: near "truncate": syntax error\n'
2021-03-07 00:22:31,049 (508158/MainThread) litecli.main ERROR - sql: 'select * from stocks;', error: OperationalError('no such table: stocks')
2021-03-07 00:22:31,050 (508158/MainThread) litecli.main ERROR - traceback: 'Traceback (most recent call last):\n  File "/home/arthur/.local/lib/python3.9/site-packages/litecli/sqlexecute.py", line 121, in run\n    for result in special.execute(cur, sql):\n  File "/home/arthur/.local/lib/python3.9/site-packages/litecli/packages/special/main.py", line 109, in execute\n    raise CommandNotFound\nlitecli.packages.special.main.CommandNotFound\n\nDuring handling of the above exception, another exception occurred:\n\nTraceback (most recent call last):\n  File "/home/arthur/.local/lib/python3.9/site-packages/litecli/main.py", line 441, in one_iteration\n    for title, cur, headers, status in res:\n  File "/home/arthur/.local/lib/python3.9/site-packages/litecli/sqlexecute.py", line 125, in run\n    cur.execute(sql)\nsqlite3.OperationalError: no such table: stocks\n'
2021-03-07 10:07:34,497 (509891/MainThread) litecli.main ERROR - sql: 'ls', error: OperationalError('near "ls": syntax error')
2021-03-07 10:07:34,498 (509891/MainThread) litecli.main ERROR - traceback: 'Traceback (most recent call last):\n  File "/home/arthur/.local/lib/python3.9/site-packages/litecli/sqlexecute.py", line 121, in run\n    for result in special.execute(cur, sql):\n  File "/home/arthur/.local/lib/python3.9/site-packages/litecli/packages/special/main.py", line 109, in execute\n    raise CommandNotFound\nlitecli.packages.special.main.CommandNotFound\n\nDuring handling of the above exception, another exception occurred:\n\nTraceback (most recent call last):\n  File "/home/arthur/.local/lib/python3.9/site-packages/litecli/main.py", line 441, in one_iteration\n    for title, cur, headers, status in res:\n  File "/home/arthur/.local/lib/python3.9/site-packages/litecli/sqlexecute.py", line 125, in run\n    cur.execute(sql)\nsqlite3.OperationalError: near "ls": syntax error\n'
2021-03-07 10:55:22,688 (512185/MainThread) litecli.main ERROR - sql: 'select * from customers where count(card_id) > 1', error: OperationalError('misuse of aggregate function count()')
2021-03-07 10:55:22,696 (512185/MainThread) litecli.main ERROR - traceback: 'Traceback (most recent call last):\n  File "/home/arthur/.local/lib/python3.9/site-packages/litecli/sqlexecute.py", line 121, in run\n    for result in special.execute(cur, sql):\n  File "/home/arthur/.local/lib/python3.9/site-packages/litecli/packages/special/main.py", line 109, in execute\n    raise CommandNotFound\nlitecli.packages.special.main.CommandNotFound\n\nDuring handling of the above exception, another exception occurred:\n\nTraceback (most recent call last):\n  File "/home/arthur/.local/lib/python3.9/site-packages/litecli/main.py", line 441, in one_iteration\n    for title, cur, headers, status in res:\n  File "/home/arthur/.local/lib/python3.9/site-packages/litecli/sqlexecute.py", line 125, in run\n    cur.execute(sql)\nsqlite3.OperationalError: misuse of aggregate function count()\n'
2021-03-07 11:40:05,839 (515424/MainThread) litecli.main ERROR - sql: 'ls', error: OperationalError('near "ls": syntax error')
2021-03-07 11:40:05,840 (515424/MainThread) litecli.main ERROR - traceback: 'Traceback (most recent call last):\n  File "/home/arthur/.local/lib/python3.9/site-packages/litecli/sqlexecute.py", line 121, in run\n    for result in special.execute(cur, sql):\n  File "/home/arthur/.local/lib/python3.9/site-packages/litecli/packages/special/main.py", line 109, in execute\n    raise CommandNotFound\nlitecli.packages.special.main.CommandNotFound\n\nDuring handling of the above exception, another exception occurred:\n\nTraceback (most recent call last):\n  File "/home/arthur/.local/lib/python3.9/site-packages/litecli/main.py", line 441, in one_iteration\n    for title, cur, headers, status in res:\n  File "/home/arthur/.local/lib/python3.9/site-packages/litecli/sqlexecute.py", line 125, in run\n    cur.execute(sql)\nsqlite3.OperationalError: near "ls": syntax error\n'
2021-03-07 11:56:39,745 (517478/MainThread) litecli.main ERROR - sql: 'select * from customers where phone_number like ', error: OperationalError('incomplete input')
2021-03-07 11:56:39,746 (517478/MainThread) litecli.main ERROR - traceback: 'Traceback (most recent call last):\n  File "/home/arthur/.local/lib/python3.9/site-packages/litecli/sqlexecute.py", line 121, in run\n    for result in special.execute(cur, sql):\n  File "/home/arthur/.local/lib/python3.9/site-packages/litecli/packages/special/main.py", line 109, in execute\n    raise CommandNotFound\nlitecli.packages.special.main.CommandNotFound\n\nDuring handling of the above exception, another exception occurred:\n\nTraceback (most recent call last):\n  File "/home/arthur/.local/lib/python3.9/site-packages/litecli/main.py", line 441, in one_iteration\n    for title, cur, headers, status in res:\n  File "/home/arthur/.local/lib/python3.9/site-packages/litecli/sqlexecute.py", line 125, in run\n    cur.execute(sql)\nsqlite3.OperationalError: incomplete input\n'
2021-03-07 13:01:51,303 (523913/MainThread) litecli.main ERROR - sql: "select * from customers where phone_number like '4%' name like 'Lisa%'", error: OperationalError('near "name": syntax error')
2021-03-07 13:01:51,307 (523913/MainThread) litecli.main ERROR - traceback: 'Traceback (most recent call last):\n  File "/home/arthur/.local/lib/python3.9/site-packages/litecli/sqlexecute.py", line 121, in run\n    for result in special.execute(cur, sql):\n  File "/home/arthur/.local/lib/python3.9/site-packages/litecli/packages/special/main.py", line 109, in execute\n    raise CommandNotFound\nlitecli.packages.special.main.CommandNotFound\n\nDuring handling of the above exception, another exception occurred:\n\nTraceback (most recent call last):\n  File "/home/arthur/.local/lib/python3.9/site-packages/litecli/main.py", line 441, in one_iteration\n    for title, cur, headers, status in res:\n  File "/home/arthur/.local/lib/python3.9/site-packages/litecli/sqlexecute.py", line 125, in run\n    cur.execute(sql)\nsqlite3.OperationalError: near "name": syntax error\n'
2021-03-08 10:19:26,513 (576672/MainThread) litecli.main ERROR - sql: 'insert into customers values (,"00000","Foo Bar","314-15926535",0,0);', error: OperationalError('near ",": syntax error')
2021-03-08 10:19:26,523 (576672/MainThread) litecli.main ERROR - traceback: 'Traceback (most recent call last):\n  File "/home/arthur/.local/lib/python3.9/site-packages/litecli/sqlexecute.py", line 121, in run\n    for result in special.execute(cur, sql):\n  File "/home/arthur/.local/lib/python3.9/site-packages/litecli/packages/special/main.py", line 109, in execute\n    raise CommandNotFound\nlitecli.packages.special.main.CommandNotFound\n\nDuring handling of the above exception, another exception occurred:\n\nTraceback (most recent call last):\n  File "/home/arthur/.local/lib/python3.9/site-packages/litecli/main.py", line 441, in one_iteration\n    for title, cur, headers, status in res:\n  File "/home/arthur/.local/lib/python3.9/site-packages/litecli/sqlexecute.py", line 125, in run\n    cur.execute(sql)\nsqlite3.OperationalError: near ",": syntax error\n'
2021-03-08 10:19:31,479 (576672/MainThread) litecli.main ERROR - sql: 'insert into customers values ("00000","Foo Bar","314-15926535",0,0);', error: OperationalError('table customers has 6 columns but 5 values were supplied')
2021-03-08 10:19:31,479 (576672/MainThread) litecli.main ERROR - traceback: 'Traceback (most recent call last):\n  File "/home/arthur/.local/lib/python3.9/site-packages/litecli/sqlexecute.py", line 121, in run\n    for result in special.execute(cur, sql):\n  File "/home/arthur/.local/lib/python3.9/site-packages/litecli/packages/special/main.py", line 109, in execute\n    raise CommandNotFound\nlitecli.packages.special.main.CommandNotFound\n\nDuring handling of the above exception, another exception occurred:\n\nTraceback (most recent call last):\n  File "/home/arthur/.local/lib/python3.9/site-packages/litecli/main.py", line 441, in one_iteration\n    for title, cur, headers, status in res:\n  File "/home/arthur/.local/lib/python3.9/site-packages/litecli/sqlexecute.py", line 125, in run\n    cur.execute(sql)\nsqlite3.OperationalError: table customers has 6 columns but 5 values were supplied\n'
2021-03-08 10:20:59,339 (576672/MainThread) litecli.main ERROR - sql: 'select ', error: OperationalError('incomplete input')
2021-03-08 10:20:59,340 (576672/MainThread) litecli.main ERROR - traceback: 'Traceback (most recent call last):\n  File "/home/arthur/.local/lib/python3.9/site-packages/litecli/sqlexecute.py", line 121, in run\n    for result in special.execute(cur, sql):\n  File "/home/arthur/.local/lib/python3.9/site-packages/litecli/packages/special/main.py", line 109, in execute\n    raise CommandNotFound\nlitecli.packages.special.main.CommandNotFound\n\nDuring handling of the above exception, another exception occurred:\n\nTraceback (most recent call last):\n  File "/home/arthur/.local/lib/python3.9/site-packages/litecli/main.py", line 441, in one_iteration\n    for title, cur, headers, status in res:\n  File "/home/arthur/.local/lib/python3.9/site-packages/litecli/sqlexecute.py", line 125, in run\n    cur.execute(sql)\nsqlite3.OperationalError: incomplete input\n'
2021-03-08 10:23:25,272 (576672/MainThread) litecli.main ERROR - sql: 'create table names as select name * from customers', error: OperationalError('near "from": syntax error')
2021-03-08 10:23:25,273 (576672/MainThread) litecli.main ERROR - traceback: 'Traceback (most recent call last):\n  File "/home/arthur/.local/lib/python3.9/site-packages/litecli/sqlexecute.py", line 121, in run\n    for result in special.execute(cur, sql):\n  File "/home/arthur/.local/lib/python3.9/site-packages/litecli/packages/special/main.py", line 109, in execute\n    raise CommandNotFound\nlitecli.packages.special.main.CommandNotFound\n\nDuring handling of the above exception, another exception occurred:\n\nTraceback (most recent call last):\n  File "/home/arthur/.local/lib/python3.9/site-packages/litecli/main.py", line 441, in one_iteration\n    for title, cur, headers, status in res:\n  File "/home/arthur/.local/lib/python3.9/site-packages/litecli/sqlexecute.py", line 125, in run\n    cur.execute(sql)\nsqlite3.OperationalError: near "from": syntax error\n'
2021-03-08 10:24:08,103 (576672/MainThread) litecli.main ERROR - sql: 'create table names as select (name * from customers)', error: OperationalError('near "from": syntax error')
2021-03-08 10:24:08,104 (576672/MainThread) litecli.main ERROR - traceback: 'Traceback (most recent call last):\n  File "/home/arthur/.local/lib/python3.9/site-packages/litecli/sqlexecute.py", line 121, in run\n    for result in special.execute(cur, sql):\n  File "/home/arthur/.local/lib/python3.9/site-packages/litecli/packages/special/main.py", line 109, in execute\n    raise CommandNotFound\nlitecli.packages.special.main.CommandNotFound\n\nDuring handling of the above exception, another exception occurred:\n\nTraceback (most recent call last):\n  File "/home/arthur/.local/lib/python3.9/site-packages/litecli/main.py", line 441, in one_iteration\n    for title, cur, headers, status in res:\n  File "/home/arthur/.local/lib/python3.9/site-packages/litecli/sqlexecute.py", line 125, in run\n    cur.execute(sql)\nsqlite3.OperationalError: near "from": syntax error\n'
2021-03-08 10:28:32,695 (577313/MainThread) litecli.main ERROR - sql: 'select * from names', error: OperationalError('no such table: names')
2021-03-08 10:28:32,696 (577313/MainThread) litecli.main ERROR - traceback: 'Traceback (most recent call last):\n  File "/home/arthur/.local/lib/python3.9/site-packages/litecli/sqlexecute.py", line 121, in run\n    for result in special.execute(cur, sql):\n  File "/home/arthur/.local/lib/python3.9/site-packages/litecli/packages/special/main.py", line 109, in execute\n    raise CommandNotFound\nlitecli.packages.special.main.CommandNotFound\n\nDuring handling of the above exception, another exception occurred:\n\nTraceback (most recent call last):\n  File "/home/arthur/.local/lib/python3.9/site-packages/litecli/main.py", line 441, in one_iteration\n    for title, cur, headers, status in res:\n  File "/home/arthur/.local/lib/python3.9/site-packages/litecli/sqlexecute.py", line 125, in run\n    cur.execute(sql)\nsqlite3.OperationalError: no such table: names\n'
2021-03-08 10:28:34,541 (577313/MainThread) litecli.main ERROR - sql: 'select * from names;', error: OperationalError('no such table: names')
2021-03-08 10:28:34,541 (577313/MainThread) litecli.main ERROR - traceback: 'Traceback (most recent call last):\n  File "/home/arthur/.local/lib/python3.9/site-packages/litecli/sqlexecute.py", line 121, in run\n    for result in special.execute(cur, sql):\n  File "/home/arthur/.local/lib/python3.9/site-packages/litecli/packages/special/main.py", line 109, in execute\n    raise CommandNotFound\nlitecli.packages.special.main.CommandNotFound\n\nDuring handling of the above exception, another exception occurred:\n\nTraceback (most recent call last):\n  File "/home/arthur/.local/lib/python3.9/site-packages/litecli/main.py", line 441, in one_iteration\n    for title, cur, headers, status in res:\n  File "/home/arthur/.local/lib/python3.9/site-packages/litecli/sqlexecute.py", line 125, in run\n    cur.execute(sql)\nsqlite3.OperationalError: no such table: names\n'
2021-03-08 10:32:35,793 (577724/MainThread) litecli.main ERROR - sql: 'select *,', error: OperationalError('incomplete input')
2021-03-08 10:32:35,794 (577724/MainThread) litecli.main ERROR - traceback: 'Traceback (most recent call last):\n  File "/home/arthur/.local/lib/python3.9/site-packages/litecli/sqlexecute.py", line 121, in run\n    for result in special.execute(cur, sql):\n  File "/home/arthur/.local/lib/python3.9/site-packages/litecli/packages/special/main.py", line 109, in execute\n    raise CommandNotFound\nlitecli.packages.special.main.CommandNotFound\n\nDuring handling of the above exception, another exception occurred:\n\nTraceback (most recent call last):\n  File "/home/arthur/.local/lib/python3.9/site-packages/litecli/main.py", line 441, in one_iteration\n    for title, cur, headers, status in res:\n  File "/home/arthur/.local/lib/python3.9/site-packages/litecli/sqlexecute.py", line 125, in run\n    cur.execute(sql)\nsqlite3.OperationalError: incomplete input\n'
2021-03-08 10:36:19,048 (577313/MainThread) litecli.main ERROR - sql: 'select * from name;', error: OperationalError('no such table: name')
2021-03-08 10:36:19,048 (577313/MainThread) litecli.main ERROR - traceback: 'Traceback (most recent call last):\n  File "/home/arthur/.local/lib/python3.9/site-packages/litecli/sqlexecute.py", line 121, in run\n    for result in special.execute(cur, sql):\n  File "/home/arthur/.local/lib/python3.9/site-packages/litecli/packages/special/main.py", line 109, in execute\n    raise CommandNotFound\nlitecli.packages.special.main.CommandNotFound\n\nDuring handling of the above exception, another exception occurred:\n\nTraceback (most recent call last):\n  File "/home/arthur/.local/lib/python3.9/site-packages/litecli/main.py", line 441, in one_iteration\n    for title, cur, headers, status in res:\n  File "/home/arthur/.local/lib/python3.9/site-packages/litecli/sqlexecute.py", line 125, in run\n    cur.execute(sql)\nsqlite3.OperationalError: no such table: name\n'
2021-03-08 10:38:15,962 (577313/MainThread) litecli.main ERROR - sql: 'select name from customers where name is like ', error: OperationalError('no such column: like')
2021-03-08 10:38:15,962 (577313/MainThread) litecli.main ERROR - traceback: 'Traceback (most recent call last):\n  File "/home/arthur/.local/lib/python3.9/site-packages/litecli/sqlexecute.py", line 121, in run\n    for result in special.execute(cur, sql):\n  File "/home/arthur/.local/lib/python3.9/site-packages/litecli/packages/special/main.py", line 109, in execute\n    raise CommandNotFound\nlitecli.packages.special.main.CommandNotFound\n\nDuring handling of the above exception, another exception occurred:\n\nTraceback (most recent call last):\n  File "/home/arthur/.local/lib/python3.9/site-packages/litecli/main.py", line 441, in one_iteration\n    for title, cur, headers, status in res:\n  File "/home/arthur/.local/lib/python3.9/site-packages/litecli/sqlexecute.py", line 125, in run\n    cur.execute(sql)\nsqlite3.OperationalError: no such column: like\n'
2021-03-08 10:38:23,180 (577313/MainThread) litecli.main ERROR - sql: 'select name from customers where name is like "%Richard%"', error: OperationalError('near ""%Richard%"": syntax error')
2021-03-08 10:38:23,180 (577313/MainThread) litecli.main ERROR - traceback: 'Traceback (most recent call last):\n  File "/home/arthur/.local/lib/python3.9/site-packages/litecli/sqlexecute.py", line 121, in run\n    for result in special.execute(cur, sql):\n  File "/home/arthur/.local/lib/python3.9/site-packages/litecli/packages/special/main.py", line 109, in execute\n    raise CommandNotFound\nlitecli.packages.special.main.CommandNotFound\n\nDuring handling of the above exception, another exception occurred:\n\nTraceback (most recent call last):\n  File "/home/arthur/.local/lib/python3.9/site-packages/litecli/main.py", line 441, in one_iteration\n    for title, cur, headers, status in res:\n  File "/home/arthur/.local/lib/python3.9/site-packages/litecli/sqlexecute.py", line 125, in run\n    cur.execute(sql)\nsqlite3.OperationalError: near ""%Richard%"": syntax error\n'
2021-03-08 10:38:29,305 (577313/MainThread) litecli.main ERROR - sql: "select name from customers where name is like '%Richard%'", error: OperationalError('near "\'%Richard%\'": syntax error')
2021-03-08 10:38:29,305 (577313/MainThread) litecli.main ERROR - traceback: 'Traceback (most recent call last):\n  File "/home/arthur/.local/lib/python3.9/site-packages/litecli/sqlexecute.py", line 121, in run\n    for result in special.execute(cur, sql):\n  File "/home/arthur/.local/lib/python3.9/site-packages/litecli/packages/special/main.py", line 109, in execute\n    raise CommandNotFound\nlitecli.packages.special.main.CommandNotFound\n\nDuring handling of the above exception, another exception occurred:\n\nTraceback (most recent call last):\n  File "/home/arthur/.local/lib/python3.9/site-packages/litecli/main.py", line 441, in one_iteration\n    for title, cur, headers, status in res:\n  File "/home/arthur/.local/lib/python3.9/site-packages/litecli/sqlexecute.py", line 125, in run\n    cur.execute(sql)\nsqlite3.OperationalError: near "\'%Richard%\'": syntax error\n'
2021-03-08 15:50:40,302 (577313/MainThread) litecli.main ERROR - sql: 'select top * from customers;', error: OperationalError('near "from": syntax error')
2021-03-08 15:50:40,303 (577313/MainThread) litecli.main ERROR - traceback: 'Traceback (most recent call last):\n  File "/home/arthur/.local/lib/python3.9/site-packages/litecli/sqlexecute.py", line 121, in run\n    for result in special.execute(cur, sql):\n  File "/home/arthur/.local/lib/python3.9/site-packages/litecli/packages/special/main.py", line 109, in execute\n    raise CommandNotFound\nlitecli.packages.special.main.CommandNotFound\n\nDuring handling of the above exception, another exception occurred:\n\nTraceback (most recent call last):\n  File "/home/arthur/.local/lib/python3.9/site-packages/litecli/main.py", line 441, in one_iteration\n    for title, cur, headers, status in res:\n  File "/home/arthur/.local/lib/python3.9/site-packages/litecli/sqlexecute.py", line 125, in run\n    cur.execute(sql)\nsqlite3.OperationalError: near "from": syntax error\n'
2021-03-08 15:50:43,610 (577313/MainThread) litecli.main ERROR - sql: 'select top 1 * from customers;', error: OperationalError('near "1": syntax error')
2021-03-08 15:50:43,610 (577313/MainThread) litecli.main ERROR - traceback: 'Traceback (most recent call last):\n  File "/home/arthur/.local/lib/python3.9/site-packages/litecli/sqlexecute.py", line 121, in run\n    for result in special.execute(cur, sql):\n  File "/home/arthur/.local/lib/python3.9/site-packages/litecli/packages/special/main.py", line 109, in execute\n    raise CommandNotFound\nlitecli.packages.special.main.CommandNotFound\n\nDuring handling of the above exception, another exception occurred:\n\nTraceback (most recent call last):\n  File "/home/arthur/.local/lib/python3.9/site-packages/litecli/main.py", line 441, in one_iteration\n    for title, cur, headers, status in res:\n  File "/home/arthur/.local/lib/python3.9/site-packages/litecli/sqlexecute.py", line 125, in run\n    cur.execute(sql)\nsqlite3.OperationalError: near "1": syntax error\n'
2021-03-08 16:41:39,780 (613845/MainThread) litecli.main ERROR - sql: 'select * from customers where id like all', error: OperationalError('near "all": syntax error')
2021-03-08 16:41:39,781 (613845/MainThread) litecli.main ERROR - traceback: 'Traceback (most recent call last):\n  File "/home/arthur/.local/lib/python3.9/site-packages/litecli/sqlexecute.py", line 121, in run\n    for result in special.execute(cur, sql):\n  File "/home/arthur/.local/lib/python3.9/site-packages/litecli/packages/special/main.py", line 109, in execute\n    raise CommandNotFound\nlitecli.packages.special.main.CommandNotFound\n\nDuring handling of the above exception, another exception occurred:\n\nTraceback (most recent call last):\n  File "/home/arthur/.local/lib/python3.9/site-packages/litecli/main.py", line 441, in one_iteration\n    for title, cur, headers, status in res:\n  File "/home/arthur/.local/lib/python3.9/site-packages/litecli/sqlexecute.py", line 125, in run\n    cur.execute(sql)\nsqlite3.OperationalError: near "all": syntax error\n'
2021-03-08 16:42:36,591 (613845/MainThread) litecli.main ERROR - sql: 'select * from customers where id like \'%%\' and card_id like "%%" and name like "%Tom%', error: OperationalError('unrecognized token: ""%Tom%"')
2021-03-08 16:42:36,592 (613845/MainThread) litecli.main ERROR - traceback: 'Traceback (most recent call last):\n  File "/home/arthur/.local/lib/python3.9/site-packages/litecli/sqlexecute.py", line 121, in run\n    for result in special.execute(cur, sql):\n  File "/home/arthur/.local/lib/python3.9/site-packages/litecli/packages/special/main.py", line 109, in execute\n    raise CommandNotFound\nlitecli.packages.special.main.CommandNotFound\n\nDuring handling of the above exception, another exception occurred:\n\nTraceback (most recent call last):\n  File "/home/arthur/.local/lib/python3.9/site-packages/litecli/main.py", line 441, in one_iteration\n    for title, cur, headers, status in res:\n  File "/home/arthur/.local/lib/python3.9/site-packages/litecli/sqlexecute.py", line 125, in run\n    cur.execute(sql)\nsqlite3.OperationalError: unrecognized token: ""%Tom%"\n'
2021-03-08 16:54:58,592 (613845/MainThread) litecli.main ERROR - sql: "SELECT * FROM customers WHERE and id LIKE '%%' AND card_id LIKE '%%' AND name LIKE '%Tom%'", error: OperationalError('near "and": syntax error')
2021-03-08 16:54:58,592 (613845/MainThread) litecli.main ERROR - traceback: 'Traceback (most recent call last):\n  File "/home/arthur/.local/lib/python3.9/site-packages/litecli/sqlexecute.py", line 121, in run\n    for result in special.execute(cur, sql):\n  File "/home/arthur/.local/lib/python3.9/site-packages/litecli/packages/special/main.py", line 109, in execute\n    raise CommandNotFound\nlitecli.packages.special.main.CommandNotFound\n\nDuring handling of the above exception, another exception occurred:\n\nTraceback (most recent call last):\n  File "/home/arthur/.local/lib/python3.9/site-packages/litecli/main.py", line 441, in one_iteration\n    for title, cur, headers, status in res:\n  File "/home/arthur/.local/lib/python3.9/site-packages/litecli/sqlexecute.py", line 125, in run\n    cur.execute(sql)\nsqlite3.OperationalError: near "and": syntax error\n'
2021-03-08 19:30:41,326 (613845/MainThread) litecli.main ERROR - sql: 'update customers set amount=257 set gift=2  where id=500', error: OperationalError('near "set": syntax error')
2021-03-08 19:30:41,326 (613845/MainThread) litecli.main ERROR - traceback: 'Traceback (most recent call last):\n  File "/home/arthur/.local/lib/python3.9/site-packages/litecli/sqlexecute.py", line 121, in run\n    for result in special.execute(cur, sql):\n  File "/home/arthur/.local/lib/python3.9/site-packages/litecli/packages/special/main.py", line 109, in execute\n    raise CommandNotFound\nlitecli.packages.special.main.CommandNotFound\n\nDuring handling of the above exception, another exception occurred:\n\nTraceback (most recent call last):\n  File "/home/arthur/.local/lib/python3.9/site-packages/litecli/main.py", line 441, in one_iteration\n    for title, cur, headers, status in res:\n  File "/home/arthur/.local/lib/python3.9/site-packages/litecli/sqlexecute.py", line 125, in run\n    cur.execute(sql)\nsqlite3.OperationalError: near "set": syntax error\n'
2021-03-08 19:30:46,498 (613845/MainThread) litecli.main ERROR - sql: 'update customers set amount=257 gift=2  where id=500', error: OperationalError('near "gift": syntax error')
2021-03-08 19:30:46,499 (613845/MainThread) litecli.main ERROR - traceback: 'Traceback (most recent call last):\n  File "/home/arthur/.local/lib/python3.9/site-packages/litecli/sqlexecute.py", line 121, in run\n    for result in special.execute(cur, sql):\n  File "/home/arthur/.local/lib/python3.9/site-packages/litecli/packages/special/main.py", line 109, in execute\n    raise CommandNotFound\nlitecli.packages.special.main.CommandNotFound\n\nDuring handling of the above exception, another exception occurred:\n\nTraceback (most recent call last):\n  File "/home/arthur/.local/lib/python3.9/site-packages/litecli/main.py", line 441, in one_iteration\n    for title, cur, headers, status in res:\n  File "/home/arthur/.local/lib/python3.9/site-packages/litecli/sqlexecute.py", line 125, in run\n    cur.execute(sql)\nsqlite3.OperationalError: near "gift": syntax error\n'
2021-03-08 20:10:32,945 (629637/MainThread) litecli.main ERROR - sql: 'select name from pragma table_info(customers) ', error: OperationalError('near "(": syntax error')
2021-03-08 20:10:32,946 (629637/MainThread) litecli.main ERROR - traceback: 'Traceback (most recent call last):\n  File "/home/arthur/.local/lib/python3.9/site-packages/litecli/sqlexecute.py", line 121, in run\n    for result in special.execute(cur, sql):\n  File "/home/arthur/.local/lib/python3.9/site-packages/litecli/packages/special/main.py", line 109, in execute\n    raise CommandNotFound\nlitecli.packages.special.main.CommandNotFound\n\nDuring handling of the above exception, another exception occurred:\n\nTraceback (most recent call last):\n  File "/home/arthur/.local/lib/python3.9/site-packages/litecli/main.py", line 441, in one_iteration\n    for title, cur, headers, status in res:\n  File "/home/arthur/.local/lib/python3.9/site-packages/litecli/sqlexecute.py", line 125, in run\n    cur.execute(sql)\nsqlite3.OperationalError: near "(": syntax error\n'
2021-03-08 20:10:37,525 (629637/MainThread) litecli.main ERROR - sql: 'select name from (pragma table_info(customers) )', error: OperationalError('near "(": syntax error')
2021-03-08 20:10:37,525 (629637/MainThread) litecli.main ERROR - traceback: 'Traceback (most recent call last):\n  File "/home/arthur/.local/lib/python3.9/site-packages/litecli/sqlexecute.py", line 121, in run\n    for result in special.execute(cur, sql):\n  File "/home/arthur/.local/lib/python3.9/site-packages/litecli/packages/special/main.py", line 109, in execute\n    raise CommandNotFound\nlitecli.packages.special.main.CommandNotFound\n\nDuring handling of the above exception, another exception occurred:\n\nTraceback (most recent call last):\n  File "/home/arthur/.local/lib/python3.9/site-packages/litecli/main.py", line 441, in one_iteration\n    for title, cur, headers, status in res:\n  File "/home/arthur/.local/lib/python3.9/site-packages/litecli/sqlexecute.py", line 125, in run\n    cur.execute(sql)\nsqlite3.OperationalError: near "(": syntax error\n'
2021-03-08 20:10:44,059 (629637/MainThread) litecli.main ERROR - sql: 'select pragma table_info(customers) ', error: OperationalError('near "(": syntax error')
2021-03-08 20:10:44,059 (629637/MainThread) litecli.main ERROR - traceback: 'Traceback (most recent call last):\n  File "/home/arthur/.local/lib/python3.9/site-packages/litecli/sqlexecute.py", line 121, in run\n    for result in special.execute(cur, sql):\n  File "/home/arthur/.local/lib/python3.9/site-packages/litecli/packages/special/main.py", line 109, in execute\n    raise CommandNotFound\nlitecli.packages.special.main.CommandNotFound\n\nDuring handling of the above exception, another exception occurred:\n\nTraceback (most recent call last):\n  File "/home/arthur/.local/lib/python3.9/site-packages/litecli/main.py", line 441, in one_iteration\n    for title, cur, headers, status in res:\n  File "/home/arthur/.local/lib/python3.9/site-packages/litecli/sqlexecute.py", line 125, in run\n    cur.execute(sql)\nsqlite3.OperationalError: near "(": syntax error\n'
2021-03-08 20:10:57,996 (629637/MainThread) litecli.main ERROR - sql: 'pragma table_info(customers) where name=id', error: OperationalError('near "where": syntax error')
2021-03-08 20:10:57,997 (629637/MainThread) litecli.main ERROR - traceback: 'Traceback (most recent call last):\n  File "/home/arthur/.local/lib/python3.9/site-packages/litecli/sqlexecute.py", line 121, in run\n    for result in special.execute(cur, sql):\n  File "/home/arthur/.local/lib/python3.9/site-packages/litecli/packages/special/main.py", line 109, in execute\n    raise CommandNotFound\nlitecli.packages.special.main.CommandNotFound\n\nDuring handling of the above exception, another exception occurred:\n\nTraceback (most recent call last):\n  File "/home/arthur/.local/lib/python3.9/site-packages/litecli/main.py", line 441, in one_iteration\n    for title, cur, headers, status in res:\n  File "/home/arthur/.local/lib/python3.9/site-packages/litecli/sqlexecute.py", line 125, in run\n    cur.execute(sql)\nsqlite3.OperationalError: near "where": syntax error\n'
2021-03-08 21:53:20,749 (637468/MainThread) litecli.main ERROR - sql: 'select * from customers where name like \'%Taylor"', error: OperationalError('unrecognized token: "\'%Taylor""')
2021-03-08 21:53:20,750 (637468/MainThread) litecli.main ERROR - traceback: 'Traceback (most recent call last):\n  File "/home/arthur/.local/lib/python3.9/site-packages/litecli/sqlexecute.py", line 121, in run\n    for result in special.execute(cur, sql):\n  File "/home/arthur/.local/lib/python3.9/site-packages/litecli/packages/special/main.py", line 109, in execute\n    raise CommandNotFound\nlitecli.packages.special.main.CommandNotFound\n\nDuring handling of the above exception, another exception occurred:\n\nTraceback (most recent call last):\n  File "/home/arthur/.local/lib/python3.9/site-packages/litecli/main.py", line 441, in one_iteration\n    for title, cur, headers, status in res:\n  File "/home/arthur/.local/lib/python3.9/site-packages/litecli/sqlexecute.py", line 125, in run\n    cur.execute(sql)\nsqlite3.OperationalError: unrecognized token: "\'%Taylor""\n'
2021-04-13 09:19:22,500 (112169/MainThread) litecli.main ERROR - sql: '.help', error: OperationalError('near ".": syntax error')
2021-04-13 09:19:22,505 (112169/MainThread) litecli.main ERROR - traceback: 'Traceback (most recent call last):\n  File "/home/arthur/.local/lib/python3.9/site-packages/litecli/sqlexecute.py", line 122, in run\n    for result in special.execute(cur, sql):\n  File "/home/arthur/.local/lib/python3.9/site-packages/litecli/packages/special/main.py", line 109, in execute\n    raise CommandNotFound\nlitecli.packages.special.main.CommandNotFound\n\nDuring handling of the above exception, another exception occurred:\n\nTraceback (most recent call last):\n  File "/home/arthur/.local/lib/python3.9/site-packages/litecli/main.py", line 441, in one_iteration\n    for title, cur, headers, status in res:\n  File "/home/arthur/.local/lib/python3.9/site-packages/litecli/sqlexecute.py", line 126, in run\n    cur.execute(sql)\nsqlite3.OperationalError: near ".": syntax error\n'
2021-04-13 09:19:40,526 (112169/MainThread) litecli.main ERROR - sql: '.read s.sql', error: OperationalError('near "INSERT": syntax error')
2021-04-13 09:19:40,534 (112169/MainThread) litecli.main ERROR - traceback: 'Traceback (most recent call last):\n  File "/home/arthur/.local/lib/python3.9/site-packages/litecli/main.py", line 441, in one_iteration\n    for title, cur, headers, status in res:\n  File "/home/arthur/.local/lib/python3.9/site-packages/litecli/sqlexecute.py", line 122, in run\n    for result in special.execute(cur, sql):\n  File "/home/arthur/.local/lib/python3.9/site-packages/litecli/packages/special/main.py", line 121, in execute\n    return special_cmd.handler(cur=cur, arg=arg, verbose=verbose)\n  File "/home/arthur/.local/lib/python3.9/site-packages/litecli/packages/special/dbcommands.py", line 219, in read_script\n    cur.executescript(script)\nsqlite3.OperationalError: near "INSERT": syntax error\n'
2021-04-13 09:19:43,733 (112169/MainThread) litecli.main ERROR - sql: '.read', error: TypeError('.read accepts exactly one path')
2021-04-13 09:19:43,734 (112169/MainThread) litecli.main ERROR - traceback: 'Traceback (most recent call last):\n  File "/home/arthur/.local/lib/python3.9/site-packages/litecli/main.py", line 441, in one_iteration\n    for title, cur, headers, status in res:\n  File "/home/arthur/.local/lib/python3.9/site-packages/litecli/sqlexecute.py", line 122, in run\n    for result in special.execute(cur, sql):\n  File "/home/arthur/.local/lib/python3.9/site-packages/litecli/packages/special/main.py", line 121, in execute\n    return special_cmd.handler(cur=cur, arg=arg, verbose=verbose)\n  File "/home/arthur/.local/lib/python3.9/site-packages/litecli/packages/special/dbcommands.py", line 215, in read_script\n    raise TypeError(".read accepts exactly one path")\nTypeError: .read accepts exactly one path\n'
2021-04-13 09:23:14,099 (112431/MainThread) litecli.main ERROR - sql: 'select `sID`, `sName`,`GPA` \nselect `sID` from student\nexcept\nselect `sID` from apply;', error: OperationalError('near "select": syntax error')
2021-04-13 09:23:14,099 (112431/MainThread) litecli.main ERROR - traceback: 'Traceback (most recent call last):\n  File "/home/arthur/.local/lib/python3.9/site-packages/litecli/sqlexecute.py", line 122, in run\n    for result in special.execute(cur, sql):\n  File "/home/arthur/.local/lib/python3.9/site-packages/litecli/packages/special/main.py", line 109, in execute\n    raise CommandNotFound\nlitecli.packages.special.main.CommandNotFound\n\nDuring handling of the above exception, another exception occurred:\n\nTraceback (most recent call last):\n  File "/home/arthur/.local/lib/python3.9/site-packages/litecli/main.py", line 441, in one_iteration\n    for title, cur, headers, status in res:\n  File "/home/arthur/.local/lib/python3.9/site-packages/litecli/sqlexecute.py", line 126, in run\n    cur.execute(sql)\nsqlite3.OperationalError: near "select": syntax error\n'
2021-04-13 09:23:46,714 (112431/MainThread) litecli.main ERROR - sql: 'select `sID`, `sName`,`GPA`\nfrom (\nselect `sID` from student\nexcept\nselect `sID` from apply\n) noapply, student;', error: OperationalError('ambiguous column name: sID')
2021-04-13 09:23:46,715 (112431/MainThread) litecli.main ERROR - traceback: 'Traceback (most recent call last):\n  File "/home/arthur/.local/lib/python3.9/site-packages/litecli/sqlexecute.py", line 122, in run\n    for result in special.execute(cur, sql):\n  File "/home/arthur/.local/lib/python3.9/site-packages/litecli/packages/special/main.py", line 109, in execute\n    raise CommandNotFound\nlitecli.packages.special.main.CommandNotFound\n\nDuring handling of the above exception, another exception occurred:\n\nTraceback (most recent call last):\n  File "/home/arthur/.local/lib/python3.9/site-packages/litecli/main.py", line 441, in one_iteration\n    for title, cur, headers, status in res:\n  File "/home/arthur/.local/lib/python3.9/site-packages/litecli/sqlexecute.py", line 126, in run\n    cur.execute(sql)\nsqlite3.OperationalError: ambiguous column name: sID\n'
2021-04-13 09:26:22,449 (112431/MainThread) litecli.main ERROR - sql: 'select concat(student.`sID`, `sName`),`GPA`\nfrom (\nselect `sID` from student\nexcept\nselect `sID` from apply\n) noapply, student\nwhere noapply.sID = student.sID;', error: OperationalError('no such function: concat')
2021-04-13 09:26:22,450 (112431/MainThread) litecli.main ERROR - traceback: 'Traceback (most recent call last):\n  File "/home/arthur/.local/lib/python3.9/site-packages/litecli/sqlexecute.py", line 122, in run\n    for result in special.execute(cur, sql):\n  File "/home/arthur/.local/lib/python3.9/site-packages/litecli/packages/special/main.py", line 109, in execute\n    raise CommandNotFound\nlitecli.packages.special.main.CommandNotFound\n\nDuring handling of the above exception, another exception occurred:\n\nTraceback (most recent call last):\n  File "/home/arthur/.local/lib/python3.9/site-packages/litecli/main.py", line 441, in one_iteration\n    for title, cur, headers, status in res:\n  File "/home/arthur/.local/lib/python3.9/site-packages/litecli/sqlexecute.py", line 126, in run\n    cur.execute(sql)\nsqlite3.OperationalError: no such function: concat\n'
2021-04-13 21:58:01,135 (149779/MainThread) litecli.main ERROR - sql: "describe (select datetime('now'))", error: OperationalError('near "(": syntax error')
2021-04-13 21:58:01,136 (149779/MainThread) litecli.main ERROR - traceback: 'Traceback (most recent call last):\n  File "/home/arthur/.local/lib/python3.9/site-packages/litecli/main.py", line 441, in one_iteration\n    for title, cur, headers, status in res:\n  File "/home/arthur/.local/lib/python3.9/site-packages/litecli/sqlexecute.py", line 122, in run\n    for result in special.execute(cur, sql):\n  File "/home/arthur/.local/lib/python3.9/site-packages/litecli/packages/special/main.py", line 121, in execute\n    return special_cmd.handler(cur=cur, arg=arg, verbose=verbose)\n  File "/home/arthur/.local/lib/python3.9/site-packages/litecli/packages/special/dbcommands.py", line 194, in describe\n    cur.execute(query)\nsqlite3.OperationalError: near "(": syntax error\n'
2021-04-13 21:58:05,312 (149779/MainThread) litecli.main ERROR - sql: "describe select datetime('now')", error: OperationalError('near "select": syntax error')
2021-04-13 21:58:05,312 (149779/MainThread) litecli.main ERROR - traceback: 'Traceback (most recent call last):\n  File "/home/arthur/.local/lib/python3.9/site-packages/litecli/main.py", line 441, in one_iteration\n    for title, cur, headers, status in res:\n  File "/home/arthur/.local/lib/python3.9/site-packages/litecli/sqlexecute.py", line 122, in run\n    for result in special.execute(cur, sql):\n  File "/home/arthur/.local/lib/python3.9/site-packages/litecli/packages/special/main.py", line 121, in execute\n    return special_cmd.handler(cur=cur, arg=arg, verbose=verbose)\n  File "/home/arthur/.local/lib/python3.9/site-packages/litecli/packages/special/dbcommands.py", line 194, in describe\n    cur.execute(query)\nsqlite3.OperationalError: near "select": syntax error\n'
2021-04-13 21:58:59,192 (149779/MainThread) litecli.main ERROR - sql: 'select create table dt;', error: OperationalError('near "create": syntax error')
2021-04-13 21:58:59,193 (149779/MainThread) litecli.main ERROR - traceback: 'Traceback (most recent call last):\n  File "/home/arthur/.local/lib/python3.9/site-packages/litecli/sqlexecute.py", line 122, in run\n    for result in special.execute(cur, sql):\n  File "/home/arthur/.local/lib/python3.9/site-packages/litecli/packages/special/main.py", line 109, in execute\n    raise CommandNotFound\nlitecli.packages.special.main.CommandNotFound\n\nDuring handling of the above exception, another exception occurred:\n\nTraceback (most recent call last):\n  File "/home/arthur/.local/lib/python3.9/site-packages/litecli/main.py", line 441, in one_iteration\n    for title, cur, headers, status in res:\n  File "/home/arthur/.local/lib/python3.9/site-packages/litecli/sqlexecute.py", line 126, in run\n    cur.execute(sql)\nsqlite3.OperationalError: near "create": syntax error\n'
2021-04-13 21:59:22,023 (149779/MainThread) litecli.main ERROR - sql: '.table ', error: OperationalError('near ".": syntax error')
2021-04-13 21:59:22,025 (149779/MainThread) litecli.main ERROR - traceback: 'Traceback (most recent call last):\n  File "/home/arthur/.local/lib/python3.9/site-packages/litecli/sqlexecute.py", line 122, in run\n    for result in special.execute(cur, sql):\n  File "/home/arthur/.local/lib/python3.9/site-packages/litecli/packages/special/main.py", line 109, in execute\n    raise CommandNotFound\nlitecli.packages.special.main.CommandNotFound\n\nDuring handling of the above exception, another exception occurred:\n\nTraceback (most recent call last):\n  File "/home/arthur/.local/lib/python3.9/site-packages/litecli/main.py", line 441, in one_iteration\n    for title, cur, headers, status in res:\n  File "/home/arthur/.local/lib/python3.9/site-packages/litecli/sqlexecute.py", line 126, in run\n    cur.execute(sql)\nsqlite3.OperationalError: near ".": syntax error\n'
2021-04-13 21:59:29,053 (149779/MainThread) litecli.main ERROR - sql: '.table dt;', error: OperationalError('near ".": syntax error')
2021-04-13 21:59:29,053 (149779/MainThread) litecli.main ERROR - traceback: 'Traceback (most recent call last):\n  File "/home/arthur/.local/lib/python3.9/site-packages/litecli/sqlexecute.py", line 122, in run\n    for result in special.execute(cur, sql):\n  File "/home/arthur/.local/lib/python3.9/site-packages/litecli/packages/special/main.py", line 109, in execute\n    raise CommandNotFound\nlitecli.packages.special.main.CommandNotFound\n\nDuring handling of the above exception, another exception occurred:\n\nTraceback (most recent call last):\n  File "/home/arthur/.local/lib/python3.9/site-packages/litecli/main.py", line 441, in one_iteration\n    for title, cur, headers, status in res:\n  File "/home/arthur/.local/lib/python3.9/site-packages/litecli/sqlexecute.py", line 126, in run\n    cur.execute(sql)\nsqlite3.OperationalError: near ".": syntax error\n'
2021-04-13 22:01:57,249 (149779/MainThread) litecli.main ERROR - sql: "select  * from (select datetime('now') d;", error: OperationalError('incomplete input')
2021-04-13 22:01:57,249 (149779/MainThread) litecli.main ERROR - traceback: 'Traceback (most recent call last):\n  File "/home/arthur/.local/lib/python3.9/site-packages/litecli/sqlexecute.py", line 122, in run\n    for result in special.execute(cur, sql):\n  File "/home/arthur/.local/lib/python3.9/site-packages/litecli/packages/special/main.py", line 109, in execute\n    raise CommandNotFound\nlitecli.packages.special.main.CommandNotFound\n\nDuring handling of the above exception, another exception occurred:\n\nTraceback (most recent call last):\n  File "/home/arthur/.local/lib/python3.9/site-packages/litecli/main.py", line 441, in one_iteration\n    for title, cur, headers, status in res:\n  File "/home/arthur/.local/lib/python3.9/site-packages/litecli/sqlexecute.py", line 126, in run\n    cur.execute(sql)\nsqlite3.OperationalError: incomplete input\n'
2021-04-13 22:02:33,481 (149779/MainThread) litecli.main ERROR - sql: "select  * from (select datetime('now')) d, (select datetime('now') d2;", error: OperationalError('incomplete input')
2021-04-13 22:02:33,482 (149779/MainThread) litecli.main ERROR - traceback: 'Traceback (most recent call last):\n  File "/home/arthur/.local/lib/python3.9/site-packages/litecli/sqlexecute.py", line 122, in run\n    for result in special.execute(cur, sql):\n  File "/home/arthur/.local/lib/python3.9/site-packages/litecli/packages/special/main.py", line 109, in execute\n    raise CommandNotFound\nlitecli.packages.special.main.CommandNotFound\n\nDuring handling of the above exception, another exception occurred:\n\nTraceback (most recent call last):\n  File "/home/arthur/.local/lib/python3.9/site-packages/litecli/main.py", line 441, in one_iteration\n    for title, cur, headers, status in res:\n  File "/home/arthur/.local/lib/python3.9/site-packages/litecli/sqlexecute.py", line 126, in run\n    cur.execute(sql)\nsqlite3.OperationalError: incomplete input\n'
2021-04-13 22:03:12,791 (149779/MainThread) litecli.main ERROR - sql: "insert into dt values select datetime('now')", error: OperationalError('near "select": syntax error')
2021-04-13 22:03:12,791 (149779/MainThread) litecli.main ERROR - traceback: 'Traceback (most recent call last):\n  File "/home/arthur/.local/lib/python3.9/site-packages/litecli/sqlexecute.py", line 122, in run\n    for result in special.execute(cur, sql):\n  File "/home/arthur/.local/lib/python3.9/site-packages/litecli/packages/special/main.py", line 109, in execute\n    raise CommandNotFound\nlitecli.packages.special.main.CommandNotFound\n\nDuring handling of the above exception, another exception occurred:\n\nTraceback (most recent call last):\n  File "/home/arthur/.local/lib/python3.9/site-packages/litecli/main.py", line 441, in one_iteration\n    for title, cur, headers, status in res:\n  File "/home/arthur/.local/lib/python3.9/site-packages/litecli/sqlexecute.py", line 126, in run\n    cur.execute(sql)\nsqlite3.OperationalError: near "select": syntax error\n'
2021-04-13 22:40:59,281 (150141/MainThread) litecli.main ERROR - sql: 'show tables;', error: OperationalError('near "show": syntax error')
2021-04-13 22:40:59,282 (150141/MainThread) litecli.main ERROR - traceback: 'Traceback (most recent call last):\n  File "/home/arthur/.local/lib/python3.9/site-packages/litecli/sqlexecute.py", line 122, in run\n    for result in special.execute(cur, sql):\n  File "/home/arthur/.local/lib/python3.9/site-packages/litecli/packages/special/main.py", line 109, in execute\n    raise CommandNotFound\nlitecli.packages.special.main.CommandNotFound\n\nDuring handling of the above exception, another exception occurred:\n\nTraceback (most recent call last):\n  File "/home/arthur/.local/lib/python3.9/site-packages/litecli/main.py", line 441, in one_iteration\n    for title, cur, headers, status in res:\n  File "/home/arthur/.local/lib/python3.9/site-packages/litecli/sqlexecute.py", line 126, in run\n    cur.execute(sql)\nsqlite3.OperationalError: near "show": syntax error\n'
2021-04-13 22:53:20,492 (151336/MainThread) litecli.main ERROR - sql: 'show tables;', error: OperationalError('near "show": syntax error')
2021-04-13 22:53:20,493 (151336/MainThread) litecli.main ERROR - traceback: 'Traceback (most recent call last):\n  File "/home/arthur/.local/lib/python3.9/site-packages/litecli/sqlexecute.py", line 122, in run\n    for result in special.execute(cur, sql):\n  File "/home/arthur/.local/lib/python3.9/site-packages/litecli/packages/special/main.py", line 109, in execute\n    raise CommandNotFound\nlitecli.packages.special.main.CommandNotFound\n\nDuring handling of the above exception, another exception occurred:\n\nTraceback (most recent call last):\n  File "/home/arthur/.local/lib/python3.9/site-packages/litecli/main.py", line 441, in one_iteration\n    for title, cur, headers, status in res:\n  File "/home/arthur/.local/lib/python3.9/site-packages/litecli/sqlexecute.py", line 126, in run\n    cur.execute(sql)\nsqlite3.OperationalError: near "show": syntax error\n'
2021-04-13 22:56:15,385 (151539/MainThread) litecli.main ERROR - sql: 'insert into `Customer`', error: OperationalError('incomplete input')
2021-04-13 22:56:15,386 (151539/MainThread) litecli.main ERROR - traceback: 'Traceback (most recent call last):\n  File "/home/arthur/.local/lib/python3.9/site-packages/litecli/sqlexecute.py", line 122, in run\n    for result in special.execute(cur, sql):\n  File "/home/arthur/.local/lib/python3.9/site-packages/litecli/packages/special/main.py", line 109, in execute\n    raise CommandNotFound\nlitecli.packages.special.main.CommandNotFound\n\nDuring handling of the above exception, another exception occurred:\n\nTraceback (most recent call last):\n  File "/home/arthur/.local/lib/python3.9/site-packages/litecli/main.py", line 441, in one_iteration\n    for title, cur, headers, status in res:\n  File "/home/arthur/.local/lib/python3.9/site-packages/litecli/sqlexecute.py", line 126, in run\n    cur.execute(sql)\nsqlite3.OperationalError: incomplete input\n'
2021-04-13 23:06:31,134 (151539/MainThread) litecli.main ERROR - sql: 'insert into `InvoiceLine`\nvalues\n(1,1);', error: OperationalError('table InvoiceLine has 3 columns but 2 values were supplied')
2021-04-13 23:06:31,135 (151539/MainThread) litecli.main ERROR - traceback: 'Traceback (most recent call last):\n  File "/home/arthur/.local/lib/python3.9/site-packages/litecli/sqlexecute.py", line 122, in run\n    for result in special.execute(cur, sql):\n  File "/home/arthur/.local/lib/python3.9/site-packages/litecli/packages/special/main.py", line 109, in execute\n    raise CommandNotFound\nlitecli.packages.special.main.CommandNotFound\n\nDuring handling of the above exception, another exception occurred:\n\nTraceback (most recent call last):\n  File "/home/arthur/.local/lib/python3.9/site-packages/litecli/main.py", line 441, in one_iteration\n    for title, cur, headers, status in res:\n  File "/home/arthur/.local/lib/python3.9/site-packages/litecli/sqlexecute.py", line 126, in run\n    cur.execute(sql)\nsqlite3.OperationalError: table InvoiceLine has 3 columns but 2 values were supplied\n'
2021-04-14 14:14:26,094 (158664/MainThread) litecli.main ERROR - sql: 'drop table if exists test\ncreate table test (id int);', error: OperationalError('near "create": syntax error')
2021-04-14 14:14:26,095 (158664/MainThread) litecli.main ERROR - traceback: 'Traceback (most recent call last):\n  File "/home/arthur/.local/lib/python3.9/site-packages/litecli/sqlexecute.py", line 122, in run\n    for result in special.execute(cur, sql):\n  File "/home/arthur/.local/lib/python3.9/site-packages/litecli/packages/special/main.py", line 109, in execute\n    raise CommandNotFound\nlitecli.packages.special.main.CommandNotFound\n\nDuring handling of the above exception, another exception occurred:\n\nTraceback (most recent call last):\n  File "/home/arthur/.local/lib/python3.9/site-packages/litecli/main.py", line 441, in one_iteration\n    for title, cur, headers, status in res:\n  File "/home/arthur/.local/lib/python3.9/site-packages/litecli/sqlexecute.py", line 126, in run\n    cur.execute(sql)\nsqlite3.OperationalError: near "create": syntax error\n'
2021-04-14 16:34:12,453 (4543/MainThread) litecli.main ERROR - sql: 'select create table `Color`;', error: OperationalError('near "create": syntax error')
2021-04-14 16:34:12,461 (4543/MainThread) litecli.main ERROR - traceback: 'Traceback (most recent call last):\n  File "/home/arthur/.local/lib/python3.9/site-packages/litecli/sqlexecute.py", line 122, in run\n    for result in special.execute(cur, sql):\n  File "/home/arthur/.local/lib/python3.9/site-packages/litecli/packages/special/main.py", line 109, in execute\n    raise CommandNotFound\nlitecli.packages.special.main.CommandNotFound\n\nDuring handling of the above exception, another exception occurred:\n\nTraceback (most recent call last):\n  File "/home/arthur/.local/lib/python3.9/site-packages/litecli/main.py", line 441, in one_iteration\n    for title, cur, headers, status in res:\n  File "/home/arthur/.local/lib/python3.9/site-packages/litecli/sqlexecute.py", line 126, in run\n    cur.execute(sql)\nsqlite3.OperationalError: near "create": syntax error\n'
2021-04-14 16:34:42,290 (4588/MainThread) litecli.main ERROR - sql: '.dump Unit;', error: OperationalError('near ".": syntax error')
2021-04-14 16:34:42,290 (4588/MainThread) litecli.main ERROR - traceback: 'Traceback (most recent call last):\n  File "/home/arthur/.local/lib/python3.9/site-packages/litecli/sqlexecute.py", line 122, in run\n    for result in special.execute(cur, sql):\n  File "/home/arthur/.local/lib/python3.9/site-packages/litecli/packages/special/main.py", line 109, in execute\n    raise CommandNotFound\nlitecli.packages.special.main.CommandNotFound\n\nDuring handling of the above exception, another exception occurred:\n\nTraceback (most recent call last):\n  File "/home/arthur/.local/lib/python3.9/site-packages/litecli/main.py", line 441, in one_iteration\n    for title, cur, headers, status in res:\n  File "/home/arthur/.local/lib/python3.9/site-packages/litecli/sqlexecute.py", line 126, in run\n    cur.execute(sql)\nsqlite3.OperationalError: near ".": syntax error\n'
2021-04-14 17:11:53,580 (5434/MainThread) litecli.main ERROR - sql: 'drop table `Customer`, `CustomerBalance`', error: OperationalError('near ",": syntax error')
2021-04-14 17:11:53,581 (5434/MainThread) litecli.main ERROR - traceback: 'Traceback (most recent call last):\n  File "/home/arthur/.local/lib/python3.9/site-packages/litecli/sqlexecute.py", line 122, in run\n    for result in special.execute(cur, sql):\n  File "/home/arthur/.local/lib/python3.9/site-packages/litecli/packages/special/main.py", line 109, in execute\n    raise CommandNotFound\nlitecli.packages.special.main.CommandNotFound\n\nDuring handling of the above exception, another exception occurred:\n\nTraceback (most recent call last):\n  File "/home/arthur/.local/lib/python3.9/site-packages/litecli/main.py", line 441, in one_iteration\n    for title, cur, headers, status in res:\n  File "/home/arthur/.local/lib/python3.9/site-packages/litecli/sqlexecute.py", line 126, in run\n    cur.execute(sql)\nsqlite3.OperationalError: near ",": syntax error\n'
2021-04-14 17:12:23,363 (5434/MainThread) litecli.main ERROR - sql: 'drop all table;', error: OperationalError('near "all": syntax error')
2021-04-14 17:12:23,363 (5434/MainThread) litecli.main ERROR - traceback: 'Traceback (most recent call last):\n  File "/home/arthur/.local/lib/python3.9/site-packages/litecli/sqlexecute.py", line 122, in run\n    for result in special.execute(cur, sql):\n  File "/home/arthur/.local/lib/python3.9/site-packages/litecli/packages/special/main.py", line 109, in execute\n    raise CommandNotFound\nlitecli.packages.special.main.CommandNotFound\n\nDuring handling of the above exception, another exception occurred:\n\nTraceback (most recent call last):\n  File "/home/arthur/.local/lib/python3.9/site-packages/litecli/main.py", line 441, in one_iteration\n    for title, cur, headers, status in res:\n  File "/home/arthur/.local/lib/python3.9/site-packages/litecli/sqlexecute.py", line 126, in run\n    cur.execute(sql)\nsqlite3.OperationalError: near "all": syntax error\n'
2021-04-14 17:13:01,176 (5434/MainThread) litecli.main ERROR - sql: '||', error: OperationalError('near "||": syntax error')
2021-04-14 17:13:01,176 (5434/MainThread) litecli.main ERROR - traceback: 'Traceback (most recent call last):\n  File "/home/arthur/.local/lib/python3.9/site-packages/litecli/sqlexecute.py", line 122, in run\n    for result in special.execute(cur, sql):\n  File "/home/arthur/.local/lib/python3.9/site-packages/litecli/packages/special/main.py", line 109, in execute\n    raise CommandNotFound\nlitecli.packages.special.main.CommandNotFound\n\nDuring handling of the above exception, another exception occurred:\n\nTraceback (most recent call last):\n  File "/home/arthur/.local/lib/python3.9/site-packages/litecli/main.py", line 441, in one_iteration\n    for title, cur, headers, status in res:\n  File "/home/arthur/.local/lib/python3.9/site-packages/litecli/sqlexecute.py", line 126, in run\n    cur.execute(sql)\nsqlite3.OperationalError: near "||": syntax error\n'
2021-04-14 23:10:48,451 (27165/MainThread) litecli.main ERROR - sql: 'describe `Customer` natural join `InvoiceLine`;', error: OperationalError('near "natural": syntax error')
2021-04-14 23:10:48,459 (27165/MainThread) litecli.main ERROR - traceback: 'Traceback (most recent call last):\n  File "/home/arthur/.local/lib/python3.9/site-packages/litecli/main.py", line 441, in one_iteration\n    for title, cur, headers, status in res:\n  File "/home/arthur/.local/lib/python3.9/site-packages/litecli/sqlexecute.py", line 122, in run\n    for result in special.execute(cur, sql):\n  File "/home/arthur/.local/lib/python3.9/site-packages/litecli/packages/special/main.py", line 121, in execute\n    return special_cmd.handler(cur=cur, arg=arg, verbose=verbose)\n  File "/home/arthur/.local/lib/python3.9/site-packages/litecli/packages/special/dbcommands.py", line 194, in describe\n    cur.execute(query)\nsqlite3.OperationalError: near "natural": syntax error\n'
2021-04-14 23:15:04,984 (28139/MainThread) litecli.main ERROR - sql: 'select *', error: OperationalError('no tables specified')
2021-04-14 23:15:04,985 (28139/MainThread) litecli.main ERROR - traceback: 'Traceback (most recent call last):\n  File "/home/arthur/.local/lib/python3.9/site-packages/litecli/sqlexecute.py", line 122, in run\n    for result in special.execute(cur, sql):\n  File "/home/arthur/.local/lib/python3.9/site-packages/litecli/packages/special/main.py", line 109, in execute\n    raise CommandNotFound\nlitecli.packages.special.main.CommandNotFound\n\nDuring handling of the above exception, another exception occurred:\n\nTraceback (most recent call last):\n  File "/home/arthur/.local/lib/python3.9/site-packages/litecli/main.py", line 441, in one_iteration\n    for title, cur, headers, status in res:\n  File "/home/arthur/.local/lib/python3.9/site-packages/litecli/sqlexecute.py", line 126, in run\n    cur.execute(sql)\nsqlite3.OperationalError: no tables specified\n'
2021-04-14 23:15:36,497 (28139/MainThread) litecli.main ERROR - sql: 'select *\nfrom `A` join `B` using(c);', error: OperationalError('cannot join using column c - column not present in both tables')
2021-04-14 23:15:36,500 (28139/MainThread) litecli.main ERROR - traceback: 'Traceback (most recent call last):\n  File "/home/arthur/.local/lib/python3.9/site-packages/litecli/sqlexecute.py", line 122, in run\n    for result in special.execute(cur, sql):\n  File "/home/arthur/.local/lib/python3.9/site-packages/litecli/packages/special/main.py", line 109, in execute\n    raise CommandNotFound\nlitecli.packages.special.main.CommandNotFound\n\nDuring handling of the above exception, another exception occurred:\n\nTraceback (most recent call last):\n  File "/home/arthur/.local/lib/python3.9/site-packages/litecli/main.py", line 441, in one_iteration\n    for title, cur, headers, status in res:\n  File "/home/arthur/.local/lib/python3.9/site-packages/litecli/sqlexecute.py", line 126, in run\n    cur.execute(sql)\nsqlite3.OperationalError: cannot join using column c - column not present in both tables\n'
2021-04-14 23:16:10,188 (28139/MainThread) litecli.main ERROR - sql: 'select *\nfrom `A` join `B` on c = d;', error: OperationalError('no such column: d')
2021-04-14 23:16:10,191 (28139/MainThread) litecli.main ERROR - traceback: 'Traceback (most recent call last):\n  File "/home/arthur/.local/lib/python3.9/site-packages/litecli/sqlexecute.py", line 122, in run\n    for result in special.execute(cur, sql):\n  File "/home/arthur/.local/lib/python3.9/site-packages/litecli/packages/special/main.py", line 109, in execute\n    raise CommandNotFound\nlitecli.packages.special.main.CommandNotFound\n\nDuring handling of the above exception, another exception occurred:\n\nTraceback (most recent call last):\n  File "/home/arthur/.local/lib/python3.9/site-packages/litecli/main.py", line 441, in one_iteration\n    for title, cur, headers, status in res:\n  File "/home/arthur/.local/lib/python3.9/site-packages/litecli/sqlexecute.py", line 126, in run\n    cur.execute(sql)\nsqlite3.OperationalError: no such column: d\n'
2021-04-14 23:17:53,722 (28139/MainThread) litecli.main ERROR - sql: 'select *\nfrom `A` full join `B` on c = e;', error: OperationalError('RIGHT and FULL OUTER JOINs are not currently supported')
2021-04-14 23:17:53,722 (28139/MainThread) litecli.main ERROR - traceback: 'Traceback (most recent call last):\n  File "/home/arthur/.local/lib/python3.9/site-packages/litecli/sqlexecute.py", line 122, in run\n    for result in special.execute(cur, sql):\n  File "/home/arthur/.local/lib/python3.9/site-packages/litecli/packages/special/main.py", line 109, in execute\n    raise CommandNotFound\nlitecli.packages.special.main.CommandNotFound\n\nDuring handling of the above exception, another exception occurred:\n\nTraceback (most recent call last):\n  File "/home/arthur/.local/lib/python3.9/site-packages/litecli/main.py", line 441, in one_iteration\n    for title, cur, headers, status in res:\n  File "/home/arthur/.local/lib/python3.9/site-packages/litecli/sqlexecute.py", line 126, in run\n    cur.execute(sql)\nsqlite3.OperationalError: RIGHT and FULL OUTER JOINs are not currently supported\n'
2021-04-14 23:18:03,531 (28139/MainThread) litecli.main ERROR - sql: 'select *\nfrom `A` full inner join `B` on c = e;', error: OperationalError('unknown or unsupported join type: full inner')
2021-04-14 23:18:03,531 (28139/MainThread) litecli.main ERROR - traceback: 'Traceback (most recent call last):\n  File "/home/arthur/.local/lib/python3.9/site-packages/litecli/sqlexecute.py", line 122, in run\n    for result in special.execute(cur, sql):\n  File "/home/arthur/.local/lib/python3.9/site-packages/litecli/packages/special/main.py", line 109, in execute\n    raise CommandNotFound\nlitecli.packages.special.main.CommandNotFound\n\nDuring handling of the above exception, another exception occurred:\n\nTraceback (most recent call last):\n  File "/home/arthur/.local/lib/python3.9/site-packages/litecli/main.py", line 441, in one_iteration\n    for title, cur, headers, status in res:\n  File "/home/arthur/.local/lib/python3.9/site-packages/litecli/sqlexecute.py", line 126, in run\n    cur.execute(sql)\nsqlite3.OperationalError: unknown or unsupported join type: full inner\n'
2021-04-14 23:18:10,187 (28139/MainThread) litecli.main ERROR - sql: 'select *\nfrom `A` right join `B` on c = e;', error: OperationalError('RIGHT and FULL OUTER JOINs are not currently supported')
2021-04-14 23:18:10,188 (28139/MainThread) litecli.main ERROR - traceback: 'Traceback (most recent call last):\n  File "/home/arthur/.local/lib/python3.9/site-packages/litecli/sqlexecute.py", line 122, in run\n    for result in special.execute(cur, sql):\n  File "/home/arthur/.local/lib/python3.9/site-packages/litecli/packages/special/main.py", line 109, in execute\n    raise CommandNotFound\nlitecli.packages.special.main.CommandNotFound\n\nDuring handling of the above exception, another exception occurred:\n\nTraceback (most recent call last):\n  File "/home/arthur/.local/lib/python3.9/site-packages/litecli/main.py", line 441, in one_iteration\n    for title, cur, headers, status in res:\n  File "/home/arthur/.local/lib/python3.9/site-packages/litecli/sqlexecute.py", line 126, in run\n    cur.execute(sql)\nsqlite3.OperationalError: RIGHT and FULL OUTER JOINs are not currently supported\n'
2021-04-14 23:20:39,736 (28139/MainThread) litecli.main ERROR - sql: 'create table customer (\nid int primary key autoincrement,\nname text\n);', error: OperationalError('AUTOINCREMENT is only allowed on an INTEGER PRIMARY KEY')
2021-04-14 23:20:39,739 (28139/MainThread) litecli.main ERROR - traceback: 'Traceback (most recent call last):\n  File "/home/arthur/.local/lib/python3.9/site-packages/litecli/sqlexecute.py", line 122, in run\n    for result in special.execute(cur, sql):\n  File "/home/arthur/.local/lib/python3.9/site-packages/litecli/packages/special/main.py", line 109, in execute\n    raise CommandNotFound\nlitecli.packages.special.main.CommandNotFound\n\nDuring handling of the above exception, another exception occurred:\n\nTraceback (most recent call last):\n  File "/home/arthur/.local/lib/python3.9/site-packages/litecli/main.py", line 441, in one_iteration\n    for title, cur, headers, status in res:\n  File "/home/arthur/.local/lib/python3.9/site-packages/litecli/sqlexecute.py", line 126, in run\n    cur.execute(sql)\nsqlite3.OperationalError: AUTOINCREMENT is only allowed on an INTEGER PRIMARY KEY\n'
2021-04-14 23:22:49,565 (28139/MainThread) litecli.main ERROR - sql: 'insert into customer values (name="Arthur")\n;', error: OperationalError('no such column: name')
2021-04-14 23:22:49,565 (28139/MainThread) litecli.main ERROR - traceback: 'Traceback (most recent call last):\n  File "/home/arthur/.local/lib/python3.9/site-packages/litecli/sqlexecute.py", line 122, in run\n    for result in special.execute(cur, sql):\n  File "/home/arthur/.local/lib/python3.9/site-packages/litecli/packages/special/main.py", line 109, in execute\n    raise CommandNotFound\nlitecli.packages.special.main.CommandNotFound\n\nDuring handling of the above exception, another exception occurred:\n\nTraceback (most recent call last):\n  File "/home/arthur/.local/lib/python3.9/site-packages/litecli/main.py", line 441, in one_iteration\n    for title, cur, headers, status in res:\n  File "/home/arthur/.local/lib/python3.9/site-packages/litecli/sqlexecute.py", line 126, in run\n    cur.execute(sql)\nsqlite3.OperationalError: no such column: name\n'
2021-04-14 23:23:26,796 (28139/MainThread) litecli.main ERROR - sql: 'insert into customer (name) values (name="Arthur");', error: OperationalError('no such column: name')
2021-04-14 23:23:26,796 (28139/MainThread) litecli.main ERROR - traceback: 'Traceback (most recent call last):\n  File "/home/arthur/.local/lib/python3.9/site-packages/litecli/sqlexecute.py", line 122, in run\n    for result in special.execute(cur, sql):\n  File "/home/arthur/.local/lib/python3.9/site-packages/litecli/packages/special/main.py", line 109, in execute\n    raise CommandNotFound\nlitecli.packages.special.main.CommandNotFound\n\nDuring handling of the above exception, another exception occurred:\n\nTraceback (most recent call last):\n  File "/home/arthur/.local/lib/python3.9/site-packages/litecli/main.py", line 441, in one_iteration\n    for title, cur, headers, status in res:\n  File "/home/arthur/.local/lib/python3.9/site-packages/litecli/sqlexecute.py", line 126, in run\n    cur.execute(sql)\nsqlite3.OperationalError: no such column: name\n'
2021-04-14 23:36:06,546 (29069/MainThread) litecli.main ERROR - sql: '.', error: OperationalError('near ".": syntax error')
2021-04-14 23:36:06,547 (29069/MainThread) litecli.main ERROR - traceback: 'Traceback (most recent call last):\n  File "/home/arthur/.local/lib/python3.9/site-packages/litecli/sqlexecute.py", line 122, in run\n    for result in special.execute(cur, sql):\n  File "/home/arthur/.local/lib/python3.9/site-packages/litecli/packages/special/main.py", line 109, in execute\n    raise CommandNotFound\nlitecli.packages.special.main.CommandNotFound\n\nDuring handling of the above exception, another exception occurred:\n\nTraceback (most recent call last):\n  File "/home/arthur/.local/lib/python3.9/site-packages/litecli/main.py", line 441, in one_iteration\n    for title, cur, headers, status in res:\n  File "/home/arthur/.local/lib/python3.9/site-packages/litecli/sqlexecute.py", line 126, in run\n    cur.execute(sql)\nsqlite3.OperationalError: near ".": syntax error\n'
2021-04-14 23:36:27,834 (29069/MainThread) litecli.main ERROR - sql: 'select * from albums, artists,album_artists,', error: OperationalError('incomplete input')
2021-04-14 23:36:27,834 (29069/MainThread) litecli.main ERROR - traceback: 'Traceback (most recent call last):\n  File "/home/arthur/.local/lib/python3.9/site-packages/litecli/sqlexecute.py", line 122, in run\n    for result in special.execute(cur, sql):\n  File "/home/arthur/.local/lib/python3.9/site-packages/litecli/packages/special/main.py", line 109, in execute\n    raise CommandNotFound\nlitecli.packages.special.main.CommandNotFound\n\nDuring handling of the above exception, another exception occurred:\n\nTraceback (most recent call last):\n  File "/home/arthur/.local/lib/python3.9/site-packages/litecli/main.py", line 441, in one_iteration\n    for title, cur, headers, status in res:\n  File "/home/arthur/.local/lib/python3.9/site-packages/litecli/sqlexecute.py", line 126, in run\n    cur.execute(sql)\nsqlite3.OperationalError: incomplete input\n'
2021-04-14 23:53:33,466 (28139/MainThread) litecli.main ERROR - sql: 'select exists cus', error: OperationalError('near "cus": syntax error')
2021-04-14 23:53:33,467 (28139/MainThread) litecli.main ERROR - traceback: 'Traceback (most recent call last):\n  File "/home/arthur/.local/lib/python3.9/site-packages/litecli/sqlexecute.py", line 122, in run\n    for result in special.execute(cur, sql):\n  File "/home/arthur/.local/lib/python3.9/site-packages/litecli/packages/special/main.py", line 109, in execute\n    raise CommandNotFound\nlitecli.packages.special.main.CommandNotFound\n\nDuring handling of the above exception, another exception occurred:\n\nTraceback (most recent call last):\n  File "/home/arthur/.local/lib/python3.9/site-packages/litecli/main.py", line 441, in one_iteration\n    for title, cur, headers, status in res:\n  File "/home/arthur/.local/lib/python3.9/site-packages/litecli/sqlexecute.py", line 126, in run\n    cur.execute(sql)\nsqlite3.OperationalError: near "cus": syntax error\n'
2021-04-15 01:01:56,519 (34114/MainThread) litecli.main ERROR - sql: 'delete from `Customer` where `Name` = "Arthur";', error: OperationalError('no such column: Name')
2021-04-15 01:01:56,520 (34114/MainThread) litecli.main ERROR - traceback: 'Traceback (most recent call last):\n  File "/home/arthur/.local/lib/python3.9/site-packages/litecli/sqlexecute.py", line 122, in run\n    for result in special.execute(cur, sql):\n  File "/home/arthur/.local/lib/python3.9/site-packages/litecli/packages/special/main.py", line 109, in execute\n    raise CommandNotFound\nlitecli.packages.special.main.CommandNotFound\n\nDuring handling of the above exception, another exception occurred:\n\nTraceback (most recent call last):\n  File "/home/arthur/.local/lib/python3.9/site-packages/litecli/main.py", line 441, in one_iteration\n    for title, cur, headers, status in res:\n  File "/home/arthur/.local/lib/python3.9/site-packages/litecli/sqlexecute.py", line 126, in run\n    cur.execute(sql)\nsqlite3.OperationalError: no such column: Name\n'
2021-04-15 01:09:37,559 (34226/MainThread) litecli.main ERROR - sql: 'delete from `Customer` where customer_name = Arthur;', error: OperationalError('no such column: Arthur')
2021-04-15 01:09:37,560 (34226/MainThread) litecli.main ERROR - traceback: 'Traceback (most recent call last):\n  File "/home/arthur/.local/lib/python3.9/site-packages/litecli/sqlexecute.py", line 122, in run\n    for result in special.execute(cur, sql):\n  File "/home/arthur/.local/lib/python3.9/site-packages/litecli/packages/special/main.py", line 109, in execute\n    raise CommandNotFound\nlitecli.packages.special.main.CommandNotFound\n\nDuring handling of the above exception, another exception occurred:\n\nTraceback (most recent call last):\n  File "/home/arthur/.local/lib/python3.9/site-packages/litecli/main.py", line 441, in one_iteration\n    for title, cur, headers, status in res:\n  File "/home/arthur/.local/lib/python3.9/site-packages/litecli/sqlexecute.py", line 126, in run\n    cur.execute(sql)\nsqlite3.OperationalError: no such column: Arthur\n'
2021-04-15 09:19:56,290 (50017/MainThread) litecli.main ERROR - sql: 'fg', error: OperationalError('near "fg": syntax error')
2021-04-15 09:19:56,292 (50017/MainThread) litecli.main ERROR - traceback: 'Traceback (most recent call last):\n  File "/home/arthur/.local/lib/python3.9/site-packages/litecli/sqlexecute.py", line 122, in run\n    for result in special.execute(cur, sql):\n  File "/home/arthur/.local/lib/python3.9/site-packages/litecli/packages/special/main.py", line 109, in execute\n    raise CommandNotFound\nlitecli.packages.special.main.CommandNotFound\n\nDuring handling of the above exception, another exception occurred:\n\nTraceback (most recent call last):\n  File "/home/arthur/.local/lib/python3.9/site-packages/litecli/main.py", line 441, in one_iteration\n    for title, cur, headers, status in res:\n  File "/home/arthur/.local/lib/python3.9/site-packages/litecli/sqlexecute.py", line 126, in run\n    cur.execute(sql)\nsqlite3.OperationalError: near "fg": syntax error\n'
2021-04-15 18:02:28,455 (62145/MainThread) litecli.main ERROR - sql: 'select * from customer\nwhere customer_name regexp "Arthu"\n;', error: OperationalError('no such function: regexp')
2021-04-15 18:02:28,456 (62145/MainThread) litecli.main ERROR - traceback: 'Traceback (most recent call last):\n  File "/home/arthur/.local/lib/python3.9/site-packages/litecli/sqlexecute.py", line 122, in run\n    for result in special.execute(cur, sql):\n  File "/home/arthur/.local/lib/python3.9/site-packages/litecli/packages/special/main.py", line 109, in execute\n    raise CommandNotFound\nlitecli.packages.special.main.CommandNotFound\n\nDuring handling of the above exception, another exception occurred:\n\nTraceback (most recent call last):\n  File "/home/arthur/.local/lib/python3.9/site-packages/litecli/main.py", line 441, in one_iteration\n    for title, cur, headers, status in res:\n  File "/home/arthur/.local/lib/python3.9/site-packages/litecli/sqlexecute.py", line 126, in run\n    cur.execute(sql)\nsqlite3.OperationalError: no such function: regexp\n'
2021-04-15 18:03:20,392 (62145/MainThread) litecli.main ERROR - sql: 'select * from customer\nwhere customer_name regexp "Arthu";', error: OperationalError('no such function: regexp')
2021-04-15 18:03:20,392 (62145/MainThread) litecli.main ERROR - traceback: 'Traceback (most recent call last):\n  File "/home/arthur/.local/lib/python3.9/site-packages/litecli/sqlexecute.py", line 122, in run\n    for result in special.execute(cur, sql):\n  File "/home/arthur/.local/lib/python3.9/site-packages/litecli/packages/special/main.py", line 109, in execute\n    raise CommandNotFound\nlitecli.packages.special.main.CommandNotFound\n\nDuring handling of the above exception, another exception occurred:\n\nTraceback (most recent call last):\n  File "/home/arthur/.local/lib/python3.9/site-packages/litecli/main.py", line 441, in one_iteration\n    for title, cur, headers, status in res:\n  File "/home/arthur/.local/lib/python3.9/site-packages/litecli/sqlexecute.py", line 126, in run\n    cur.execute(sql)\nsqlite3.OperationalError: no such function: regexp\n'
2021-04-15 20:40:44,616 (70380/MainThread) litecli.main ERROR - sql: 's.tables', error: OperationalError('near "s": syntax error')
2021-04-15 20:40:44,617 (70380/MainThread) litecli.main ERROR - traceback: 'Traceback (most recent call last):\n  File "/home/arthur/.local/lib/python3.9/site-packages/litecli/sqlexecute.py", line 122, in run\n    for result in special.execute(cur, sql):\n  File "/home/arthur/.local/lib/python3.9/site-packages/litecli/packages/special/main.py", line 109, in execute\n    raise CommandNotFound\nlitecli.packages.special.main.CommandNotFound\n\nDuring handling of the above exception, another exception occurred:\n\nTraceback (most recent call last):\n  File "/home/arthur/.local/lib/python3.9/site-packages/litecli/main.py", line 441, in one_iteration\n    for title, cur, headers, status in res:\n  File "/home/arthur/.local/lib/python3.9/site-packages/litecli/sqlexecute.py", line 126, in run\n    cur.execute(sql)\nsqlite3.OperationalError: near "s": syntax error\n'
2021-04-15 23:45:55,123 (79794/MainThread) litecli.main ERROR - sql: 'tables', error: OperationalError('near "tables": syntax error')
2021-04-15 23:45:55,123 (79794/MainThread) litecli.main ERROR - traceback: 'Traceback (most recent call last):\n  File "/home/arthur/.local/lib/python3.9/site-packages/litecli/sqlexecute.py", line 122, in run\n    for result in special.execute(cur, sql):\n  File "/home/arthur/.local/lib/python3.9/site-packages/litecli/packages/special/main.py", line 109, in execute\n    raise CommandNotFound\nlitecli.packages.special.main.CommandNotFound\n\nDuring handling of the above exception, another exception occurred:\n\nTraceback (most recent call last):\n  File "/home/arthur/.local/lib/python3.9/site-packages/litecli/main.py", line 441, in one_iteration\n    for title, cur, headers, status in res:\n  File "/home/arthur/.local/lib/python3.9/site-packages/litecli/sqlexecute.py", line 126, in run\n    cur.execute(sql)\nsqlite3.OperationalError: near "tables": syntax error\n'
2021-04-16 11:56:04,767 (100592/MainThread) litecli.main ERROR - sql: 'foreign', error: OperationalError('near "foreign": syntax error')
2021-04-16 11:56:04,768 (100592/MainThread) litecli.main ERROR - traceback: 'Traceback (most recent call last):\n  File "/home/arthur/.local/lib/python3.9/site-packages/litecli/sqlexecute.py", line 122, in run\n    for result in special.execute(cur, sql):\n  File "/home/arthur/.local/lib/python3.9/site-packages/litecli/packages/special/main.py", line 109, in execute\n    raise CommandNotFound\nlitecli.packages.special.main.CommandNotFound\n\nDuring handling of the above exception, another exception occurred:\n\nTraceback (most recent call last):\n  File "/home/arthur/.local/lib/python3.9/site-packages/litecli/main.py", line 441, in one_iteration\n    for title, cur, headers, status in res:\n  File "/home/arthur/.local/lib/python3.9/site-packages/litecli/sqlexecute.py", line 126, in run\n    cur.execute(sql)\nsqlite3.OperationalError: near "foreign": syntax error\n'
2021-04-16 13:08:33,719 (107647/MainThread) litecli.main ERROR - sql: 'create table child (', error: OperationalError('incomplete input')
2021-04-16 13:08:33,720 (107647/MainThread) litecli.main ERROR - traceback: 'Traceback (most recent call last):\n  File "/home/arthur/.local/lib/python3.9/site-packages/litecli/sqlexecute.py", line 122, in run\n    for result in special.execute(cur, sql):\n  File "/home/arthur/.local/lib/python3.9/site-packages/litecli/packages/special/main.py", line 109, in execute\n    raise CommandNotFound\nlitecli.packages.special.main.CommandNotFound\n\nDuring handling of the above exception, another exception occurred:\n\nTraceback (most recent call last):\n  File "/home/arthur/.local/lib/python3.9/site-packages/litecli/main.py", line 441, in one_iteration\n    for title, cur, headers, status in res:\n  File "/home/arthur/.local/lib/python3.9/site-packages/litecli/sqlexecute.py", line 126, in run\n    cur.execute(sql)\nsqlite3.OperationalError: incomplete input\n'
2021-04-16 13:12:34,508 (107647/MainThread) litecli.main ERROR - sql: 'insert into child_dog  values(2,45;', error: OperationalError('incomplete input')
2021-04-16 13:12:34,509 (107647/MainThread) litecli.main ERROR - traceback: 'Traceback (most recent call last):\n  File "/home/arthur/.local/lib/python3.9/site-packages/litecli/sqlexecute.py", line 122, in run\n    for result in special.execute(cur, sql):\n  File "/home/arthur/.local/lib/python3.9/site-packages/litecli/packages/special/main.py", line 109, in execute\n    raise CommandNotFound\nlitecli.packages.special.main.CommandNotFound\n\nDuring handling of the above exception, another exception occurred:\n\nTraceback (most recent call last):\n  File "/home/arthur/.local/lib/python3.9/site-packages/litecli/main.py", line 441, in one_iteration\n    for title, cur, headers, status in res:\n  File "/home/arthur/.local/lib/python3.9/site-packages/litecli/sqlexecute.py", line 126, in run\n    cur.execute(sql)\nsqlite3.OperationalError: incomplete input\n'
2021-04-16 13:12:36,638 (107647/MainThread) litecli.main ERROR - sql: 'insert into child_dog  values(2,45);', error: IntegrityError('FOREIGN KEY constraint failed')
2021-04-16 13:12:36,639 (107647/MainThread) litecli.main ERROR - traceback: 'Traceback (most recent call last):\n  File "/home/arthur/.local/lib/python3.9/site-packages/litecli/sqlexecute.py", line 122, in run\n    for result in special.execute(cur, sql):\n  File "/home/arthur/.local/lib/python3.9/site-packages/litecli/packages/special/main.py", line 109, in execute\n    raise CommandNotFound\nlitecli.packages.special.main.CommandNotFound\n\nDuring handling of the above exception, another exception occurred:\n\nTraceback (most recent call last):\n  File "/home/arthur/.local/lib/python3.9/site-packages/litecli/main.py", line 441, in one_iteration\n    for title, cur, headers, status in res:\n  File "/home/arthur/.local/lib/python3.9/site-packages/litecli/sqlexecute.py", line 126, in run\n    cur.execute(sql)\nsqlite3.IntegrityError: FOREIGN KEY constraint failed\n'
2021-04-16 15:33:25,168 (117147/MainThread) litecli.main ERROR - sql: 'ncdu', error: OperationalError('near "ncdu": syntax error')
2021-04-16 15:33:25,169 (117147/MainThread) litecli.main ERROR - traceback: 'Traceback (most recent call last):\n  File "/home/arthur/.local/lib/python3.9/site-packages/litecli/sqlexecute.py", line 122, in run\n    for result in special.execute(cur, sql):\n  File "/home/arthur/.local/lib/python3.9/site-packages/litecli/packages/special/main.py", line 109, in execute\n    raise CommandNotFound\nlitecli.packages.special.main.CommandNotFound\n\nDuring handling of the above exception, another exception occurred:\n\nTraceback (most recent call last):\n  File "/home/arthur/.local/lib/python3.9/site-packages/litecli/main.py", line 441, in one_iteration\n    for title, cur, headers, status in res:\n  File "/home/arthur/.local/lib/python3.9/site-packages/litecli/sqlexecute.py", line 126, in run\n    cur.execute(sql)\nsqlite3.OperationalError: near "ncdu": syntax error\n'
2021-04-16 16:03:55,245 (119176/MainThread) litecli.main ERROR - sql: 'select * from customer where customer_name is like %', error: OperationalError('incomplete input')
2021-04-16 16:03:55,246 (119176/MainThread) litecli.main ERROR - traceback: 'Traceback (most recent call last):\n  File "/home/arthur/.local/lib/python3.9/site-packages/litecli/sqlexecute.py", line 122, in run\n    for result in special.execute(cur, sql):\n  File "/home/arthur/.local/lib/python3.9/site-packages/litecli/packages/special/main.py", line 109, in execute\n    raise CommandNotFound\nlitecli.packages.special.main.CommandNotFound\n\nDuring handling of the above exception, another exception occurred:\n\nTraceback (most recent call last):\n  File "/home/arthur/.local/lib/python3.9/site-packages/litecli/main.py", line 441, in one_iteration\n    for title, cur, headers, status in res:\n  File "/home/arthur/.local/lib/python3.9/site-packages/litecli/sqlexecute.py", line 126, in run\n    cur.execute(sql)\nsqlite3.OperationalError: incomplete input\n'
2021-04-16 16:03:57,969 (119176/MainThread) litecli.main ERROR - sql: 'select * from customer where customer_name is like "%"', error: OperationalError('near ""%"": syntax error')
2021-04-16 16:03:57,970 (119176/MainThread) litecli.main ERROR - traceback: 'Traceback (most recent call last):\n  File "/home/arthur/.local/lib/python3.9/site-packages/litecli/sqlexecute.py", line 122, in run\n    for result in special.execute(cur, sql):\n  File "/home/arthur/.local/lib/python3.9/site-packages/litecli/packages/special/main.py", line 109, in execute\n    raise CommandNotFound\nlitecli.packages.special.main.CommandNotFound\n\nDuring handling of the above exception, another exception occurred:\n\nTraceback (most recent call last):\n  File "/home/arthur/.local/lib/python3.9/site-packages/litecli/main.py", line 441, in one_iteration\n    for title, cur, headers, status in res:\n  File "/home/arthur/.local/lib/python3.9/site-packages/litecli/sqlexecute.py", line 126, in run\n    cur.execute(sql)\nsqlite3.OperationalError: near ""%"": syntax error\n'
2021-04-16 16:04:00,289 (119176/MainThread) litecli.main ERROR - sql: 'select * from customer where customer_name is like "%%"', error: OperationalError('near ""%%"": syntax error')
2021-04-16 16:04:00,289 (119176/MainThread) litecli.main ERROR - traceback: 'Traceback (most recent call last):\n  File "/home/arthur/.local/lib/python3.9/site-packages/litecli/sqlexecute.py", line 122, in run\n    for result in special.execute(cur, sql):\n  File "/home/arthur/.local/lib/python3.9/site-packages/litecli/packages/special/main.py", line 109, in execute\n    raise CommandNotFound\nlitecli.packages.special.main.CommandNotFound\n\nDuring handling of the above exception, another exception occurred:\n\nTraceback (most recent call last):\n  File "/home/arthur/.local/lib/python3.9/site-packages/litecli/main.py", line 441, in one_iteration\n    for title, cur, headers, status in res:\n  File "/home/arthur/.local/lib/python3.9/site-packages/litecli/sqlexecute.py", line 126, in run\n    cur.execute(sql)\nsqlite3.OperationalError: near ""%%"": syntax error\n'
2021-04-16 16:04:01,904 (119176/MainThread) litecli.main ERROR - sql: 'select * from customer where customer_name is like "%a%"', error: OperationalError('near ""%a%"": syntax error')
2021-04-16 16:04:01,904 (119176/MainThread) litecli.main ERROR - traceback: 'Traceback (most recent call last):\n  File "/home/arthur/.local/lib/python3.9/site-packages/litecli/sqlexecute.py", line 122, in run\n    for result in special.execute(cur, sql):\n  File "/home/arthur/.local/lib/python3.9/site-packages/litecli/packages/special/main.py", line 109, in execute\n    raise CommandNotFound\nlitecli.packages.special.main.CommandNotFound\n\nDuring handling of the above exception, another exception occurred:\n\nTraceback (most recent call last):\n  File "/home/arthur/.local/lib/python3.9/site-packages/litecli/main.py", line 441, in one_iteration\n    for title, cur, headers, status in res:\n  File "/home/arthur/.local/lib/python3.9/site-packages/litecli/sqlexecute.py", line 126, in run\n    cur.execute(sql)\nsqlite3.OperationalError: near ""%a%"": syntax error\n'
2021-04-16 18:01:14,504 (126955/MainThread) litecli.main ERROR - sql: 'insert into customer_balance_view', error: OperationalError('incomplete input')
2021-04-16 18:01:14,505 (126955/MainThread) litecli.main ERROR - traceback: 'Traceback (most recent call last):\n  File "/home/arthur/.local/lib/python3.9/site-packages/litecli/sqlexecute.py", line 122, in run\n    for result in special.execute(cur, sql):\n  File "/home/arthur/.local/lib/python3.9/site-packages/litecli/packages/special/main.py", line 109, in execute\n    raise CommandNotFound\nlitecli.packages.special.main.CommandNotFound\n\nDuring handling of the above exception, another exception occurred:\n\nTraceback (most recent call last):\n  File "/home/arthur/.local/lib/python3.9/site-packages/litecli/main.py", line 441, in one_iteration\n    for title, cur, headers, status in res:\n  File "/home/arthur/.local/lib/python3.9/site-packages/litecli/sqlexecute.py", line 126, in run\n    cur.execute(sql)\nsqlite3.OperationalError: incomplete input\n'
2021-04-16 18:01:52,626 (126955/MainThread) litecli.main ERROR - sql: 'update customer_balance_view\nset balance = 0;', error: OperationalError('cannot modify customer_balance_view because it is a view')
2021-04-16 18:01:52,627 (126955/MainThread) litecli.main ERROR - traceback: 'Traceback (most recent call last):\n  File "/home/arthur/.local/lib/python3.9/site-packages/litecli/sqlexecute.py", line 122, in run\n    for result in special.execute(cur, sql):\n  File "/home/arthur/.local/lib/python3.9/site-packages/litecli/packages/special/main.py", line 109, in execute\n    raise CommandNotFound\nlitecli.packages.special.main.CommandNotFound\n\nDuring handling of the above exception, another exception occurred:\n\nTraceback (most recent call last):\n  File "/home/arthur/.local/lib/python3.9/site-packages/litecli/main.py", line 441, in one_iteration\n    for title, cur, headers, status in res:\n  File "/home/arthur/.local/lib/python3.9/site-packages/litecli/sqlexecute.py", line 126, in run\n    cur.execute(sql)\nsqlite3.OperationalError: cannot modify customer_balance_view because it is a view\n'
2021-04-19 15:22:13,489 (63905/MainThread) litecli.main ERROR - sql: 'insert into a values (1,2,3,21,3,12,4,12,3,123,12,3)', error: OperationalError('table a has 1 columns but 12 values were supplied')
2021-04-19 15:22:13,493 (63905/MainThread) litecli.main ERROR - traceback: 'Traceback (most recent call last):\n  File "/home/arthur/.local/lib/python3.9/site-packages/litecli/sqlexecute.py", line 122, in run\n    for result in special.execute(cur, sql):\n  File "/home/arthur/.local/lib/python3.9/site-packages/litecli/packages/special/main.py", line 109, in execute\n    raise CommandNotFound\nlitecli.packages.special.main.CommandNotFound\n\nDuring handling of the above exception, another exception occurred:\n\nTraceback (most recent call last):\n  File "/home/arthur/.local/lib/python3.9/site-packages/litecli/main.py", line 441, in one_iteration\n    for title, cur, headers, status in res:\n  File "/home/arthur/.local/lib/python3.9/site-packages/litecli/sqlexecute.py", line 126, in run\n    cur.execute(sql)\nsqlite3.OperationalError: table a has 1 columns but 12 values were supplied\n'
2021-04-19 15:22:25,700 (63905/MainThread) litecli.main ERROR - sql: 'insert into a vacuum 1', error: OperationalError('near "vacuum": syntax error')
2021-04-19 15:22:25,701 (63905/MainThread) litecli.main ERROR - traceback: 'Traceback (most recent call last):\n  File "/home/arthur/.local/lib/python3.9/site-packages/litecli/sqlexecute.py", line 122, in run\n    for result in special.execute(cur, sql):\n  File "/home/arthur/.local/lib/python3.9/site-packages/litecli/packages/special/main.py", line 109, in execute\n    raise CommandNotFound\nlitecli.packages.special.main.CommandNotFound\n\nDuring handling of the above exception, another exception occurred:\n\nTraceback (most recent call last):\n  File "/home/arthur/.local/lib/python3.9/site-packages/litecli/main.py", line 441, in one_iteration\n    for title, cur, headers, status in res:\n  File "/home/arthur/.local/lib/python3.9/site-packages/litecli/sqlexecute.py", line 126, in run\n    cur.execute(sql)\nsqlite3.OperationalError: near "vacuum": syntax error\n'
2021-04-19 15:22:29,334 (63905/MainThread) litecli.main ERROR - sql: 'insert into a values 1', error: OperationalError('near "1": syntax error')
2021-04-19 15:22:29,334 (63905/MainThread) litecli.main ERROR - traceback: 'Traceback (most recent call last):\n  File "/home/arthur/.local/lib/python3.9/site-packages/litecli/sqlexecute.py", line 122, in run\n    for result in special.execute(cur, sql):\n  File "/home/arthur/.local/lib/python3.9/site-packages/litecli/packages/special/main.py", line 109, in execute\n    raise CommandNotFound\nlitecli.packages.special.main.CommandNotFound\n\nDuring handling of the above exception, another exception occurred:\n\nTraceback (most recent call last):\n  File "/home/arthur/.local/lib/python3.9/site-packages/litecli/main.py", line 441, in one_iteration\n    for title, cur, headers, status in res:\n  File "/home/arthur/.local/lib/python3.9/site-packages/litecli/sqlexecute.py", line 126, in run\n    cur.execute(sql)\nsqlite3.OperationalError: near "1": syntax error\n'
2021-04-19 15:23:00,753 (63905/MainThread) litecli.main ERROR - sql: 'select * from a when x is NULL', error: OperationalError('near "when": syntax error')
2021-04-19 15:23:00,753 (63905/MainThread) litecli.main ERROR - traceback: 'Traceback (most recent call last):\n  File "/home/arthur/.local/lib/python3.9/site-packages/litecli/sqlexecute.py", line 122, in run\n    for result in special.execute(cur, sql):\n  File "/home/arthur/.local/lib/python3.9/site-packages/litecli/packages/special/main.py", line 109, in execute\n    raise CommandNotFound\nlitecli.packages.special.main.CommandNotFound\n\nDuring handling of the above exception, another exception occurred:\n\nTraceback (most recent call last):\n  File "/home/arthur/.local/lib/python3.9/site-packages/litecli/main.py", line 441, in one_iteration\n    for title, cur, headers, status in res:\n  File "/home/arthur/.local/lib/python3.9/site-packages/litecli/sqlexecute.py", line 126, in run\n    cur.execute(sql)\nsqlite3.OperationalError: near "when": syntax error\n'
2021-04-19 15:49:02,295 (66471/MainThread) litecli.main ERROR - sql: 'end', error: OperationalError('cannot commit - no transaction is active')
2021-04-19 15:49:02,304 (66471/MainThread) litecli.main ERROR - traceback: 'Traceback (most recent call last):\n  File "/home/arthur/.local/lib/python3.9/site-packages/litecli/sqlexecute.py", line 122, in run\n    for result in special.execute(cur, sql):\n  File "/home/arthur/.local/lib/python3.9/site-packages/litecli/packages/special/main.py", line 109, in execute\n    raise CommandNotFound\nlitecli.packages.special.main.CommandNotFound\n\nDuring handling of the above exception, another exception occurred:\n\nTraceback (most recent call last):\n  File "/home/arthur/.local/lib/python3.9/site-packages/litecli/main.py", line 441, in one_iteration\n    for title, cur, headers, status in res:\n  File "/home/arthur/.local/lib/python3.9/site-packages/litecli/sqlexecute.py", line 126, in run\n    cur.execute(sql)\nsqlite3.OperationalError: cannot commit - no transaction is active\n'
2021-04-19 15:58:32,755 (67150/MainThread) litecli.main ERROR - sql: 'upsert', error: OperationalError('near "upsert": syntax error')
2021-04-19 15:58:32,757 (67150/MainThread) litecli.main ERROR - traceback: 'Traceback (most recent call last):\n  File "/home/arthur/.local/lib/python3.9/site-packages/litecli/sqlexecute.py", line 122, in run\n    for result in special.execute(cur, sql):\n  File "/home/arthur/.local/lib/python3.9/site-packages/litecli/packages/special/main.py", line 109, in execute\n    raise CommandNotFound\nlitecli.packages.special.main.CommandNotFound\n\nDuring handling of the above exception, another exception occurred:\n\nTraceback (most recent call last):\n  File "/home/arthur/.local/lib/python3.9/site-packages/litecli/main.py", line 441, in one_iteration\n    for title, cur, headers, status in res:\n  File "/home/arthur/.local/lib/python3.9/site-packages/litecli/sqlexecute.py", line 126, in run\n    cur.execute(sql)\nsqlite3.OperationalError: near "upsert": syntax error\n'
2021-04-19 15:59:27,879 (67150/MainThread) litecli.main ERROR - sql: 'insert or replace into employee (id, role, name)', error: OperationalError('incomplete input')
2021-04-19 15:59:27,879 (67150/MainThread) litecli.main ERROR - traceback: 'Traceback (most recent call last):\n  File "/home/arthur/.local/lib/python3.9/site-packages/litecli/sqlexecute.py", line 122, in run\n    for result in special.execute(cur, sql):\n  File "/home/arthur/.local/lib/python3.9/site-packages/litecli/packages/special/main.py", line 109, in execute\n    raise CommandNotFound\nlitecli.packages.special.main.CommandNotFound\n\nDuring handling of the above exception, another exception occurred:\n\nTraceback (most recent call last):\n  File "/home/arthur/.local/lib/python3.9/site-packages/litecli/main.py", line 441, in one_iteration\n    for title, cur, headers, status in res:\n  File "/home/arthur/.local/lib/python3.9/site-packages/litecli/sqlexecute.py", line 126, in run\n    cur.execute(sql)\nsqlite3.OperationalError: incomplete input\n'
2021-04-19 16:04:19,816 (67150/MainThread) litecli.main ERROR - sql: 'select exists (select * from employee when id=9);', error: OperationalError('near "when": syntax error')
2021-04-19 16:04:19,816 (67150/MainThread) litecli.main ERROR - traceback: 'Traceback (most recent call last):\n  File "/home/arthur/.local/lib/python3.9/site-packages/litecli/sqlexecute.py", line 122, in run\n    for result in special.execute(cur, sql):\n  File "/home/arthur/.local/lib/python3.9/site-packages/litecli/packages/special/main.py", line 109, in execute\n    raise CommandNotFound\nlitecli.packages.special.main.CommandNotFound\n\nDuring handling of the above exception, another exception occurred:\n\nTraceback (most recent call last):\n  File "/home/arthur/.local/lib/python3.9/site-packages/litecli/main.py", line 441, in one_iteration\n    for title, cur, headers, status in res:\n  File "/home/arthur/.local/lib/python3.9/site-packages/litecli/sqlexecute.py", line 126, in run\n    cur.execute(sql)\nsqlite3.OperationalError: near "when": syntax error\n'
2021-04-19 16:04:26,238 (67150/MainThread) litecli.main ERROR - sql: 'select exists (select * from employee where id=91;', error: OperationalError('incomplete input')
2021-04-19 16:04:26,239 (67150/MainThread) litecli.main ERROR - traceback: 'Traceback (most recent call last):\n  File "/home/arthur/.local/lib/python3.9/site-packages/litecli/sqlexecute.py", line 122, in run\n    for result in special.execute(cur, sql):\n  File "/home/arthur/.local/lib/python3.9/site-packages/litecli/packages/special/main.py", line 109, in execute\n    raise CommandNotFound\nlitecli.packages.special.main.CommandNotFound\n\nDuring handling of the above exception, another exception occurred:\n\nTraceback (most recent call last):\n  File "/home/arthur/.local/lib/python3.9/site-packages/litecli/main.py", line 441, in one_iteration\n    for title, cur, headers, status in res:\n  File "/home/arthur/.local/lib/python3.9/site-packages/litecli/sqlexecute.py", line 126, in run\n    cur.execute(sql)\nsqlite3.OperationalError: incomplete input\n'
2021-04-19 16:05:49,464 (67150/MainThread) litecli.main ERROR - sql: 'case select exists (select * from employee where id=1)\nwhen 1 then select "yes"\nwhen 2 then select "no"\nend\n;', error: OperationalError('near "case": syntax error')
2021-04-19 16:05:49,465 (67150/MainThread) litecli.main ERROR - traceback: 'Traceback (most recent call last):\n  File "/home/arthur/.local/lib/python3.9/site-packages/litecli/sqlexecute.py", line 122, in run\n    for result in special.execute(cur, sql):\n  File "/home/arthur/.local/lib/python3.9/site-packages/litecli/packages/special/main.py", line 109, in execute\n    raise CommandNotFound\nlitecli.packages.special.main.CommandNotFound\n\nDuring handling of the above exception, another exception occurred:\n\nTraceback (most recent call last):\n  File "/home/arthur/.local/lib/python3.9/site-packages/litecli/main.py", line 441, in one_iteration\n    for title, cur, headers, status in res:\n  File "/home/arthur/.local/lib/python3.9/site-packages/litecli/sqlexecute.py", line 126, in run\n    cur.execute(sql)\nsqlite3.OperationalError: near "case": syntax error\n'
2021-04-19 16:06:30,688 (67150/MainThread) litecli.main ERROR - sql: 'select case select exists (select * from employee where id=1)\nwhen 1 then select "yes"\nwhen 2 then select "no"\nend a;', error: OperationalError('near "select": syntax error')
2021-04-19 16:06:30,689 (67150/MainThread) litecli.main ERROR - traceback: 'Traceback (most recent call last):\n  File "/home/arthur/.local/lib/python3.9/site-packages/litecli/sqlexecute.py", line 122, in run\n    for result in special.execute(cur, sql):\n  File "/home/arthur/.local/lib/python3.9/site-packages/litecli/packages/special/main.py", line 109, in execute\n    raise CommandNotFound\nlitecli.packages.special.main.CommandNotFound\n\nDuring handling of the above exception, another exception occurred:\n\nTraceback (most recent call last):\n  File "/home/arthur/.local/lib/python3.9/site-packages/litecli/main.py", line 441, in one_iteration\n    for title, cur, headers, status in res:\n  File "/home/arthur/.local/lib/python3.9/site-packages/litecli/sqlexecute.py", line 126, in run\n    cur.execute(sql)\nsqlite3.OperationalError: near "select": syntax error\n'
2021-04-19 16:06:36,159 (67150/MainThread) litecli.main ERROR - sql: 'select 2, case select exists (select * from employee where id=1)\nwhen 1 then select "yes"\nwhen 2 then select "no"\nend a;', error: OperationalError('near "select": syntax error')
2021-04-19 16:06:36,160 (67150/MainThread) litecli.main ERROR - traceback: 'Traceback (most recent call last):\n  File "/home/arthur/.local/lib/python3.9/site-packages/litecli/sqlexecute.py", line 122, in run\n    for result in special.execute(cur, sql):\n  File "/home/arthur/.local/lib/python3.9/site-packages/litecli/packages/special/main.py", line 109, in execute\n    raise CommandNotFound\nlitecli.packages.special.main.CommandNotFound\n\nDuring handling of the above exception, another exception occurred:\n\nTraceback (most recent call last):\n  File "/home/arthur/.local/lib/python3.9/site-packages/litecli/main.py", line 441, in one_iteration\n    for title, cur, headers, status in res:\n  File "/home/arthur/.local/lib/python3.9/site-packages/litecli/sqlexecute.py", line 126, in run\n    cur.execute(sql)\nsqlite3.OperationalError: near "select": syntax error\n'
2021-04-19 16:07:08,715 (67150/MainThread) litecli.main ERROR - sql: 'case when 1 < 22 then select "ok"\n;', error: OperationalError('near "case": syntax error')
2021-04-19 16:07:08,716 (67150/MainThread) litecli.main ERROR - traceback: 'Traceback (most recent call last):\n  File "/home/arthur/.local/lib/python3.9/site-packages/litecli/sqlexecute.py", line 122, in run\n    for result in special.execute(cur, sql):\n  File "/home/arthur/.local/lib/python3.9/site-packages/litecli/packages/special/main.py", line 109, in execute\n    raise CommandNotFound\nlitecli.packages.special.main.CommandNotFound\n\nDuring handling of the above exception, another exception occurred:\n\nTraceback (most recent call last):\n  File "/home/arthur/.local/lib/python3.9/site-packages/litecli/main.py", line 441, in one_iteration\n    for title, cur, headers, status in res:\n  File "/home/arthur/.local/lib/python3.9/site-packages/litecli/sqlexecute.py", line 126, in run\n    cur.execute(sql)\nsqlite3.OperationalError: near "case": syntax error\n'
2021-04-19 16:07:14,363 (67150/MainThread) litecli.main ERROR - sql: 'select', error: OperationalError('incomplete input')
2021-04-19 16:07:14,364 (67150/MainThread) litecli.main ERROR - traceback: 'Traceback (most recent call last):\n  File "/home/arthur/.local/lib/python3.9/site-packages/litecli/sqlexecute.py", line 122, in run\n    for result in special.execute(cur, sql):\n  File "/home/arthur/.local/lib/python3.9/site-packages/litecli/packages/special/main.py", line 109, in execute\n    raise CommandNotFound\nlitecli.packages.special.main.CommandNotFound\n\nDuring handling of the above exception, another exception occurred:\n\nTraceback (most recent call last):\n  File "/home/arthur/.local/lib/python3.9/site-packages/litecli/main.py", line 441, in one_iteration\n    for title, cur, headers, status in res:\n  File "/home/arthur/.local/lib/python3.9/site-packages/litecli/sqlexecute.py", line 126, in run\n    cur.execute(sql)\nsqlite3.OperationalError: incomplete input\n'
2021-04-19 16:07:28,785 (67150/MainThread) litecli.main ERROR - sql: 'select 2, case select exists (select * from employee where id=1)\nwhen 1 then "yes"\nwhen 2 then "no"\nend a;', error: OperationalError('near "select": syntax error')
2021-04-19 16:07:28,786 (67150/MainThread) litecli.main ERROR - traceback: 'Traceback (most recent call last):\n  File "/home/arthur/.local/lib/python3.9/site-packages/litecli/sqlexecute.py", line 122, in run\n    for result in special.execute(cur, sql):\n  File "/home/arthur/.local/lib/python3.9/site-packages/litecli/packages/special/main.py", line 109, in execute\n    raise CommandNotFound\nlitecli.packages.special.main.CommandNotFound\n\nDuring handling of the above exception, another exception occurred:\n\nTraceback (most recent call last):\n  File "/home/arthur/.local/lib/python3.9/site-packages/litecli/main.py", line 441, in one_iteration\n    for title, cur, headers, status in res:\n  File "/home/arthur/.local/lib/python3.9/site-packages/litecli/sqlexecute.py", line 126, in run\n    cur.execute(sql)\nsqlite3.OperationalError: near "select": syntax error\n'
2021-04-19 16:08:19,532 (67150/MainThread) litecli.main ERROR - sql: 'select 2, case e\nwhen 1 then "yes"\nwhen 2 then "no"\nend a\nfrom (select 1)\n;', error: OperationalError('no such column: e')
2021-04-19 16:08:19,533 (67150/MainThread) litecli.main ERROR - traceback: 'Traceback (most recent call last):\n  File "/home/arthur/.local/lib/python3.9/site-packages/litecli/sqlexecute.py", line 122, in run\n    for result in special.execute(cur, sql):\n  File "/home/arthur/.local/lib/python3.9/site-packages/litecli/packages/special/main.py", line 109, in execute\n    raise CommandNotFound\nlitecli.packages.special.main.CommandNotFound\n\nDuring handling of the above exception, another exception occurred:\n\nTraceback (most recent call last):\n  File "/home/arthur/.local/lib/python3.9/site-packages/litecli/main.py", line 441, in one_iteration\n    for title, cur, headers, status in res:\n  File "/home/arthur/.local/lib/python3.9/site-packages/litecli/sqlexecute.py", line 126, in run\n    cur.execute(sql)\nsqlite3.OperationalError: no such column: e\n'
2021-04-19 16:09:23,506 (67150/MainThread) litecli.main ERROR - sql: 'select case e\nwhen 1 then "yes"\nwhen 2 then "no"\nend a\nfrom (select exists(select * from employee where id=1))\n;', error: OperationalError('no such column: e')
2021-04-19 16:09:23,506 (67150/MainThread) litecli.main ERROR - traceback: 'Traceback (most recent call last):\n  File "/home/arthur/.local/lib/python3.9/site-packages/litecli/sqlexecute.py", line 122, in run\n    for result in special.execute(cur, sql):\n  File "/home/arthur/.local/lib/python3.9/site-packages/litecli/packages/special/main.py", line 109, in execute\n    raise CommandNotFound\nlitecli.packages.special.main.CommandNotFound\n\nDuring handling of the above exception, another exception occurred:\n\nTraceback (most recent call last):\n  File "/home/arthur/.local/lib/python3.9/site-packages/litecli/main.py", line 441, in one_iteration\n    for title, cur, headers, status in res:\n  File "/home/arthur/.local/lib/python3.9/site-packages/litecli/sqlexecute.py", line 126, in run\n    cur.execute(sql)\nsqlite3.OperationalError: no such column: e\n'
2021-06-25 18:41:54,916 (15423/MainThread) litecli.main ERROR - sql: 'insert into employee(*) values(1,"a","a")', error: OperationalError('near "*": syntax error')
2021-06-25 18:41:54,924 (15423/MainThread) litecli.main ERROR - traceback: 'Traceback (most recent call last):\n  File "/usr/lib/python3.9/site-packages/litecli/sqlexecute.py", line 122, in run\n    for result in special.execute(cur, sql):\n  File "/usr/lib/python3.9/site-packages/litecli/packages/special/main.py", line 109, in execute\n    raise CommandNotFound\nlitecli.packages.special.main.CommandNotFound\n\nDuring handling of the above exception, another exception occurred:\n\nTraceback (most recent call last):\n  File "/usr/lib/python3.9/site-packages/litecli/main.py", line 441, in one_iteration\n    for title, cur, headers, status in res:\n  File "/usr/lib/python3.9/site-packages/litecli/sqlexecute.py", line 126, in run\n    cur.execute(sql)\nsqlite3.OperationalError: near "*": syntax error\n'
2021-06-25 18:41:57,808 (15423/MainThread) litecli.main ERROR - sql: 'insert into employee() values(1,"a","a")', error: OperationalError('near ")": syntax error')
2021-06-25 18:41:57,808 (15423/MainThread) litecli.main ERROR - traceback: 'Traceback (most recent call last):\n  File "/usr/lib/python3.9/site-packages/litecli/sqlexecute.py", line 122, in run\n    for result in special.execute(cur, sql):\n  File "/usr/lib/python3.9/site-packages/litecli/packages/special/main.py", line 109, in execute\n    raise CommandNotFound\nlitecli.packages.special.main.CommandNotFound\n\nDuring handling of the above exception, another exception occurred:\n\nTraceback (most recent call last):\n  File "/usr/lib/python3.9/site-packages/litecli/main.py", line 441, in one_iteration\n    for title, cur, headers, status in res:\n  File "/usr/lib/python3.9/site-packages/litecli/sqlexecute.py", line 126, in run\n    cur.execute(sql)\nsqlite3.OperationalError: near ")": syntax error\n'
2021-06-25 19:10:46,469 (21994/MainThread) litecli.main ERROR - sql: 'insert into logins(uid,uname,upassword,utype) values("1","1","1","1",1);', error: OperationalError('5 values for 4 columns')
2021-06-25 19:10:46,470 (21994/MainThread) litecli.main ERROR - traceback: 'Traceback (most recent call last):\n  File "/usr/lib/python3.9/site-packages/litecli/sqlexecute.py", line 122, in run\n    for result in special.execute(cur, sql):\n  File "/usr/lib/python3.9/site-packages/litecli/packages/special/main.py", line 109, in execute\n    raise CommandNotFound\nlitecli.packages.special.main.CommandNotFound\n\nDuring handling of the above exception, another exception occurred:\n\nTraceback (most recent call last):\n  File "/usr/lib/python3.9/site-packages/litecli/main.py", line 441, in one_iteration\n    for title, cur, headers, status in res:\n  File "/usr/lib/python3.9/site-packages/litecli/sqlexecute.py", line 126, in run\n    cur.execute(sql)\nsqlite3.OperationalError: 5 values for 4 columns\n'
2021-09-23 22:12:18,151 (145979/MainThread) litecli.main ERROR - sql: '.tables;', error: OperationalError('database is locked')
2021-09-23 22:12:18,161 (145979/MainThread) litecli.main ERROR - traceback: 'Traceback (most recent call last):\n  File "/home/arthur/.local/lib/python3.9/site-packages/litecli/main.py", line 441, in one_iteration\n    for title, cur, headers, status in res:\n  File "/home/arthur/.local/lib/python3.9/site-packages/litecli/sqlexecute.py", line 122, in run\n    for result in special.execute(cur, sql):\n  File "/home/arthur/.local/lib/python3.9/site-packages/litecli/packages/special/main.py", line 121, in execute\n    return special_cmd.handler(cur=cur, arg=arg, verbose=verbose)\n  File "/home/arthur/.local/lib/python3.9/site-packages/litecli/packages/special/dbcommands.py", line 43, in list_tables\n    cur.execute(query, args)\nsqlite3.OperationalError: database is locked\n'
2022-04-03 19:35:47,159 (414870/MainThread) litecli.main ERROR - sql: 'create database main', error: OperationalError('near "database": syntax error')
2022-04-03 19:35:47,167 (414870/MainThread) litecli.main ERROR - traceback: 'Traceback (most recent call last):\n  File "/home/arthur/.local/lib/python3.10/site-packages/litecli/sqlexecute.py", line 122, in run\n    for result in special.execute(cur, sql):\n  File "/home/arthur/.local/lib/python3.10/site-packages/litecli/packages/special/main.py", line 109, in execute\n    raise CommandNotFound\nlitecli.packages.special.main.CommandNotFound\n\nDuring handling of the above exception, another exception occurred:\n\nTraceback (most recent call last):\n  File "/home/arthur/.local/lib/python3.10/site-packages/litecli/main.py", line 443, in one_iteration\n    for title, cur, headers, status in res:\n  File "/home/arthur/.local/lib/python3.10/site-packages/litecli/sqlexecute.py", line 126, in run\n    cur.execute(sql)\nsqlite3.OperationalError: near "database": syntax error\n'
2022-04-03 19:35:50,895 (414870/MainThread) litecli.main ERROR - sql: 'database main', error: OperationalError('near "database": syntax error')
2022-04-03 19:35:50,896 (414870/MainThread) litecli.main ERROR - traceback: 'Traceback (most recent call last):\n  File "/home/arthur/.local/lib/python3.10/site-packages/litecli/sqlexecute.py", line 122, in run\n    for result in special.execute(cur, sql):\n  File "/home/arthur/.local/lib/python3.10/site-packages/litecli/packages/special/main.py", line 109, in execute\n    raise CommandNotFound\nlitecli.packages.special.main.CommandNotFound\n\nDuring handling of the above exception, another exception occurred:\n\nTraceback (most recent call last):\n  File "/home/arthur/.local/lib/python3.10/site-packages/litecli/main.py", line 443, in one_iteration\n    for title, cur, headers, status in res:\n  File "/home/arthur/.local/lib/python3.10/site-packages/litecli/sqlexecute.py", line 126, in run\n    cur.execute(sql)\nsqlite3.OperationalError: near "database": syntax error\n'
2022-04-03 19:35:52,359 (414870/MainThread) litecli.main ERROR - sql: 'ls', error: OperationalError('near "ls": syntax error')
2022-04-03 19:35:52,359 (414870/MainThread) litecli.main ERROR - traceback: 'Traceback (most recent call last):\n  File "/home/arthur/.local/lib/python3.10/site-packages/litecli/sqlexecute.py", line 122, in run\n    for result in special.execute(cur, sql):\n  File "/home/arthur/.local/lib/python3.10/site-packages/litecli/packages/special/main.py", line 109, in execute\n    raise CommandNotFound\nlitecli.packages.special.main.CommandNotFound\n\nDuring handling of the above exception, another exception occurred:\n\nTraceback (most recent call last):\n  File "/home/arthur/.local/lib/python3.10/site-packages/litecli/main.py", line 443, in one_iteration\n    for title, cur, headers, status in res:\n  File "/home/arthur/.local/lib/python3.10/site-packages/litecli/sqlexecute.py", line 126, in run\n    cur.execute(sql)\nsqlite3.OperationalError: near "ls": syntax error\n'
2022-04-03 20:15:17,476 (420670/MainThread) litecli.main ERROR - sql: 'ls', error: OperationalError('near "ls": syntax error')
2022-04-03 20:15:17,485 (420670/MainThread) litecli.main ERROR - traceback: 'Traceback (most recent call last):\n  File "/home/arthur/.local/lib/python3.10/site-packages/litecli/sqlexecute.py", line 122, in run\n    for result in special.execute(cur, sql):\n  File "/home/arthur/.local/lib/python3.10/site-packages/litecli/packages/special/main.py", line 109, in execute\n    raise CommandNotFound\nlitecli.packages.special.main.CommandNotFound\n\nDuring handling of the above exception, another exception occurred:\n\nTraceback (most recent call last):\n  File "/home/arthur/.local/lib/python3.10/site-packages/litecli/main.py", line 443, in one_iteration\n    for title, cur, headers, status in res:\n  File "/home/arthur/.local/lib/python3.10/site-packages/litecli/sqlexecute.py", line 126, in run\n    cur.execute(sql)\nsqlite3.OperationalError: near "ls": syntax error\n'
